Workbook
Name a_metros: Configuración!$B$9
Name alfa: Configuración!$B$29
Name banda_1: Configuración!$B$40
Name banda_2: Configuración!$C$40
Name banda_3: Configuración!$D$40
Name c_luz: Configuración!$B$8
Name colas: Configuración!$B$31
Name conf_sigma: Configuración!$B$32
Name conv: Configuración!$B$10
Name corrientes: Configuración!$B$24:$B$26
Name delta_def: Configuración!$B$33
Name dias: Réplicas!$B$37
Name dur_piloto: 'Registro piloto'!$J$21
Name estab_1: Configuración!$B$41
Name estab_2: Configuración!$C$41
Name estab_3: Configuración!$D$41
Name factor_forma: Configuración!$B$13
Name horas_dia: Configuración!$B$47
Name I1_A: Configuración!$B$24
Name I2_A: Configuración!$B$25
Name I3_A: Configuración!$B$26
Name incert_1: Configuración!$B$42
Name incert_2: Configuración!$C$42
Name incert_3: Configuración!$D$42
Name min_traza_man: Configuración!$B$48
Name n_fondo: Configuración!$B$14
Name n_I1: 'Resumen piloto'!$B$22
Name n_I2: 'Resumen piloto'!$B$23
Name n_I3: 'Resumen piloto'!$B$24
Name n_zona: Configuración!$B$19
Name pasos: Configuración!$B$7
Name pfab_1: Configuración!$B$43
Name pfab_2: Configuración!$C$43
Name pfab_3: Configuración!$D$43
Name potencia: Configuración!$B$30
Name pts_min: Configuración!$B$17
Name rec_min: Configuración!$B$18
Name resol: Configuración!$B$21
Name rpd: Réplicas!$B$38
Name S_I1: 'Resumen piloto'!$D$22
Name S_I2: 'Resumen piloto'!$D$23
Name S_I3: 'Resumen piloto'!$D$24
Name semi: Configuración!$B$16
Name semilla: Configuración!$B$49
Name tau0_1: Configuración!$B$37
Name tau0_2: Configuración!$C$37
Name tau0_3: Configuración!$D$37
Name taumax_1: Configuración!$B$39
Name taumax_2: Configuración!$C$39
Name taumax_3: Configuración!$D$39
Name tol_1: Configuración!$B$38
Name tol_2: Configuración!$C$38
Name tol_3: Configuración!$D$38
Name unidad: Configuración!$B$6
Name ventana: Configuración!$B$15
Name zona_ac: Configuración!$B$20

Sheet Instrucciones
B1: Piloto del autocorrelador · cálculo del número de réplicas
B2: Trabajo práctico · Diseño de Experimentos Avanzados (3008475) · UNAL 2026-II · J. E. Rodríguez Ochoa y S. Zapata Henao · sábado 24 de octubre de 2026
B4: Antes de medir
A5: 1 | B5: Configuración: la posición va en µm y la potencia óptica en µW. Revisar que el haz recorra 2 veces el desplazamiento (retrorreflector: τ = 2Δx/c). Las corrientes ya están puestas según la hoja de pruebas de fábrica: I1 = 5 A (τ0 = 107 fs), I2 = 6 A (76 fs), I3 = 7 A (54 fs).
A6: 2 | B6: Registro piloto: el orden de las 15 trazas ya está sorteado (5 por corriente). Medir en ese orden.
B7: Durante el piloto
A8: 3 | B8: En la hoja Rk (k = número de la traza en el Registro), escribir desde la fila 2 la posición del micrómetro (columna A, en µm) y la potencia óptica (columna B, en µW), una lectura por fila, en orden de posición. Con el montaje actual son unas 20 lecturas (16–17 en la zona de solapamiento y 2 por ala); caben hasta 300. La guía de muestreo (Configuración, numeral 7) da el paso y la posición de las alas para cada corriente.
A9: 4 | B9: Mirar el Estado de la traza (celda M20) y las dos gráficas a la derecha. «OK» = la traza se procesó bien. Un «Aviso» no invalida la traza pero va al informe; un «Revisar» hay que mirarlo antes de seguir.
A10: 5 | B10: En el Registro, anotar la hora de inicio y de fin (hh:mm), la potencia media del láser en mW y, si la traza se descarta por una causa anotada, «No» y la causa.
B11: Al terminar (sábado por la noche)
A12: 6 | B12: Resumen piloto: media, S y CV de τp por corriente y las gráficas de puntos y de τp contra el orden.
A13: 7 | B13: Configuración, numeral 5: llenar los datos del fabricante que se tengan (si no hay ninguno, δ = 10 fs). Revisar también las horas útiles por día.
A14: 8 | B14: Réplicas: el n por corriente sale solo (σ = 1,56·S mayor, δ por la regla, α = 0,05, potencia 0,90). Elegir 3 o 4 días en la celda B37 y revisar si caben y el δ detectable.
A15: 9 | B15: Plan semana: orden sorteado de cada día. Copiarlo como valores a las hojas de registro de la semana.
B16: Cómo se calcula τp en cada traza
A17: · | B17: Retardo τ = (pasos × desplazamiento en metros / c) × 10¹⁵ fs; con 2 pasos, 6,67 fs por cada µm del micrómetro.
A18: · | B18: Se resta el fondo (promedio de los primeros y últimos N puntos), se normaliza al máximo y se buscan los dos cruces a 0,5 más cercanos al pico, interpolando linealmente entre puntos.
A19: · | B19: Δτ_AC = distancia entre los cruces; τp = 0,65 × Δτ_AC (factor de Calmar, sech²). Es el ancho a media altura medido directamente, sin ajuste por mínimos cuadrados. Con 20 lecturas según la guía (≈ 6 dentro del ancho) la simulación da un sesgo de +0,4 a +0,9 fs (igual para todas las trazas de una corriente), frente a una dispersión de 0,7 a 1,6 fs entre trazas.
A20: · | B20: El número de réplicas usa la aproximación normal de la t no central; se comparó con el cálculo exacto (scipy) para d entre 0,3 y 4: da el mismo n en 147 de 148 casos (el otro difiere en 1). Confirmar el resultado final en Minitab.
B21: Colores
A22: · | B22: Amarillo con letra azul = se escribe. Verde = resultado clave. Letra verde = viene de otra hoja. Gris = cálculo intermedio. La hoja Ejemplo tiene una traza manual simulada de 54 fs (7 A) para ver cómo debe quedar.

Sheet Configuración
A1: Configuración del piloto y del cálculo de réplicas
A2: Celdas amarillas con letra azul = se pueden editar. Todo lo demás es fórmula.
A4: Parámetro | B4: Valor | C4: Nota
A5: 1. Conversión del desplazamiento a retardo
A6: Unidad de la posición del micrómetro (columna A de R01–R15) | B6: µm | C6: Fija en µm (p. ej. 12483 para 12,483 mm). La potencia óptica de la columna B va en µW.
A7: Número de veces que el haz recorre el desplazamiento | B7: 2 | C7: 2 = retrorreflector en el brazo móvil (ida y vuelta): τ = 2Δx/c. Usar 4 si el brazo es de doble paso.
A8: Velocidad de la luz c (m/s) | B8: 299792458 | C8: Valor exacto (SI).
A9: Factor de la unidad a metros | B9: =IF(unidad="nm",10^-9,IF(unidad="mm",10^-3,10^-6)) -> 1e-06 | C9: Automático según la unidad.
A10: Retardo por unidad de desplazamiento (fs por unidad) | B10: =pasos*a_metros/c_luz*10^15 -> 6.6712819 | C10: Automático. Con µm y 2 pasos da 6,6713 fs por cada µm del micrómetro.
A12: 2. Lectura del ancho de pulso
A13: Factor de forma: τp = factor × ancho de la traza | B13: 0.65 | C13: 0,65 = el que usa Calmar (sech²; el valor teórico es 0,648). Gaussiano: 0,7071.
A14: Lecturas en cada ala (fuera del solapamiento) para el fondo | B14: 2 | C14: El fondo es el promedio de las primeras y las últimas N lecturas de la traza. Con el montaje actual: 2 por ala, a 2 y 3 Δτ_AC del pico (ver la guía de muestreo).
A15: Ventana de suavizado (puntos, número impar) | B15: 1 | C15: 1 = sin suavizar. Con toma manual (pocos puntos) dejarla en 1: promediar lecturas vecinas ensancha la traza. No cambiarla durante el experimento: es parte del programa de análisis fijo del protocolo.
A16: Semiventana (automático) | B16: =INT((MAX(1,ventana)-1)/2) -> 0 | C16: Puntos a cada lado del promedio móvil.
A17: Lecturas mínimas dentro del ancho a media altura | B17: 5 | C17: Por debajo de esto la interpolación de los cruces pierde precisión: afinar el paso cerca del pico.
A18: Recorrido mínimo a cada lado del centro (múltiplos de Δτ_AC) | B18: 2 | C18: Las lecturas del fondo deben quedar a 2 Δτ_AC o más del centro, donde la autocorrelación sech² es < 0,5 % del pico. Si quedan más cerca, el fondo sale alto y el ancho sale corto (≈ −1,5 fs en simulación).
A19: Lecturas en la zona de solapamiento | B19: 16 | C19: Con el montaje actual caben 16 o 17 lecturas en la zona donde hay solapamiento (señal). Más 2 por ala = 20.
A20: Semiancho de la zona de solapamiento (múltiplos de Δτ_AC) | B20: 1.5 | C20: A ±1,5 Δτ_AC la señal es ≈ 1 % del pico: ahí termina en la práctica el solapamiento.
A21: Resolución de lectura del micrómetro (µm) | B21: 1 | C21: La menor división que se lee con seguridad (con nonio, 1 µm; sin nonio, 10 µm). Solo se usa en la guía de muestreo de abajo.
A23: 3. Corrientes del diseño
A24: Corriente I1 (A) | B24: 5 | C24: Corriente de bombeo del amplificador (AMP pump). Hoja de pruebas de fábrica, tabla 5. Se usan las tres corrientes altas alcanzables: el controlador llega a 7,12 A, así que la fila de 7,23 A queda fuera.
A25: Corriente I2 (A) | B25: 6 | C25: Corriente de bombeo del amplificador (AMP pump). Hoja de pruebas de fábrica, tabla 5. Se usan las tres corrientes altas alcanzables: el controlador llega a 7,12 A, así que la fila de 7,23 A queda fuera.
A26: Corriente I3 (A) | B26: 7 | C26: Corriente de bombeo del amplificador (AMP pump). Hoja de pruebas de fábrica, tabla 5. Se usan las tres corrientes altas alcanzables: el controlador llega a 7,12 A, así que la fila de 7,23 A queda fuera.
A28: 4. Número de réplicas (protocolo, sección 4)
A29: α (riesgo de error tipo I) | B29: 0.05 | C29: Protocolo: 0,05.
A30: Potencia deseada 1 − β | B30: 0.9 | C30: Protocolo: 0,90.
A31: Colas de la prueba (1 o 2) | B31: 2 | C31: 2 si τ0 es un valor medido por el fabricante (cualquier cambio importa); 1 si solo se tiene el máximo garantizado. Con 2 colas el n es algo mayor (más conservador).
A32: Confianza del límite superior de σ | B32: 0.8 | C32: Protocolo: σ = límite superior del 80 % de S (con n = 5 multiplica S por 1,56).
A33: δ por defecto si el fabricante no da ningún dato (fs) | B33: 10 | C33: Protocolo, sección 4, regla 5.
A35: 5. Datos del fabricante para fijar δ (llenar los que existan; ver hoja Réplicas)
A36: Dato | B36: I1 | C36: I2 | D36: I3
A37: τ0: ancho medido por el fabricante (fs) | B37: 107 | C37: 76 | D37: 54
A38: (1) Tolerancia del valor medido t, en τ0 ± t (fs)
A39: (2) Máximo garantizado τmáx (fs) | D39: 80
A40: (3) Semiancho de la banda de aceptación (fs)
A41: (4) Estabilidad declarada del ancho (% rms, p. ej. 2 para 2 %)
A42: Incertidumbre u del fabricante (fs); piso δ ≥ 2u
A43: Referencia: potencia media de fábrica (mW) | B43: 218 | C43: 378 | D43: 579
A44: Fuente: hoja de pruebas de fábrica (tabla 5: 5 A → 107 fs, 6 A → 76 fs, 7 A → 54 fs). La hoja no da tolerancia, banda de aceptación, estabilidad del ancho ni incertidumbre. La estabilidad de 0,40 % rms es de la potencia, no del ancho, y por eso no se usa en la regla 4. τmáx = 80 fs es la especificación de la tabla 4, válida solo en el punto nominal (7,0 A). Ojo: la tabla 4 reporta 70 fs a 7,0 A y la tabla 5 reporta 54 fs a 7 A; se usa la tabla 5 porque da las tres corrientes con el mismo método.
A46: 6. Tiempo disponible para la semana
...

Sheet Registro piloto
A1: Registro del piloto · sábado 24 de octubre de 2026
A2: Orden sorteado (semilla 20261024): 5 réplicas por corriente, 15 trazas. Medir en este orden; la traza N° k se pega en la hoja Rk.
A3: Amarillo = llenar. La duración se toma de la hora de inicio de una traza a la de la siguiente (incluye el cambio de corriente).
A4: N° | B4: Hoja | C4: Corriente | D4: Corriente (A) | E4: Hora inicio | F4: Hora fin | G4: Potencia media del láser (mW) | H4: ¿Válida? | I4: Observaciones (causa si no es válida) | J4: Δτ_AC (fs) | K4: τp (fs) | L4: Estado de la traza
A5: 1 | B5: R01 | C5: I2 | D5: =IF(C5="","",IF(INDEX(corrientes,MATCH(C5,{"I1","I2","I3"},0))="","(falta)",INDEX(corrientes,MATCH(C5,{"I1","I2","I3"},0)))) -> 6 | E5: 0.25625 | F5: 0.26527778 | H5: Sí | J5: =IFERROR('R01'!$M$12+0,"") -> 102.19708 | K5: =IFERROR('R01'!$M$13+0,"") -> 66.428104 | L5: ='R01'!$M$20 -> OK
A6: 2 | B6: R02 | C6: I3 | D6: =IF(C6="","",IF(INDEX(corrientes,MATCH(C6,{"I1","I2","I3"},0))="","(falta)",INDEX(corrientes,MATCH(C6,{"I1","I2","I3"},0)))) -> 7 | E6: 0.27013889 | F6: 0.27777778 | H6: Sí | J6: =IFERROR('R02'!$M$12+0,"") -> 198.20488 | K6: =IFERROR('R02'!$M$13+0,"") -> 128.83317 | L6: ='R02'!$M$20 -> Aviso: pocas lecturas dentro del ancho; afinar el paso cerca del pico
A7: 3 | B7: R03 | C7: I3 | D7: =IF(C7="","",IF(INDEX(corrientes,MATCH(C7,{"I1","I2","I3"},0))="","(falta)",INDEX(corrientes,MATCH(C7,{"I1","I2","I3"},0)))) -> 7 | E7: 0.27916667 | F7: 0.28333333 | H7: Sí | J7: =IFERROR('R03'!$M$12+0,"") -> 253.72721 | K7: =IFERROR('R03'!$M$13+0,"") -> 164.92269 | L7: ='R03'!$M$20 -> Aviso: pocas lecturas dentro del ancho; afinar el paso cerca del pico
A8: 4 | B8: R04 | C8: I2 | D8: =IF(C8="","",IF(INDEX(corrientes,MATCH(C8,{"I1","I2","I3"},0))="","(falta)",INDEX(corrientes,MATCH(C8,{"I1","I2","I3"},0)))) -> 6 | E8: 0.28402778 | F8: 0.2875 | H8: Sí | J8: =IFERROR('R04'!$M$12+0,"") -> 249.691 | K8: =IFERROR('R04'!$M$13+0,"") -> 162.29915 | L8: ='R04'!$M$20 -> Aviso: pocas lecturas dentro del ancho; afinar el paso cerca del pico
A9: 5 | B9: R05 | C9: I3 | D9: =IF(C9="","",IF(INDEX(corrientes,MATCH(C9,{"I1","I2","I3"},0))="","(falta)",INDEX(corrientes,MATCH(C9,{"I1","I2","I3"},0)))) -> 7 | E9: 0.2875 | F9: 0.29236111 | H9: Sí | J9: =IFERROR('R05'!$M$12+0,"") -> 249.30127 | K9: =IFERROR('R05'!$M$13+0,"") -> 162.04582 | L9: ='R05'!$M$20 -> Aviso: pocas lecturas dentro del ancho; afinar el paso cerca del pico
A10: 6 | B10: R06 | C10: I2 | D10: =IF(C10="","",IF(INDEX(corrientes,MATCH(C10,{"I1","I2","I3"},0))="","(falta)",INDEX(corrientes,MATCH(C10,{"I1","I2","I3"},0)))) -> 6 | E10: 0.29305556 | F10: 0.29583333 | H10: Sí | J10: =IFERROR('R06'!$M$12+0,"") -> 238.59705 | K10: =IFERROR('R06'!$M$13+0,"") -> 155.08808 | L10: ='R06'!$M$20 -> Aviso: pocas lecturas dentro del ancho; afinar el paso cerca del pico
A11: 7 | B11: R07 | C11: I2 | D11: =IF(C11="","",IF(INDEX(corrientes,MATCH(C11,{"I1","I2","I3"},0))="","(falta)",INDEX(corrientes,MATCH(C11,{"I1","I2","I3"},0)))) -> 6 | E11: 0.29652778 | H11: Sí | J11: =IFERROR('R07'!$M$12+0,"") | K11: =IFERROR('R07'!$M$13+0,"") | L11: ='R07'!$M$20 -> Revisar: columnas A y B con distinto número de datos
A12: 8 | B12: R08 | C12: I3 | D12: =IF(C12="","",IF(INDEX(corrientes,MATCH(C12,{"I1","I2","I3"},0))="","(falta)",INDEX(corrientes,MATCH(C12,{"I1","I2","I3"},0)))) -> 7 | E12: 0.29930556 | F12: 0.30277778 | H12: Sí | J12: =IFERROR('R08'!$M$12+0,"") -> 243.95337 | K12: =IFERROR('R08'!$M$13+0,"") -> 158.56969 | L12: ='R08'!$M$20 -> Aviso: pocas lecturas dentro del ancho; afinar el paso cerca del pico
A13: 9 | B13: R09 | C13: I1 | D13: =IF(C13="","",IF(INDEX(corrientes,MATCH(C13,{"I1","I2","I3"},0))="","(falta)",INDEX(corrientes,MATCH(C13,{"I1","I2","I3"},0)))) -> 5 | E13: 0.30347222 | F13: 0.30555556 | H13: Sí | J13: =IFERROR('R09'!$M$12+0,"") -> 314.33869 | K13: =IFERROR('R09'!$M$13+0,"") -> 204.32015 | L13: ='R09'!$M$20 -> Aviso: el barrido no llega a las alas
A14: 10 | B14: R10 | C14: I1 | D14: =IF(C14="","",IF(INDEX(corrientes,MATCH(C14,{"I1","I2","I3"},0))="","(falta)",INDEX(corrientes,MATCH(C14,{"I1","I2","I3"},0)))) -> 5 | E14: 0.30625 | F14: 0.30972222 | H14: Sí | J14: =IFERROR('R10'!$M$12+0,"") -> 303.93009 | K14: =IFERROR('R10'!$M$13+0,"") -> 197.55456 | L14: ='R10'!$M$20 -> Aviso: pocas lecturas dentro del ancho; afinar el paso cerca del pico
A15: 11 | B15: R11 | C15: I1 | D15: =IF(C15="","",IF(INDEX(corrientes,MATCH(C15,{"I1","I2","I3"},0))="","(falta)",INDEX(corrientes,MATCH(C15,{"I1","I2","I3"},0)))) -> 5 | E15: 0.31041667 | F15: 0.3125 | H15: Sí | J15: =IFERROR('R11'!$M$12+0,"") -> 306.56248 | K15: =IFERROR('R11'!$M$13+0,"") -> 199.26561 | L15: ='R11'!$M$20 -> Aviso: el barrido no llega a las alas
A16: 12 | B16: R12 | C16: I1 | D16: =IF(C16="","",IF(INDEX(corrientes,MATCH(C16,{"I1","I2","I3"},0))="","(falta)",INDEX(corrientes,MATCH(C16,{"I1","I2","I3"},0)))) -> 5 | E16: 0.31319444 | F16: 0.31736111 | H16: Sí | J16: =IFERROR('R12'!$M$12+0,"") -> 314.88611 | K16: =IFERROR('R12'!$M$13+0,"") -> 204.67597 | L16: ='R12'!$M$20 -> Aviso: el barrido no llega a las alas
A17: 13 | B17: R13 | C17: I3 | D17: =IF(C17="","",IF(INDEX(corrientes,MATCH(C17,{"I1","I2","I3"},0))="","(falta)",INDEX(corrientes,MATCH(C17,{"I1","I2","I3"},0)))) -> 7 | E17: 0.31805556 | F17: 0.32291667 | H17: Sí | J17: =IFERROR('R13'!$M$12+0,"") -> 237.27131 | K17: =IFERROR('R13'!$M$13+0,"") -> 154.22635 | L17: ='R13'!$M$20 -> Aviso: pocas lecturas dentro del ancho; afinar el paso cerca del pico
A18: 14 | B18: R14 | C18: I1 | D18: =IF(C18="","",IF(INDEX(corrientes,MATCH(C18,{"I1","I2","I3"},0))="","(falta)",INDEX(corrientes,MATCH(C18,{"I1","I2","I3"},0)))) -> 5 | E18: 0.32361111 | F18: 0.32847222 | H18: Sí | J18: =IFERROR('R14'!$M$12+0,"") -> 307.0489 | K18: =IFERROR('R14'!$M$13+0,"") -> 199.58178 | L18: ='R14'!$M$20 -> Aviso: el barrido no llega a las alas
A19: 15 | B19: R15 | C19: I2 | D19: =IF(C19="","",IF(INDEX(corrientes,MATCH(C19,{"I1","I2","I3"},0))="","(falta)",INDEX(corrientes,MATCH(C19,{"I1","I2","I3"},0)))) -> 6 | E19: 0.32916667 | H19: Sí | J19: =IFERROR('R15'!$M$12+0,"") -> 238.09426 | K19: =IFERROR('R15'!$M$13+0,"") -> 154.76127 | L19: ='R15'!$M$20 -> Aviso: pocas lecturas dentro del ancho; afinar el paso cerca del pico
A21: Nota: R02 a R07 Descartar | I21: Duración media por traza (min) | J21: =IF(COUNT(E5:E19)<2,"",(MAX(E5:E19)-MIN(E5:E19))*1440/(COUNT(E5:E19)-1)) -> 7.5 | K21: entre inicios consecutivos
I22: Duración media de la toma sola (min) | J22: =IF(COUNT(F5:F19)=0,"",SUMPRODUCT((F5:F19>0)*(E5:E19>0)*(F5:F19-E5:E19))*1440/SUMPRODUCT((F5:F19>0)*(E5:E19>0))) -> 6.3076923 | K22: de inicio a fin de cada traza
A24: Reglas del protocolo (sección 5): una traza solo se marca «No» por una causa anotada en el momento (el láser perdió los pulsos, la potencia salió del rango o el barrido se interrumpió). Nunca por dar un valor inesperado. Toda traza descartada se repone con una nueva (pegarla en la misma hoja y anotarlo).

Sheet Resumen piloto
A1: Resumen del piloto por corriente
A2: Solo cuentan las trazas con τp calculado y marcadas «Sí» en el Registro.
A4: N° | B4: Corriente | C4: τp usable (fs) | D4: (τp − media)² | E4: Orden | G4: x I1 | H4: τp I1 | I4: x I2 | J4: τp I2 | K4: x I3 | L4: τp I3
A5: ='Registro piloto'!A5 -> 1 | B5: ='Registro piloto'!C5 -> I2 | C5: =IF(AND(ISNUMBER('Registro piloto'!K5),'Registro piloto'!H5<>"No"),'Registro piloto'!K5,"") -> 66.428104 | D5: =IF(ISNUMBER(C5),(C5-INDEX($C$22:$C$24,MATCH(B5,$A$22:$A$24,0)))^2,0) -> 4653.4293 | E5: =A5 -> 1 | G5: =IF(AND(B5="I1",ISNUMBER(C5)),1,NA()) -> #N/A | H5: =IF(AND(B5="I1",ISNUMBER(C5)),C5,NA()) -> #N/A | I5: =IF(AND(B5="I2",ISNUMBER(C5)),2,NA()) -> 2 | J5: =IF(AND(B5="I2",ISNUMBER(C5)),C5,NA()) -> 66.428104 | K5: =IF(AND(B5="I3",ISNUMBER(C5)),3,NA()) -> #N/A | L5: =IF(AND(B5="I3",ISNUMBER(C5)),C5,NA()) -> #N/A
A6: ='Registro piloto'!A6 -> 2 | B6: ='Registro piloto'!C6 -> I3 | C6: =IF(AND(ISNUMBER('Registro piloto'!K6),'Registro piloto'!H6<>"No"),'Registro piloto'!K6,"") -> 128.83317 | D6: =IF(ISNUMBER(C6),(C6-INDEX($C$22:$C$24,MATCH(B6,$A$22:$A$24,0)))^2,0) -> 619.3317 | E6: =A6 -> 2 | G6: =IF(AND(B6="I1",ISNUMBER(C6)),1,NA()) -> #N/A | H6: =IF(AND(B6="I1",ISNUMBER(C6)),C6,NA()) -> #N/A | I6: =IF(AND(B6="I2",ISNUMBER(C6)),2,NA()) -> #N/A | J6: =IF(AND(B6="I2",ISNUMBER(C6)),C6,NA()) -> #N/A | K6: =IF(AND(B6="I3",ISNUMBER(C6)),3,NA()) -> 3 | L6: =IF(AND(B6="I3",ISNUMBER(C6)),C6,NA()) -> 128.83317
A7: ='Registro piloto'!A7 -> 3 | B7: ='Registro piloto'!C7 -> I3 | C7: =IF(AND(ISNUMBER('Registro piloto'!K7),'Registro piloto'!H7<>"No"),'Registro piloto'!K7,"") -> 164.92269 | D7: =IF(ISNUMBER(C7),(C7-INDEX($C$22:$C$24,MATCH(B7,$A$22:$A$24,0)))^2,0) -> 125.51041 | E7: =A7 -> 3 | G7: =IF(AND(B7="I1",ISNUMBER(C7)),1,NA()) -> #N/A | H7: =IF(AND(B7="I1",ISNUMBER(C7)),C7,NA()) -> #N/A | I7: =IF(AND(B7="I2",ISNUMBER(C7)),2,NA()) -> #N/A | J7: =IF(AND(B7="I2",ISNUMBER(C7)),C7,NA()) -> #N/A | K7: =IF(AND(B7="I3",ISNUMBER(C7)),3,NA()) -> 3 | L7: =IF(AND(B7="I3",ISNUMBER(C7)),C7,NA()) -> 164.92269
A8: ='Registro piloto'!A8 -> 4 | B8: ='Registro piloto'!C8 -> I2 | C8: =IF(AND(ISNUMBER('Registro piloto'!K8),'Registro piloto'!H8<>"No"),'Registro piloto'!K8,"") -> 162.29915 | D8: =IF(ISNUMBER(C8),(C8-INDEX($C$22:$C$24,MATCH(B8,$A$22:$A$24,0)))^2,0) -> 764.79906 | E8: =A8 -> 4 | G8: =IF(AND(B8="I1",ISNUMBER(C8)),1,NA()) -> #N/A | H8: =IF(AND(B8="I1",ISNUMBER(C8)),C8,NA()) -> #N/A | I8: =IF(AND(B8="I2",ISNUMBER(C8)),2,NA()) -> 2 | J8: =IF(AND(B8="I2",ISNUMBER(C8)),C8,NA()) -> 162.29915 | K8: =IF(AND(B8="I3",ISNUMBER(C8)),3,NA()) -> #N/A | L8: =IF(AND(B8="I3",ISNUMBER(C8)),C8,NA()) -> #N/A
A9: ='Registro piloto'!A9 -> 5 | B9: ='Registro piloto'!C9 -> I3 | C9: =IF(AND(ISNUMBER('Registro piloto'!K9),'Registro piloto'!H9<>"No"),'Registro piloto'!K9,"") -> 162.04582 | D9: =IF(ISNUMBER(C9),(C9-INDEX($C$22:$C$24,MATCH(B9,$A$22:$A$24,0)))^2,0) -> 69.32693 | E9: =A9 -> 5 | G9: =IF(AND(B9="I1",ISNUMBER(C9)),1,NA()) -> #N/A | H9: =IF(AND(B9="I1",ISNUMBER(C9)),C9,NA()) -> #N/A | I9: =IF(AND(B9="I2",ISNUMBER(C9)),2,NA()) -> #N/A | J9: =IF(AND(B9="I2",ISNUMBER(C9)),C9,NA()) -> #N/A | K9: =IF(AND(B9="I3",ISNUMBER(C9)),3,NA()) -> 3 | L9: =IF(AND(B9="I3",ISNUMBER(C9)),C9,NA()) -> 162.04582
A10: ='Registro piloto'!A10 -> 6 | B10: ='Registro piloto'!C10 -> I2 | C10: =IF(AND(ISNUMBER('Registro piloto'!K10),'Registro piloto'!H10<>"No"),'Registro piloto'!K10,"") -> 155.08808 | D10: =IF(ISNUMBER(C10),(C10-INDEX($C$22:$C$24,MATCH(B10,$A$22:$A$24,0)))^2,0) -> 417.95436 | E10: =A10 -> 6 | G10: =IF(AND(B10="I1",ISNUMBER(C10)),1,NA()) -> #N/A | H10: =IF(AND(B10="I1",ISNUMBER(C10)),C10,NA()) -> #N/A | I10: =IF(AND(B10="I2",ISNUMBER(C10)),2,NA()) -> 2 | J10: =IF(AND(B10="I2",ISNUMBER(C10)),C10,NA()) -> 155.08808 | K10: =IF(AND(B10="I3",ISNUMBER(C10)),3,NA()) -> #N/A | L10: =IF(AND(B10="I3",ISNUMBER(C10)),C10,NA()) -> #N/A
A11: ='Registro piloto'!A11 -> 7 | B11: ='Registro piloto'!C11 -> I2 | C11: =IF(AND(ISNUMBER('Registro piloto'!K11),'Registro piloto'!H11<>"No"),'Registro piloto'!K11,"") | D11: =IF(ISNUMBER(C11),(C11-INDEX($C$22:$C$24,MATCH(B11,$A$22:$A$24,0)))^2,0) -> 0 | E11: =A11 -> 7 | G11: =IF(AND(B11="I1",ISNUMBER(C11)),1,NA()) -> #N/A | H11: =IF(AND(B11="I1",ISNUMBER(C11)),C11,NA()) -> #N/A | I11: =IF(AND(B11="I2",ISNUMBER(C11)),2,NA()) -> #N/A | J11: =IF(AND(B11="I2",ISNUMBER(C11)),C11,NA()) -> #N/A | K11: =IF(AND(B11="I3",ISNUMBER(C11)),3,NA()) -> #N/A | L11: =IF(AND(B11="I3",ISNUMBER(C11)),C11,NA()) -> #N/A
A12: ='Registro piloto'!A12 -> 8 | B12: ='Registro piloto'!C12 -> I3 | C12: =IF(AND(ISNUMBER('Registro piloto'!K12),'Registro piloto'!H12<>"No"),'Registro piloto'!K12,"") -> 158.56969 | D12: =IF(ISNUMBER(C12),(C12-INDEX($C$22:$C$24,MATCH(B12,$A$22:$A$24,0)))^2,0) -> 23.523932 | E12: =A12 -> 8 | G12: =IF(AND(B12="I1",ISNUMBER(C12)),1,NA()) -> #N/A | H12: =IF(AND(B12="I1",ISNUMBER(C12)),C12,NA()) -> #N/A | I12: =IF(AND(B12="I2",ISNUMBER(C12)),2,NA()) -> #N/A | J12: =IF(AND(B12="I2",ISNUMBER(C12)),C12,NA()) -> #N/A | K12: =IF(AND(B12="I3",ISNUMBER(C12)),3,NA()) -> 3 | L12: =IF(AND(B12="I3",ISNUMBER(C12)),C12,NA()) -> 158.56969
A13: ='Registro piloto'!A13 -> 9 | B13: ='Registro piloto'!C13 -> I1 | C13: =IF(AND(ISNUMBER('Registro piloto'!K13),'Registro piloto'!H13<>"No"),'Registro piloto'!K13,"") -> 204.32015 | D13: =IF(ISNUMBER(C13),(C13-INDEX($C$22:$C$24,MATCH(B13,$A$22:$A$24,0)))^2,0) -> 10.501037 | E13: =A13 -> 9 | G13: =IF(AND(B13="I1",ISNUMBER(C13)),1,NA()) -> 1 | H13: =IF(AND(B13="I1",ISNUMBER(C13)),C13,NA()) -> 204.32015 | I13: =IF(AND(B13="I2",ISNUMBER(C13)),2,NA()) -> #N/A | J13: =IF(AND(B13="I2",ISNUMBER(C13)),C13,NA()) -> #N/A | K13: =IF(AND(B13="I3",ISNUMBER(C13)),3,NA()) -> #N/A | L13: =IF(AND(B13="I3",ISNUMBER(C13)),C13,NA()) -> #N/A
A14: ='Registro piloto'!A14 -> 10 | B14: ='Registro piloto'!C14 -> I1 | C14: =IF(AND(ISNUMBER('Registro piloto'!K14),'Registro piloto'!H14<>"No"),'Registro piloto'!K14,"") -> 197.55456 | D14: =IF(ISNUMBER(C14),(C14-INDEX($C$22:$C$24,MATCH(B14,$A$22:$A$24,0)))^2,0) -> 12.42602 | E14: =A14 -> 10 | G14: =IF(AND(B14="I1",ISNUMBER(C14)),1,NA()) -> 1 | H14: =IF(AND(B14="I1",ISNUMBER(C14)),C14,NA()) -> 197.55456 | I14: =IF(AND(B14="I2",ISNUMBER(C14)),2,NA()) -> #N/A | J14: =IF(AND(B14="I2",ISNUMBER(C14)),C14,NA()) -> #N/A | K14: =IF(AND(B14="I3",ISNUMBER(C14)),3,NA()) -> #N/A | L14: =IF(AND(B14="I3",ISNUMBER(C14)),C14,NA()) -> #N/A
A15: ='Registro piloto'!A15 -> 11 | B15: ='Registro piloto'!C15 -> I1 | C15: =IF(AND(ISNUMBER('Registro piloto'!K15),'Registro piloto'!H15<>"No"),'Registro piloto'!K15,"") -> 199.26561 | D15: =IF(ISNUMBER(C15),(C15-INDEX($C$22:$C$24,MATCH(B15,$A$22:$A$24,0)))^2,0) -> 3.2906015 | E15: =A15 -> 11 | G15: =IF(AND(B15="I1",ISNUMBER(C15)),1,NA()) -> 1 | H15: =IF(AND(B15="I1",ISNUMBER(C15)),C15,NA()) -> 199.26561 | I15: =IF(AND(B15="I2",ISNUMBER(C15)),2,NA()) -> #N/A | J15: =IF(AND(B15="I2",ISNUMBER(C15)),C15,NA()) -> #N/A | K15: =IF(AND(B15="I3",ISNUMBER(C15)),3,NA()) -> #N/A | L15: =IF(AND(B15="I3",ISNUMBER(C15)),C15,NA()) -> #N/A
A16: ='Registro piloto'!A16 -> 12 | B16: ='Registro piloto'!C16 -> I1 | C16: =IF(AND(ISNUMBER('Registro piloto'!K16),'Registro piloto'!H16<>"No"),'Registro piloto'!K16,"") -> 204.67597 | D16: =IF(ISNUMBER(C16),(C16-INDEX($C$22:$C$24,MATCH(B16,$A$22:$A$24,0)))^2,0) -> 12.933797 | E16: =A16 -> 12 | G16: =IF(AND(B16="I1",ISNUMBER(C16)),1,NA()) -> 1 | H16: =IF(AND(B16="I1",ISNUMBER(C16)),C16,NA()) -> 204.67597 | I16: =IF(AND(B16="I2",ISNUMBER(C16)),2,NA()) -> #N/A | J16: =IF(AND(B16="I2",ISNUMBER(C16)),C16,NA()) -> #N/A | K16: =IF(AND(B16="I3",ISNUMBER(C16)),3,NA()) -> #N/A | L16: =IF(AND(B16="I3",ISNUMBER(C16)),C16,NA()) -> #N/A
... A19: ='Registro piloto'!A19 -> 15 | B19: ='Registro piloto'!C19 -> I2 | C19: =IF(AND(ISNUMBER('Registro piloto'!K19),'Registro piloto'!H19<>"No"),'Registro piloto'!K19,"") -> 154.76127 | D19: =IF(ISNUMBER(C19),(C19-INDEX($C$22:$C$24,MATCH(B19,$A$22:$A$24,0)))^2,0) -> 404.69835 | E19: =A19 -> 15 | G19: =IF(AND(B19="I1",ISNUMBER(C19)),1,NA()) -> #N/A | H19: =IF(AND(B19="I1",ISNUMBER(C19)),C19,NA()) -> #N/A | I19: =IF(AND(B19="I2",ISNUMBER(C19)),2,NA()) -> 2 | J19: =IF(AND(B19="I2",ISNUMBER(C19)),C19,NA()) -> 154.76127 | K19: =IF(AND(B19="I3",ISNUMBER(C19)),3,NA()) -> #N/A | L19: =IF(AND(B19="I3",ISNUMBER(C19)),C19,NA()) -> #N/A
G20: Columnas G:L: solo alimentan las gráficas (#N/A = punto que no se dibuja).
A21: Corriente | B21: n | C21: Media τp (fs) | D21: S (fs) | E21: CV (%) | G21: Corriente (A) | H21: τ0 fábrica (fs) | I21: Media − τ0 (fs) | J21: x
A22: I1 | B22: =COUNTIFS($B$5:$B$19,A22,$C$5:$C$19,">0") -> 5 | C22: =IF(B22=0,"",AVERAGEIFS($C$5:$C$19,$B$5:$B$19,A22)) -> 201.07962 | D22: =IF(B22<2,"",SQRT(SUMIFS($D$5:$D$19,$B$5:$B$19,A22)/(B22-1))) -> 3.2169456 | E22: =IF(ISNUMBER(D22),100*D22/C22,"") -> 1.5998367 | G22: =IF(I1_A="","",I1_A) -> 5 | H22: =IF(ISNUMBER(tau0_1),tau0_1,NA()) -> 107 | I22: =IF(AND(ISNUMBER(C22),ISNUMBER(H22)),C22-H22,"") -> 94.079615 | J22: 1
A23: I2 | B23: =COUNTIFS($B$5:$B$19,A23,$C$5:$C$19,">0") -> 4 | C23: =IF(B23=0,"",AVERAGEIFS($C$5:$C$19,$B$5:$B$19,A23)) -> 134.64415 | D23: =IF(B23<2,"",SQRT(SUMIFS($D$5:$D$19,$B$5:$B$19,A23)/(B23-1))) -> 45.610237 | E23: =IF(ISNUMBER(D23),100*D23/C23,"") -> 33.874651 | G23: =IF(I2_A="","",I2_A) -> 6 | H23: =IF(ISNUMBER(tau0_2),tau0_2,NA()) -> 76 | I23: =IF(AND(ISNUMBER(C23),ISNUMBER(H23)),C23-H23,"") -> 58.644152 | J23: 2
A24: I3 | B24: =COUNTIFS($B$5:$B$19,A24,$C$5:$C$19,">0") -> 5 | C24: =IF(B24=0,"",AVERAGEIFS($C$5:$C$19,$B$5:$B$19,A24)) -> 153.71955 | D24: =IF(B24<2,"",SQRT(SUMIFS($D$5:$D$19,$B$5:$B$19,A24)/(B24-1))) -> 14.473681 | E24: =IF(ISNUMBER(D24),100*D24/C24,"") -> 9.4156416 | G24: =IF(I3_A="","",I3_A) -> 7 | H24: =IF(ISNUMBER(tau0_3),tau0_3,NA()) -> 54 | I24: =IF(AND(ISNUMBER(C24),ISNUMBER(H24)),C24-H24,"") -> 99.719545 | J24: 3
A25: Con solo 5 datos por corriente no se prueba normalidad: el piloto solo estima S. La normalidad se revisa con los datos de la semana (protocolo, sección 6).

Sheet Réplicas
A1: Número de réplicas de la semana (protocolo, sección 4)
A2: Todo es automático. Celdas verdes = resultados clave. Montgomery, sec. 2-4.2 y curvas OC (apéndice V).
I3: Curva OC numérica: potencia de la t de una muestra (aproximación normal de la t no central)
A4: Paso 1 · σ conservadora | B4: I1 | C4: I2 | D4: I3 | E4: Usado | I4: n | J4: ν | K4: t crítico | L4: λ = d√n | M4: Potencia | N4: n si ≥ 1−β | O4: d₀ | P4: d₁ | Q4: d₂ | R4: d₃ | S4: d_det
A5: n del piloto (trazas válidas) | B5: =n_I1 -> 5 | C5: =n_I2 -> 4 | D5: =n_I3 -> 5 | I5: 2 | J5: =I5-1 -> 1 | K5: =IF(colas=2,TINV(alfa,J5),TINV(2*alfa,J5)) -> 12.706205 | L5: =IF(ISNUMBER($E$19),$E$19*SQRT(I5),"") -> 0.1794786 | M5: =IF(ISNUMBER($E$19),((1-NORMSDIST((K5*(1-1/(4*J5))-($E$19)*SQRT(I5))/SQRT(1+K5^2/(2*J5))))+IF(colas=2,NORMSDIST((-K5*(1-1/(4*J5))-($E$19)*SQRT(I5))/SQRT(1+K5^2/(2*J5))),0)),"") -> 0.29190893 | N5: =IF(ISNUMBER(M5),IF(M5>=potencia,I5,""),"") | O5: =(K5+TINV(2*(1-potencia),J5))/SQRT(I5) -> 11.160894 | P5: =IFERROR(O5-(((1-NORMSDIST((K5*(1-1/(4*J5))-(O5)*SQRT(I5))/SQRT(1+K5^2/(2*J5))))+IF(colas=2,NORMSDIST((-K5*(1-1/(4*J5))-(O5)*SQRT(I5))/SQRT(1+K5^2/(2*J5))),0))-potencia)/((((1-NORMSDIST((K5*(1-1/(4*J5))-(O5+(0.001*O5))*SQRT(I5))/SQRT(1+K5^2/(2*J5))))+IF(colas=2,NORMSDIST((-K5*(1-1/(4*J5))-(O5+(0.001*O5))*SQRT(I5))/SQRT(1+K5^2/(2*J5))),0))-((1-NORMSDIST((K5*(1-1/(4*J5))-(O5-(0.001*O5))*SQRT(I5))/SQRT(1+K5^2/(2*J5))))+IF(colas=2,NORMSDIST((-K5*(1-1/(4*J5))-(O5-(0.001*O5))*SQRT(I5))/SQRT(1+K5^2/(2*J5))),0)))/(2*(0.001*O5))),O5) -> 14.125419 | Q5: =IFERROR(P5-(((1-NORMSDIST((K5*(1-1/(4*J5))-(P5)*SQRT(I5))/SQRT(1+K5^2/(2*J5))))+IF(colas=2,NORMSDIST((-K5*(1-1/(4*J5))-(P5)*SQRT(I5))/SQRT(1+K5^2/(2*J5))),0))-potencia)/((((1-NORMSDIST((K5*(1-1/(4*J5))-(P5+(0.001*P5))*SQRT(I5))/SQRT(1+K5^2/(2*J5))))+IF(colas=2,NORMSDIST((-K5*(1-1/(4*J5))-(P5+(0.001*P5))*SQRT(I5))/SQRT(1+K5^2/(2*J5))),0))-((1-NORMSDIST((K5*(1-1/(4*J5))-(P5-(0.001*P5))*SQRT(I5))/SQRT(1+K5^2/(2*J5))))+IF(colas=2,NORMSDIST((-K5*(1-1/(4*J5))-(P5-(0.001*P5))*SQRT(I5))/SQRT(1+K5^2/(2*J5))),0)))/(2*(0.001*P5))),P5) -> 14.862646 | R5: =IFERROR(Q5-(((1-NORMSDIST((K5*(1-1/(4*J5))-(Q5)*SQRT(I5))/SQRT(1+K5^2/(2*J5))))+IF(colas=2,NORMSDIST((-K5*(1-1/(4*J5))-(Q5)*SQRT(I5))/SQRT(1+K5^2/(2*J5))),0))-potencia)/((((1-NORMSDIST((K5*(1-1/(4*J5))-(Q5+(0.001*Q5))*SQRT(I5))/SQRT(1+K5^2/(2*J5))))+IF(colas=2,NORMSDIST((-K5*(1-1/(4*J5))-(Q5+(0.001*Q5))*SQRT(I5))/SQRT(1+K5^2/(2*J5))),0))-((1-NORMSDIST((K5*(1-1/(4*J5))-(Q5-(0.001*Q5))*SQRT(I5))/SQRT(1+K5^2/(2*J5))))+IF(colas=2,NORMSDIST((-K5*(1-1/(4*J5))-(Q5-(0.001*Q5))*SQRT(I5))/SQRT(1+K5^2/(2*J5))),0)))/(2*(0.001*Q5))),Q5) -> 14.917475 | S5: =R5 -> 14.917475
A6: S del piloto (fs) | B6: =IF(ISNUMBER(S_I1),S_I1,"") -> 3.2169456 | C6: =IF(ISNUMBER(S_I2),S_I2,"") -> 45.610237 | D6: =IF(ISNUMBER(S_I3),S_I3,"") -> 14.473681 | E6: =IF(COUNT(B6:D6)=0,"",MAX(B6:D6)) -> 45.610237 | I6: 3 | J6: =I6-1 -> 2 | K6: =IF(colas=2,TINV(alfa,J6),TINV(2*alfa,J6)) -> 4.3026527 | L6: =IF(ISNUMBER($E$19),$E$19*SQRT(I6),"") -> 0.21981549 | M6: =IF(ISNUMBER($E$19),((1-NORMSDIST((K6*(1-1/(4*J6))-($E$19)*SQRT(I6))/SQRT(1+K6^2/(2*J6))))+IF(colas=2,NORMSDIST((-K6*(1-1/(4*J6))-($E$19)*SQRT(I6))/SQRT(1+K6^2/(2*J6))),0)),"") -> 0.11406961 | N6: =IF(ISNUMBER(M6),IF(M6>=potencia,I6,""),"") | O6: =(K6+TINV(2*(1-potencia),J6))/SQRT(I6) -> 3.5727998 | P6: =IFERROR(O6-(((1-NORMSDIST((K6*(1-1/(4*J6))-(O6)*SQRT(I6))/SQRT(1+K6^2/(2*J6))))+IF(colas=2,NORMSDIST((-K6*(1-1/(4*J6))-(O6)*SQRT(I6))/SQRT(1+K6^2/(2*J6))),0))-potencia)/((((1-NORMSDIST((K6*(1-1/(4*J6))-(O6+(0.001*O6))*SQRT(I6))/SQRT(1+K6^2/(2*J6))))+IF(colas=2,NORMSDIST((-K6*(1-1/(4*J6))-(O6+(0.001*O6))*SQRT(I6))/SQRT(1+K6^2/(2*J6))),0))-((1-NORMSDIST((K6*(1-1/(4*J6))-(O6-(0.001*O6))*SQRT(I6))/SQRT(1+K6^2/(2*J6))))+IF(colas=2,NORMSDIST((-K6*(1-1/(4*J6))-(O6-(0.001*O6))*SQRT(I6))/SQRT(1+K6^2/(2*J6))),0)))/(2*(0.001*O6))),O6) -> 3.8823186 | Q6: =IFERROR(P6-(((1-NORMSDIST((K6*(1-1/(4*J6))-(P6)*SQRT(I6))/SQRT(1+K6^2/(2*J6))))+IF(colas=2,NORMSDIST((-K6*(1-1/(4*J6))-(P6)*SQRT(I6))/SQRT(1+K6^2/(2*J6))),0))-potencia)/((((1-NORMSDIST((K6*(1-1/(4*J6))-(P6+(0.001*P6))*SQRT(I6))/SQRT(1+K6^2/(2*J6))))+IF(colas=2,NORMSDIST((-K6*(1-1/(4*J6))-(P6+(0.001*P6))*SQRT(I6))/SQRT(1+K6^2/(2*J6))),0))-((1-NORMSDIST((K6*(1-1/(4*J6))-(P6-(0.001*P6))*SQRT(I6))/SQRT(1+K6^2/(2*J6))))+IF(colas=2,NORMSDIST((-K6*(1-1/(4*J6))-(P6-(0.001*P6))*SQRT(I6))/SQRT(1+K6^2/(2*J6))),0)))/(2*(0.001*P6))),P6) -> 3.9279407 | R6: =IFERROR(Q6-(((1-NORMSDIST((K6*(1-1/(4*J6))-(Q6)*SQRT(I6))/SQRT(1+K6^2/(2*J6))))+IF(colas=2,NORMSDIST((-K6*(1-1/(4*J6))-(Q6)*SQRT(I6))/SQRT(1+K6^2/(2*J6))),0))-potencia)/((((1-NORMSDIST((K6*(1-1/(4*J6))-(Q6+(0.001*Q6))*SQRT(I6))/SQRT(1+K6^2/(2*J6))))+IF(colas=2,NORMSDIST((-K6*(1-1/(4*J6))-(Q6+(0.001*Q6))*SQRT(I6))/SQRT(1+K6^2/(2*J6))),0))-((1-NORMSDIST((K6*(1-1/(4*J6))-(Q6-(0.001*Q6))*SQRT(I6))/SQRT(1+K6^2/(2*J6))))+IF(colas=2,NORMSDIST((-K6*(1-1/(4*J6))-(Q6-(0.001*Q6))*SQRT(I6))/SQRT(1+K6^2/(2*J6))),0)))/(2*(0.001*Q6))),Q6) -> 3.928924 | S6: =R6 -> 3.928924
A7: Corriente con la S mayor | E7: =IF(ISNUMBER(E6),INDEX($B$4:$D$4,MATCH(E6,B6:D6,0)),"") -> I2 | I7: 4 | J7: =I7-1 -> 3 | K7: =IF(colas=2,TINV(alfa,J7),TINV(2*alfa,J7)) -> 3.1824463 | L7: =IF(ISNUMBER($E$19),$E$19*SQRT(I7),"") -> 0.25382107 | M7: =IF(ISNUMBER($E$19),((1-NORMSDIST((K7*(1-1/(4*J7))-($E$19)*SQRT(I7))/SQRT(1+K7^2/(2*J7))))+IF(colas=2,NORMSDIST((-K7*(1-1/(4*J7))-($E$19)*SQRT(I7))/SQRT(1+K7^2/(2*J7))),0)),"") -> 0.078679343 | N7: =IF(ISNUMBER(M7),IF(M7>=potencia,I7,""),"") | O7: =(K7+TINV(2*(1-potencia),J7))/SQRT(I7) -> 2.4100953 | P7: =IFERROR(O7-(((1-NORMSDIST((K7*(1-1/(4*J7))-(O7)*SQRT(I7))/SQRT(1+K7^2/(2*J7))))+IF(colas=2,NORMSDIST((-K7*(1-1/(4*J7))-(O7)*SQRT(I7))/SQRT(1+K7^2/(2*J7))),0))-potencia)/((((1-NORMSDIST((K7*(1-1/(4*J7))-(O7+(0.001*O7))*SQRT(I7))/SQRT(1+K7^2/(2*J7))))+IF(colas=2,NORMSDIST((-K7*(1-1/(4*J7))-(O7+(0.001*O7))*SQRT(I7))/SQRT(1+K7^2/(2*J7))),0))-((1-NORMSDIST((K7*(1-1/(4*J7))-(O7-(0.001*O7))*SQRT(I7))/SQRT(1+K7^2/(2*J7))))+IF(colas=2,NORMSDIST((-K7*(1-1/(4*J7))-(O7-(0.001*O7))*SQRT(I7))/SQRT(1+K7^2/(2*J7))),0)))/(2*(0.001*O7))),O7) -> 2.5023243 | Q7: =IFERROR(P7-(((1-NORMSDIST((K7*(1-1/(4*J7))-(P7)*SQRT(I7))/SQRT(1+K7^2/(2*J7))))+IF(colas=2,NORMSDIST((-K7*(1-1/(4*J7))-(P7)*SQRT(I7))/SQRT(1+K7^2/(2*J7))),0))-potencia)/((((1-NORMSDIST((K7*(1-1/(4*J7))-(P7+(0.001*P7))*SQRT(I7))/SQRT(1+K7^2/(2*J7))))+IF(colas=2,NORMSDIST((-K7*(1-1/(4*J7))-(P7+(0.001*P7))*SQRT(I7))/SQRT(1+K7^2/(2*J7))),0))-((1-NORMSDIST((K7*(1-1/(4*J7))-(P7-(0.001*P7))*SQRT(I7))/SQRT(1+K7^2/(2*J7))))+IF(colas=2,NORMSDIST((-K7*(1-1/(4*J7))-(P7-(0.001*P7))*SQRT(I7))/SQRT(1+K7^2/(2*J7))),0)))/(2*(0.001*P7))),P7) -> 2.5091403 | R7: =IFERROR(Q7-(((1-NORMSDIST((K7*(1-1/(4*J7))-(Q7)*SQRT(I7))/SQRT(1+K7^2/(2*J7))))+IF(colas=2,NORMSDIST((-K7*(1-1/(4*J7))-(Q7)*SQRT(I7))/SQRT(1+K7^2/(2*J7))),0))-potencia)/((((1-NORMSDIST((K7*(1-1/(4*J7))-(Q7+(0.001*Q7))*SQRT(I7))/SQRT(1+K7^2/(2*J7))))+IF(colas=2,NORMSDIST((-K7*(1-1/(4*J7))-(Q7+(0.001*Q7))*SQRT(I7))/SQRT(1+K7^2/(2*J7))),0))-((1-NORMSDIST((K7*(1-1/(4*J7))-(Q7-(0.001*Q7))*SQRT(I7))/SQRT(1+K7^2/(2*J7))))+IF(colas=2,NORMSDIST((-K7*(1-1/(4*J7))-(Q7-(0.001*Q7))*SQRT(I7))/SQRT(1+K7^2/(2*J7))),0)))/(2*(0.001*Q7))),Q7) -> 2.5091767 | S7: =R7 -> 2.5091767
A8: n con que se estimó esa S | E8: =IF(ISNUMBER(E6),INDEX(B5:D5,MATCH(E6,B6:D6,0)),"") -> 4 | I8: 5 | J8: =I8-1 -> 4 | K8: =IF(colas=2,TINV(alfa,J8),TINV(2*alfa,J8)) -> 2.7764451 | L8: =IF(ISNUMBER($E$19),$E$19*SQRT(I8),"") -> 0.28378058 | M8: =IF(ISNUMBER($E$19),((1-NORMSDIST((K8*(1-1/(4*J8))-($E$19)*SQRT(I8))/SQRT(1+K8^2/(2*J8))))+IF(colas=2,NORMSDIST((-K8*(1-1/(4*J8))-($E$19)*SQRT(I8))/SQRT(1+K8^2/(2*J8))),0)),"") -> 0.068657792 | N8: =IF(ISNUMBER(M8),IF(M8>=potencia,I8,""),"") | O8: =(K8+TINV(2*(1-potencia),J8))/SQRT(I8) -> 1.9273347 | P8: =IFERROR(O8-(((1-NORMSDIST((K8*(1-1/(4*J8))-(O8)*SQRT(I8))/SQRT(1+K8^2/(2*J8))))+IF(colas=2,NORMSDIST((-K8*(1-1/(4*J8))-(O8)*SQRT(I8))/SQRT(1+K8^2/(2*J8))),0))-potencia)/((((1-NORMSDIST((K8*(1-1/(4*J8))-(O8+(0.001*O8))*SQRT(I8))/SQRT(1+K8^2/(2*J8))))+IF(colas=2,NORMSDIST((-K8*(1-1/(4*J8))-(O8+(0.001*O8))*SQRT(I8))/SQRT(1+K8^2/(2*J8))),0))-((1-NORMSDIST((K8*(1-1/(4*J8))-(O8-(0.001*O8))*SQRT(I8))/SQRT(1+K8^2/(2*J8))))+IF(colas=2,NORMSDIST((-K8*(1-1/(4*J8))-(O8-(0.001*O8))*SQRT(I8))/SQRT(1+K8^2/(2*J8))),0)))/(2*(0.001*O8))),O8) -> 1.9656415 | Q8: =IFERROR(P8-(((1-NORMSDIST((K8*(1-1/(4*J8))-(P8)*SQRT(I8))/SQRT(1+K8^2/(2*J8))))+IF(colas=2,NORMSDIST((-K8*(1-1/(4*J8))-(P8)*SQRT(I8))/SQRT(1+K8^2/(2*J8))),0))-potencia)/((((1-NORMSDIST((K8*(1-1/(4*J8))-(P8+(0.001*P8))*SQRT(I8))/SQRT(1+K8^2/(2*J8))))+IF(colas=2,NORMSDIST((-K8*(1-1/(4*J8))-(P8+(0.001*P8))*SQRT(I8))/SQRT(1+K8^2/(2*J8))),0))-((1-NORMSDIST((K8*(1-1/(4*J8))-(P8-(0.001*P8))*SQRT(I8))/SQRT(1+K8^2/(2*J8))))+IF(colas=2,NORMSDIST((-K8*(1-1/(4*J8))-(P8-(0.001*P8))*SQRT(I8))/SQRT(1+K8^2/(2*J8))),0)))/(2*(0.001*P8))),P8) -> 1.9671674 | R8: =IFERROR(Q8-(((1-NORMSDIST((K8*(1-1/(4*J8))-(Q8)*SQRT(I8))/SQRT(1+K8^2/(2*J8))))+IF(colas=2,NORMSDIST((-K8*(1-1/(4*J8))-(Q8)*SQRT(I8))/SQRT(1+K8^2/(2*J8))),0))-potencia)/((((1-NORMSDIST((K8*(1-1/(4*J8))-(Q8+(0.001*Q8))*SQRT(I8))/SQRT(1+K8^2/(2*J8))))+IF(colas=2,NORMSDIST((-K8*(1-1/(4*J8))-(Q8+(0.001*Q8))*SQRT(I8))/SQRT(1+K8^2/(2*J8))),0))-((1-NORMSDIST((K8*(1-1/(4*J8))-(Q8-(0.001*Q8))*SQRT(I8))/SQRT(1+K8^2/(2*J8))))+IF(colas=2,NORMSDIST((-K8*(1-1/(4*J8))-(Q8-(0.001*Q8))*SQRT(I8))/SQRT(1+K8^2/(2*J8))),0)))/(2*(0.001*Q8))),Q8) -> 1.9671698 | S8: =R8 -> 1.9671698
A9: Factor del límite superior: √[(n − 1)/χ²(1 − conf; n − 1)] | E9: =IF(AND(ISNUMBER(E8),E8>=2),SQRT((E8-1)/CHIINV(conf_sigma,E8-1)),"") -> 1.7275873 | G9: Con n = 5 y conf = 0,80 el factor es 1,557 (el «1,56» del protocolo). | I9: 6 | J9: =I9-1 -> 5 | K9: =IF(colas=2,TINV(alfa,J9),TINV(2*alfa,J9)) -> 2.5705818 | L9: =IF(ISNUMBER($E$19),$E$19*SQRT(I9),"") -> 0.31086605 | M9: =IF(ISNUMBER($E$19),((1-NORMSDIST((K9*(1-1/(4*J9))-($E$19)*SQRT(I9))/SQRT(1+K9^2/(2*J9))))+IF(colas=2,NORMSDIST((-K9*(1-1/(4*J9))-($E$19)*SQRT(I9))/SQRT(1+K9^2/(2*J9))),0)),"") -> 0.065424039 | N9: =IF(ISNUMBER(M9),IF(M9>=potencia,I9,""),"") | O9: =(K9+TINV(2*(1-potencia),J9))/SQRT(I9) -> 1.6519628 | P9: =IFERROR(O9-(((1-NORMSDIST((K9*(1-1/(4*J9))-(O9)*SQRT(I9))/SQRT(1+K9^2/(2*J9))))+IF(colas=2,NORMSDIST((-K9*(1-1/(4*J9))-(O9)*SQRT(I9))/SQRT(1+K9^2/(2*J9))),0))-potencia)/((((1-NORMSDIST((K9*(1-1/(4*J9))-(O9+(0.001*O9))*SQRT(I9))/SQRT(1+K9^2/(2*J9))))+IF(colas=2,NORMSDIST((-K9*(1-1/(4*J9))-(O9+(0.001*O9))*SQRT(I9))/SQRT(1+K9^2/(2*J9))),0))-((1-NORMSDIST((K9*(1-1/(4*J9))-(O9-(0.001*O9))*SQRT(I9))/SQRT(1+K9^2/(2*J9))))+IF(colas=2,NORMSDIST((-K9*(1-1/(4*J9))-(O9-(0.001*O9))*SQRT(I9))/SQRT(1+K9^2/(2*J9))),0)))/(2*(0.001*O9))),O9) -> 1.6707724 | Q9: =IFERROR(P9-(((1-NORMSDIST((K9*(1-1/(4*J9))-(P9)*SQRT(I9))/SQRT(1+K9^2/(2*J9))))+IF(colas=2,NORMSDIST((-K9*(1-1/(4*J9))-(P9)*SQRT(I9))/SQRT(1+K9^2/(2*J9))),0))-potencia)/((((1-NORMSDIST((K9*(1-1/(4*J9))-(P9+(0.001*P9))*SQRT(I9))/SQRT(1+K9^2/(2*J9))))+IF(colas=2,NORMSDIST((-K9*(1-1/(4*J9))-(P9+(0.001*P9))*SQRT(I9))/SQRT(1+K9^2/(2*J9))),0))-((1-NORMSDIST((K9*(1-1/(4*J9))-(P9-(0.001*P9))*SQRT(I9))/SQRT(1+K9^2/(2*J9))))+IF(colas=2,NORMSDIST((-K9*(1-1/(4*J9))-(P9-(0.001*P9))*SQRT(I9))/SQRT(1+K9^2/(2*J9))),0)))/(2*(0.001*P9))),P9) -> 1.671208 | R9: =IFERROR(Q9-(((1-NORMSDIST((K9*(1-1/(4*J9))-(Q9)*SQRT(I9))/SQRT(1+K9^2/(2*J9))))+IF(colas=2,NORMSDIST((-K9*(1-1/(4*J9))-(Q9)*SQRT(I9))/SQRT(1+K9^2/(2*J9))),0))-potencia)/((((1-NORMSDIST((K9*(1-1/(4*J9))-(Q9+(0.001*Q9))*SQRT(I9))/SQRT(1+K9^2/(2*J9))))+IF(colas=2,NORMSDIST((-K9*(1-1/(4*J9))-(Q9+(0.001*Q9))*SQRT(I9))/SQRT(1+K9^2/(2*J9))),0))-((1-NORMSDIST((K9*(1-1/(4*J9))-(Q9-(0.001*Q9))*SQRT(I9))/SQRT(1+K9^2/(2*J9))))+IF(colas=2,NORMSDIST((-K9*(1-1/(4*J9))-(Q9-(0.001*Q9))*SQRT(I9))/SQRT(1+K9^2/(2*J9))),0)))/(2*(0.001*Q9))),Q9) -> 1.6712082 | S9: =R9 -> 1.6712082
A10: σ para el diseño = factor × S mayor (fs) | E10: =IF(ISNUMBER(E9),E9*E6,"") -> 78.795665 | I10: 7 | J10: =I10-1 -> 6 | K10: =IF(colas=2,TINV(alfa,J10),TINV(2*alfa,J10)) -> 2.4469119 | L10: =IF(ISNUMBER($E$19),$E$19*SQRT(I10),"") -> 0.33577371 | M10: =IF(ISNUMBER($E$19),((1-NORMSDIST((K10*(1-1/(4*J10))-($E$19)*SQRT(I10))/SQRT(1+K10^2/(2*J10))))+IF(colas=2,NORMSDIST((-K10*(1-1/(4*J10))-($E$19)*SQRT(I10))/SQRT(1+K10^2/(2*J10))),0)),"") -> 0.064669281 | N10: =IF(ISNUMBER(M10),IF(M10>=potencia,I10,""),"") | O10: =(K10+TINV(2*(1-potencia),J10))/SQRT(I10) -> 1.4690223 | P10: =IFERROR(O10-(((1-NORMSDIST((K10*(1-1/(4*J10))-(O10)*SQRT(I10))/SQRT(1+K10^2/(2*J10))))+IF(colas=2,NORMSDIST((-K10*(1-1/(4*J10))-(O10)*SQRT(I10))/SQRT(1+K10^2/(2*J10))),0))-potencia)/((((1-NORMSDIST((K10*(1-1/(4*J10))-(O10+(0.001*O10))*SQRT(I10))/SQRT(1+K10^2/(2*J10))))+IF(colas=2,NORMSDIST((-K10*(1-1/(4*J10))-(O10+(0.001*O10))*SQRT(I10))/SQRT(1+K10^2/(2*J10))),0))-((1-NORMSDIST((K10*(1-1/(4*J10))-(O10-(0.001*O10))*SQRT(I10))/SQRT(1+K10^2/(2*J10))))+IF(colas=2,NORMSDIST((-K10*(1-1/(4*J10))-(O10-(0.001*O10))*SQRT(I10))/SQRT(1+K10^2/(2*J10))),0)))/(2*(0.001*O10))),O10) -> 1.4792007 | Q10: =IFERROR(P10-(((1-NORMSDIST((K10*(1-1/(4*J10))-(P10)*SQRT(I10))/SQRT(1+K10^2/(2*J10))))+IF(colas=2,NORMSDIST((-K10*(1-1/(4*J10))-(P10)*SQRT(I10))/SQRT(1+K10^2/(2*J10))),0))-potencia)/((((1-NORMSDIST((K10*(1-1/(4*J10))-(P10+(0.001*P10))*SQRT(I10))/SQRT(1+K10^2/(2*J10))))+IF(colas=2,NORMSDIST((-K10*(1-1/(4*J10))-(P10+(0.001*P10))*SQRT(I10))/SQRT(1+K10^2/(2*J10))),0))-((1-NORMSDIST((K10*(1-1/(4*J10))-(P10-(0.001*P10))*SQRT(I10))/SQRT(1+K10^2/(2*J10))))+IF(colas=2,NORMSDIST((-K10*(1-1/(4*J10))-(P10-(0.001*P10))*SQRT(I10))/SQRT(1+K10^2/(2*J10))),0)))/(2*(0.001*P10))),P10) -> 1.4793451 | R10: =IFERROR(Q10-(((1-NORMSDIST((K10*(1-1/(4*J10))-(Q10)*SQRT(I10))/SQRT(1+K10^2/(2*J10))))+IF(colas=2,NORMSDIST((-K10*(1-1/(4*J10))-(Q10)*SQRT(I10))/SQRT(1+K10^2/(2*J10))),0))-potencia)/((((1-NORMSDIST((K10*(1-1/(4*J10))-(Q10+(0.001*Q10))*SQRT(I10))/SQRT(1+K10^2/(2*J10))))+IF(colas=2,NORMSDIST((-K10*(1-1/(4*J10))-(Q10+(0.001*Q10))*SQRT(I10))/SQRT(1+K10^2/(2*J10))),0))-((1-NORMSDIST((K10*(1-1/(4*J10))-(Q10-(0.001*Q10))*SQRT(I10))/SQRT(1+K10^2/(2*J10))))+IF(colas=2,NORMSDIST((-K10*(1-1/(4*J10))-(Q10-(0.001*Q10))*SQRT(I10))/SQRT(1+K10^2/(2*J10))),0)))/(2*(0.001*Q10))),Q10) -> 1.4793451 | S10: =R10 -> 1.4793451
I11: 8 | J11: =I11-1 -> 7 | K11: =IF(colas=2,TINV(alfa,J11),TINV(2*alfa,J11)) -> 2.3646243 | L11: =IF(ISNUMBER($E$19),$E$19*SQRT(I11),"") -> 0.3589572 | M11: =IF(ISNUMBER($E$19),((1-NORMSDIST((K11*(1-1/(4*J11))-($E$19)*SQRT(I11))/SQRT(1+K11^2/(2*J11))))+IF(colas=2,NORMSDIST((-K11*(1-1/(4*J11))-($E$19)*SQRT(I11))/SQRT(1+K11^2/(2*J11))),0)),"") -> 0.065021455 | N11: =IF(ISNUMBER(M11),IF(M11>=potencia,I11,""),"") | O11: =(K11+TINV(2*(1-potencia),J11))/SQRT(I11) -> 1.3362721 | P11: =IFERROR(O11-(((1-NORMSDIST((K11*(1-1/(4*J11))-(O11)*SQRT(I11))/SQRT(1+K11^2/(2*J11))))+IF(colas=2,NORMSDIST((-K11*(1-1/(4*J11))-(O11)*SQRT(I11))/SQRT(1+K11^2/(2*J11))),0))-potencia)/((((1-NORMSDIST((K11*(1-1/(4*J11))-(O11+(0.001*O11))*SQRT(I11))/SQRT(1+K11^2/(2*J11))))+IF(colas=2,NORMSDIST((-K11*(1-1/(4*J11))-(O11+(0.001*O11))*SQRT(I11))/SQRT(1+K11^2/(2*J11))),0))-((1-NORMSDIST((K11*(1-1/(4*J11))-(O11-(0.001*O11))*SQRT(I11))/SQRT(1+K11^2/(2*J11))))+IF(colas=2,NORMSDIST((-K11*(1-1/(4*J11))-(O11-(0.001*O11))*SQRT(I11))/SQRT(1+K11^2/(2*J11))),0)))/(2*(0.001*O11))),O11) -> 1.3421048 | Q11: =IFERROR(P11-(((1-NORMSDIST((K11*(1-1/(4*J11))-(P11)*SQRT(I11))/SQRT(1+K11^2/(2*J11))))+IF(colas=2,NORMSDIST((-K11*(1-1/(4*J11))-(P11)*SQRT(I11))/SQRT(1+K11^2/(2*J11))),0))-potencia)/((((1-NORMSDIST((K11*(1-1/(4*J11))-(P11+(0.001*P11))*SQRT(I11))/SQRT(1+K11^2/(2*J11))))+IF(colas=2,NORMSDIST((-K11*(1-1/(4*J11))-(P11+(0.001*P11))*SQRT(I11))/SQRT(1+K11^2/(2*J11))),0))-((1-NORMSDIST((K11*(1-1/(4*J11))-(P11-(0.001*P11))*SQRT(I11))/SQRT(1+K11^2/(2*J11))))+IF(colas=2,NORMSDIST((-K11*(1-1/(4*J11))-(P11-(0.001*P11))*SQRT(I11))/SQRT(1+K11^2/(2*J11))),0)))/(2*(0.001*P11))),P11) -> 1.3421572 | R11: =IFERROR(Q11-(((1-NORMSDIST((K11*(1-1/(4*J11))-(Q11)*SQRT(I11))/SQRT(1+K11^2/(2*J11))))+IF(colas=2,NORMSDIST((-K11*(1-1/(4*J11))-(Q11)*SQRT(I11))/SQRT(1+K11^2/(2*J11))),0))-potencia)/((((1-NORMSDIST((K11*(1-1/(4*J11))-(Q11+(0.001*Q11))*SQRT(I11))/SQRT(1+K11^2/(2*J11))))+IF(colas=2,NORMSDIST((-K11*(1-1/(4*J11))-(Q11+(0.001*Q11))*SQRT(I11))/SQRT(1+K11^2/(2*J11))),0))-((1-NORMSDIST((K11*(1-1/(4*J11))-(Q11-(0.001*Q11))*SQRT(I11))/SQRT(1+K11^2/(2*J11))))+IF(colas=2,NORMSDIST((-K11*(1-1/(4*J11))-(Q11-(0.001*Q11))*SQRT(I11))/SQRT(1+K11^2/(2*J11))),0)))/(2*(0.001*Q11))),Q11) -> 1.3421572 | S11: =R11 -> 1.3421572
A12: Paso 2 · δ que importa detectar | B12: I1 | C12: I2 | D12: I3 | E12: Usado | I12: 9 | J12: =I12-1 -> 8 | K12: =IF(colas=2,TINV(alfa,J12),TINV(2*alfa,J12)) -> 2.3060041 | L12: =IF(ISNUMBER($E$19),$E$19*SQRT(I12),"") -> 0.3807316 | M12: =IF(ISNUMBER($E$19),((1-NORMSDIST((K12*(1-1/(4*J12))-($E$19)*SQRT(I12))/SQRT(1+K12^2/(2*J12))))+IF(colas=2,NORMSDIST((-K12*(1-1/(4*J12))-($E$19)*SQRT(I12))/SQRT(1+K12^2/(2*J12))),0)),"") -> 0.065940071 | N12: =IF(ISNUMBER(M12),IF(M12>=potencia,I12,""),"") | O12: =(K12+TINV(2*(1-potencia),J12))/SQRT(I12) -> 1.2342731 | P12: =IFERROR(O12-(((1-NORMSDIST((K12*(1-1/(4*J12))-(O12)*SQRT(I12))/SQRT(1+K12^2/(2*J12))))+IF(colas=2,NORMSDIST((-K12*(1-1/(4*J12))-(O12)*SQRT(I12))/SQRT(1+K12^2/(2*J12))),0))-potencia)/((((1-NORMSDIST((K12*(1-1/(4*J12))-(O12+(0.001*O12))*SQRT(I12))/SQRT(1+K12^2/(2*J12))))+IF(colas=2,NORMSDIST((-K12*(1-1/(4*J12))-(O12+(0.001*O12))*SQRT(I12))/SQRT(1+K12^2/(2*J12))),0))-((1-NORMSDIST((K12*(1-1/(4*J12))-(O12-(0.001*O12))*SQRT(I12))/SQRT(1+K12^2/(2*J12))))+IF(colas=2,NORMSDIST((-K12*(1-1/(4*J12))-(O12-(0.001*O12))*SQRT(I12))/SQRT(1+K12^2/(2*J12))),0)))/(2*(0.001*O12))),O12) -> 1.2377152 | Q12: =IFERROR(P12-(((1-NORMSDIST((K12*(1-1/(4*J12))-(P12)*SQRT(I12))/SQRT(1+K12^2/(2*J12))))+IF(colas=2,NORMSDIST((-K12*(1-1/(4*J12))-(P12)*SQRT(I12))/SQRT(1+K12^2/(2*J12))),0))-potencia)/((((1-NORMSDIST((K12*(1-1/(4*J12))-(P12+(0.001*P12))*SQRT(I12))/SQRT(1+K12^2/(2*J12))))+IF(colas=2,NORMSDIST((-K12*(1-1/(4*J12))-(P12+(0.001*P12))*SQRT(I12))/SQRT(1+K12^2/(2*J12))),0))-((1-NORMSDIST((K12*(1-1/(4*J12))-(P12-(0.001*P12))*SQRT(I12))/SQRT(1+K12^2/(2*J12))))+IF(colas=2,NORMSDIST((-K12*(1-1/(4*J12))-(P12-(0.001*P12))*SQRT(I12))/SQRT(1+K12^2/(2*J12))),0)))/(2*(0.001*P12))),P12) -> 1.237735 | R12: =IFERROR(Q12-(((1-NORMSDIST((K12*(1-1/(4*J12))-(Q12)*SQRT(I12))/SQRT(1+K12^2/(2*J12))))+IF(colas=2,NORMSDIST((-K12*(1-1/(4*J12))-(Q12)*SQRT(I12))/SQRT(1+K12^2/(2*J12))),0))-potencia)/((((1-NORMSDIST((K12*(1-1/(4*J12))-(Q12+(0.001*Q12))*SQRT(I12))/SQRT(1+K12^2/(2*J12))))+IF(colas=2,NORMSDIST((-K12*(1-1/(4*J12))-(Q12+(0.001*Q12))*SQRT(I12))/SQRT(1+K12^2/(2*J12))),0))-((1-NORMSDIST((K12*(1-1/(4*J12))-(Q12-(0.001*Q12))*SQRT(I12))/SQRT(1+K12^2/(2*J12))))+IF(colas=2,NORMSDIST((-K12*(1-1/(4*J12))-(Q12-(0.001*Q12))*SQRT(I12))/SQRT(1+K12^2/(2*J12))),0)))/(2*(0.001*Q12))),Q12) -> 1.237735 | S12: =R12 -> 1.237735
A13: Regla que aplica (primer dato del fabricante que exista) | B13: =IF(ISNUMBER(tol_1),"1 · tolerancia",IF(AND(ISNUMBER(tau0_1),ISNUMBER(taumax_1),taumax_1>tau0_1),"2 · τmáx − τ0",IF(ISNUMBER(banda_1),"3 · banda",IF(AND(ISNUMBER(estab_1),ISNUMBER(tau0_1)),"4 · estabilidad","5 · por defecto")))) -> 5 · por defecto | C13: =IF(ISNUMBER(tol_2),"1 · tolerancia",IF(AND(ISNUMBER(tau0_2),ISNUMBER(taumax_2),taumax_2>tau0_2),"2 · τmáx − τ0",IF(ISNUMBER(banda_2),"3 · banda",IF(AND(ISNUMBER(estab_2),ISNUMBER(tau0_2)),"4 · estabilidad","5 · por defecto")))) -> 5 · por defecto | D13: =IF(ISNUMBER(tol_3),"1 · tolerancia",IF(AND(ISNUMBER(tau0_3),ISNUMBER(taumax_3),taumax_3>tau0_3),"2 · τmáx − τ0",IF(ISNUMBER(banda_3),"3 · banda",IF(AND(ISNUMBER(estab_3),ISNUMBER(tau0_3)),"4 · estabilidad","5 · por defecto")))) -> 2 · τmáx − τ0 | I13: 10 | J13: =I13-1 -> 9 | K13: =IF(colas=2,TINV(alfa,J13),TINV(2*alfa,J13)) -> 2.2621572 | L13: =IF(ISNUMBER($E$19),$E$19*SQRT(I13),"") -> 0.40132635 | M13: =IF(ISNUMBER($E$19),((1-NORMSDIST((K13*(1-1/(4*J13))-($E$19)*SQRT(I13))/SQRT(1+K13^2/(2*J13))))+IF(colas=2,NORMSDIST((-K13*(1-1/(4*J13))-($E$19)*SQRT(I13))/SQRT(1+K13^2/(2*J13))),0)),"") -> 0.067178459 | N13: =IF(ISNUMBER(M13),IF(M13>=potencia,I13,""),"") | O13: =(K13+TINV(2*(1-potencia),J13))/SQRT(I13) -> 1.152709 | P13: =IFERROR(O13-(((1-NORMSDIST((K13*(1-1/(4*J13))-(O13)*SQRT(I13))/SQRT(1+K13^2/(2*J13))))+IF(colas=2,NORMSDIST((-K13*(1-1/(4*J13))-(O13)*SQRT(I13))/SQRT(1+K13^2/(2*J13))),0))-potencia)/((((1-NORMSDIST((K13*(1-1/(4*J13))-(O13+(0.001*O13))*SQRT(I13))/SQRT(1+K13^2/(2*J13))))+IF(colas=2,NORMSDIST((-K13*(1-1/(4*J13))-(O13+(0.001*O13))*SQRT(I13))/SQRT(1+K13^2/(2*J13))),0))-((1-NORMSDIST((K13*(1-1/(4*J13))-(O13-(0.001*O13))*SQRT(I13))/SQRT(1+K13^2/(2*J13))))+IF(colas=2,NORMSDIST((-K13*(1-1/(4*J13))-(O13-(0.001*O13))*SQRT(I13))/SQRT(1+K13^2/(2*J13))),0)))/(2*(0.001*O13))),O13) -> 1.154749 | Q13: =IFERROR(P13-(((1-NORMSDIST((K13*(1-1/(4*J13))-(P13)*SQRT(I13))/SQRT(1+K13^2/(2*J13))))+IF(colas=2,NORMSDIST((-K13*(1-1/(4*J13))-(P13)*SQRT(I13))/SQRT(1+K13^2/(2*J13))),0))-potencia)/((((1-NORMSDIST((K13*(1-1/(4*J13))-(P13+(0.001*P13))*SQRT(I13))/SQRT(1+K13^2/(2*J13))))+IF(colas=2,NORMSDIST((-K13*(1-1/(4*J13))-(P13+(0.001*P13))*SQRT(I13))/SQRT(1+K13^2/(2*J13))),0))-((1-NORMSDIST((K13*(1-1/(4*J13))-(P13-(0.001*P13))*SQRT(I13))/SQRT(1+K13^2/(2*J13))))+IF(colas=2,NORMSDIST((-K13*(1-1/(4*J13))-(P13-(0.001*P13))*SQRT(I13))/SQRT(1+K13^2/(2*J13))),0)))/(2*(0.001*P13))),P13) -> 1.1547565 | R13: =IFERROR(Q13-(((1-NORMSDIST((K13*(1-1/(4*J13))-(Q13)*SQRT(I13))/SQRT(1+K13^2/(2*J13))))+IF(colas=2,NORMSDIST((-K13*(1-1/(4*J13))-(Q13)*SQRT(I13))/SQRT(1+K13^2/(2*J13))),0))-potencia)/((((1-NORMSDIST((K13*(1-1/(4*J13))-(Q13+(0.001*Q13))*SQRT(I13))/SQRT(1+K13^2/(2*J13))))+IF(colas=2,NORMSDIST((-K13*(1-1/(4*J13))-(Q13+(0.001*Q13))*SQRT(I13))/SQRT(1+K13^2/(2*J13))),0))-((1-NORMSDIST((K13*(1-1/(4*J13))-(Q13-(0.001*Q13))*SQRT(I13))/SQRT(1+K13^2/(2*J13))))+IF(colas=2,NORMSDIST((-K13*(1-1/(4*J13))-(Q13-(0.001*Q13))*SQRT(I13))/SQRT(1+K13^2/(2*J13))),0)))/(2*(0.001*Q13))),Q13) -> 1.1547565 | S13: =R13 -> 1.1547565
A14: δ según la regla (fs) | B14: =IF(ISNUMBER(tol_1),tol_1,IF(AND(ISNUMBER(tau0_1),ISNUMBER(taumax_1),taumax_1>tau0_1),taumax_1-tau0_1,IF(ISNUMBER(banda_1),banda_1,IF(AND(ISNUMBER(estab_1),ISNUMBER(tau0_1)),3*estab_1/100*tau0_1,delta_def)))) -> 10 | C14: =IF(ISNUMBER(tol_2),tol_2,IF(AND(ISNUMBER(tau0_2),ISNUMBER(taumax_2),taumax_2>tau0_2),taumax_2-tau0_2,IF(ISNUMBER(banda_2),banda_2,IF(AND(ISNUMBER(estab_2),ISNUMBER(tau0_2)),3*estab_2/100*tau0_2,delta_def)))) -> 10 | D14: =IF(ISNUMBER(tol_3),tol_3,IF(AND(ISNUMBER(tau0_3),ISNUMBER(taumax_3),taumax_3>tau0_3),taumax_3-tau0_3,IF(ISNUMBER(banda_3),banda_3,IF(AND(ISNUMBER(estab_3),ISNUMBER(tau0_3)),3*estab_3/100*tau0_3,delta_def)))) -> 26 | I14: 11 | J14: =I14-1 -> 10 | K14: =IF(colas=2,TINV(alfa,J14),TINV(2*alfa,J14)) -> 2.2281389 | L14: =IF(ISNUMBER($E$19),$E$19*SQRT(I14),"") -> 0.42091463 | M14: =IF(ISNUMBER($E$19),((1-NORMSDIST((K14*(1-1/(4*J14))-($E$19)*SQRT(I14))/SQRT(1+K14^2/(2*J14))))+IF(colas=2,NORMSDIST((-K14*(1-1/(4*J14))-($E$19)*SQRT(I14))/SQRT(1+K14^2/(2*J14))),0)),"") -> 0.068611322 | N14: =IF(ISNUMBER(M14),IF(M14>=potencia,I14,""),"") | O14: =(K14+TINV(2*(1-potencia),J14))/SQRT(I14) -> 1.0855381 | P14: =IFERROR(O14-(((1-NORMSDIST((K14*(1-1/(4*J14))-(O14)*SQRT(I14))/SQRT(1+K14^2/(2*J14))))+IF(colas=2,NORMSDIST((-K14*(1-1/(4*J14))-(O14)*SQRT(I14))/SQRT(1+K14^2/(2*J14))),0))-potencia)/((((1-NORMSDIST((K14*(1-1/(4*J14))-(O14+(0.001*O14))*SQRT(I14))/SQRT(1+K14^2/(2*J14))))+IF(colas=2,NORMSDIST((-K14*(1-1/(4*J14))-(O14+(0.001*O14))*SQRT(I14))/SQRT(1+K14^2/(2*J14))),0))-((1-NORMSDIST((K14*(1-1/(4*J14))-(O14-(0.001*O14))*SQRT(I14))/SQRT(1+K14^2/(2*J14))))+IF(colas=2,NORMSDIST((-K14*(1-1/(4*J14))-(O14-(0.001*O14))*SQRT(I14))/SQRT(1+K14^2/(2*J14))),0)))/(2*(0.001*O14))),O14) -> 1.086716 | Q14: =IFERROR(P14-(((1-NORMSDIST((K14*(1-1/(4*J14))-(P14)*SQRT(I14))/SQRT(1+K14^2/(2*J14))))+IF(colas=2,NORMSDIST((-K14*(1-1/(4*J14))-(P14)*SQRT(I14))/SQRT(1+K14^2/(2*J14))),0))-potencia)/((((1-NORMSDIST((K14*(1-1/(4*J14))-(P14+(0.001*P14))*SQRT(I14))/SQRT(1+K14^2/(2*J14))))+IF(colas=2,NORMSDIST((-K14*(1-1/(4*J14))-(P14+(0.001*P14))*SQRT(I14))/SQRT(1+K14^2/(2*J14))),0))-((1-NORMSDIST((K14*(1-1/(4*J14))-(P14-(0.001*P14))*SQRT(I14))/SQRT(1+K14^2/(2*J14))))+IF(colas=2,NORMSDIST((-K14*(1-1/(4*J14))-(P14-(0.001*P14))*SQRT(I14))/SQRT(1+K14^2/(2*J14))),0)))/(2*(0.001*P14))),P14) -> 1.0867187 | R14: =IFERROR(Q14-(((1-NORMSDIST((K14*(1-1/(4*J14))-(Q14)*SQRT(I14))/SQRT(1+K14^2/(2*J14))))+IF(colas=2,NORMSDIST((-K14*(1-1/(4*J14))-(Q14)*SQRT(I14))/SQRT(1+K14^2/(2*J14))),0))-potencia)/((((1-NORMSDIST((K14*(1-1/(4*J14))-(Q14+(0.001*Q14))*SQRT(I14))/SQRT(1+K14^2/(2*J14))))+IF(colas=2,NORMSDIST((-K14*(1-1/(4*J14))-(Q14+(0.001*Q14))*SQRT(I14))/SQRT(1+K14^2/(2*J14))),0))-((1-NORMSDIST((K14*(1-1/(4*J14))-(Q14-(0.001*Q14))*SQRT(I14))/SQRT(1+K14^2/(2*J14))))+IF(colas=2,NORMSDIST((-K14*(1-1/(4*J14))-(Q14-(0.001*Q14))*SQRT(I14))/SQRT(1+K14^2/(2*J14))),0)))/(2*(0.001*Q14))),Q14) -> 1.0867187 | S14: =R14 -> 1.0867187
A15: δ con el piso 2u (fs) | B15: =IF(ISNUMBER(incert_1),MAX(B14,2*incert_1),B14) -> 10 | C15: =IF(ISNUMBER(incert_2),MAX(C14,2*incert_2),C14) -> 10 | D15: =IF(ISNUMBER(incert_3),MAX(D14,2*incert_3),D14) -> 26 | E15: =MIN(B15:D15) -> 10 | G15: Si δ cambia por corriente, se usa la menor (la que exige más réplicas). La regla 2 necesita τ0 medido; sin él cae a la 5 (10 fs). | I15: 12 | J15: =I15-1 -> 11 | K15: =IF(colas=2,TINV(alfa,J15),TINV(2*alfa,J15)) -> 2.2009852 | L15: =IF(ISNUMBER($E$19),$E$19*SQRT(I15),"") -> 0.43963099 | M15: =IF(ISNUMBER($E$19),((1-NORMSDIST((K15*(1-1/(4*J15))-($E$19)*SQRT(I15))/SQRT(1+K15^2/(2*J15))))+IF(colas=2,NORMSDIST((-K15*(1-1/(4*J15))-($E$19)*SQRT(I15))/SQRT(1+K15^2/(2*J15))),0)),"") -> 0.07016962 | N15: =IF(ISNUMBER(M15),IF(M15>=potencia,I15,""),"") | O15: =(K15+TINV(2*(1-potencia),J15))/SQRT(I15) -> 1.0289581 | P15: =IFERROR(O15-(((1-NORMSDIST((K15*(1-1/(4*J15))-(O15)*SQRT(I15))/SQRT(1+K15^2/(2*J15))))+IF(colas=2,NORMSDIST((-K15*(1-1/(4*J15))-(O15)*SQRT(I15))/SQRT(1+K15^2/(2*J15))),0))-potencia)/((((1-NORMSDIST((K15*(1-1/(4*J15))-(O15+(0.001*O15))*SQRT(I15))/SQRT(1+K15^2/(2*J15))))+IF(colas=2,NORMSDIST((-K15*(1-1/(4*J15))-(O15+(0.001*O15))*SQRT(I15))/SQRT(1+K15^2/(2*J15))),0))-((1-NORMSDIST((K15*(1-1/(4*J15))-(O15-(0.001*O15))*SQRT(I15))/SQRT(1+K15^2/(2*J15))))+IF(colas=2,NORMSDIST((-K15*(1-1/(4*J15))-(O15-(0.001*O15))*SQRT(I15))/SQRT(1+K15^2/(2*J15))),0)))/(2*(0.001*O15))),O15) -> 1.0295869 | Q15: =IFERROR(P15-(((1-NORMSDIST((K15*(1-1/(4*J15))-(P15)*SQRT(I15))/SQRT(1+K15^2/(2*J15))))+IF(colas=2,NORMSDIST((-K15*(1-1/(4*J15))-(P15)*SQRT(I15))/SQRT(1+K15^2/(2*J15))),0))-potencia)/((((1-NORMSDIST((K15*(1-1/(4*J15))-(P15+(0.001*P15))*SQRT(I15))/SQRT(1+K15^2/(2*J15))))+IF(colas=2,NORMSDIST((-K15*(1-1/(4*J15))-(P15+(0.001*P15))*SQRT(I15))/SQRT(1+K15^2/(2*J15))),0))-((1-NORMSDIST((K15*(1-1/(4*J15))-(P15-(0.001*P15))*SQRT(I15))/SQRT(1+K15^2/(2*J15))))+IF(colas=2,NORMSDIST((-K15*(1-1/(4*J15))-(P15-(0.001*P15))*SQRT(I15))/SQRT(1+K15^2/(2*J15))),0)))/(2*(0.001*P15))),P15) -> 1.0295877 | R15: =IFERROR(Q15-(((1-NORMSDIST((K15*(1-1/(4*J15))-(Q15)*SQRT(I15))/SQRT(1+K15^2/(2*J15))))+IF(colas=2,NORMSDIST((-K15*(1-1/(4*J15))-(Q15)*SQRT(I15))/SQRT(1+K15^2/(2*J15))),0))-potencia)/((((1-NORMSDIST((K15*(1-1/(4*J15))-(Q15+(0.001*Q15))*SQRT(I15))/SQRT(1+K15^2/(2*J15))))+IF(colas=2,NORMSDIST((-K15*(1-1/(4*J15))-(Q15+(0.001*Q15))*SQRT(I15))/SQRT(1+K15^2/(2*J15))),0))-((1-NORMSDIST((K15*(1-1/(4*J15))-(Q15-(0.001*Q15))*SQRT(I15))/SQRT(1+K15^2/(2*J15))))+IF(colas=2,NORMSDIST((-K15*(1-1/(4*J15))-(Q15-(0.001*Q15))*SQRT(I15))/SQRT(1+K15^2/(2*J15))),0)))/(2*(0.001*Q15))),Q15) -> 1.0295877 | S15: =R15 -> 1.0295877
I16: 13 | J16: =I16-1 -> 12 | K16: =IF(colas=2,TINV(alfa,J16),TINV(2*alfa,J16)) -> 2.1788128 | L16: =IF(ISNUMBER($E$19),$E$19*SQRT(I16),"") -> 0.45758244 | M16: =IF(ISNUMBER($E$19),((1-NORMSDIST((K16*(1-1/(4*J16))-($E$19)*SQRT(I16))/SQRT(1+K16^2/(2*J16))))+IF(colas=2,NORMSDIST((-K16*(1-1/(4*J16))-($E$19)*SQRT(I16))/SQRT(1+K16^2/(2*J16))),0)),"") -> 0.071812805 | N16: =IF(ISNUMBER(M16),IF(M16>=potencia,I16,""),"") | O16: =(K16+TINV(2*(1-potencia),J16))/SQRT(I16) -> 0.98044096 | P16: =IFERROR(O16-(((1-NORMSDIST((K16*(1-1/(4*J16))-(O16)*SQRT(I16))/SQRT(1+K16^2/(2*J16))))+IF(colas=2,NORMSDIST((-K16*(1-1/(4*J16))-(O16)*SQRT(I16))/SQRT(1+K16^2/(2*J16))),0))-potencia)/((((1-NORMSDIST((K16*(1-1/(4*J16))-(O16+(0.001*O16))*SQRT(I16))/SQRT(1+K16^2/(2*J16))))+IF(colas=2,NORMSDIST((-K16*(1-1/(4*J16))-(O16+(0.001*O16))*SQRT(I16))/SQRT(1+K16^2/(2*J16))),0))-((1-NORMSDIST((K16*(1-1/(4*J16))-(O16-(0.001*O16))*SQRT(I16))/SQRT(1+K16^2/(2*J16))))+IF(colas=2,NORMSDIST((-K16*(1-1/(4*J16))-(O16-(0.001*O16))*SQRT(I16))/SQRT(1+K16^2/(2*J16))),0)))/(2*(0.001*O16))),O16) -> 0.98071056 | Q16: =IFERROR(P16-(((1-NORMSDIST((K16*(1-1/(4*J16))-(P16)*SQRT(I16))/SQRT(1+K16^2/(2*J16))))+IF(colas=2,NORMSDIST((-K16*(1-1/(4*J16))-(P16)*SQRT(I16))/SQRT(1+K16^2/(2*J16))),0))-potencia)/((((1-NORMSDIST((K16*(1-1/(4*J16))-(P16+(0.001*P16))*SQRT(I16))/SQRT(1+K16^2/(2*J16))))+IF(colas=2,NORMSDIST((-K16*(1-1/(4*J16))-(P16+(0.001*P16))*SQRT(I16))/SQRT(1+K16^2/(2*J16))),0))-((1-NORMSDIST((K16*(1-1/(4*J16))-(P16-(0.001*P16))*SQRT(I16))/SQRT(1+K16^2/(2*J16))))+IF(colas=2,NORMSDIST((-K16*(1-1/(4*J16))-(P16-(0.001*P16))*SQRT(I16))/SQRT(1+K16^2/(2*J16))),0)))/(2*(0.001*P16))),P16) -> 0.98071071 | R16: =IFERROR(Q16-(((1-NORMSDIST((K16*(1-1/(4*J16))-(Q16)*SQRT(I16))/SQRT(1+K16^2/(2*J16))))+IF(colas=2,NORMSDIST((-K16*(1-1/(4*J16))-(Q16)*SQRT(I16))/SQRT(1+K16^2/(2*J16))),0))-potencia)/((((1-NORMSDIST((K16*(1-1/(4*J16))-(Q16+(0.001*Q16))*SQRT(I16))/SQRT(1+K16^2/(2*J16))))+IF(colas=2,NORMSDIST((-K16*(1-1/(4*J16))-(Q16+(0.001*Q16))*SQRT(I16))/SQRT(1+K16^2/(2*J16))),0))-((1-NORMSDIST((K16*(1-1/(4*J16))-(Q16-(0.001*Q16))*SQRT(I16))/SQRT(1+K16^2/(2*J16))))+IF(colas=2,NORMSDIST((-K16*(1-1/(4*J16))-(Q16-(0.001*Q16))*SQRT(I16))/SQRT(1+K16^2/(2*J16))),0)))/(2*(0.001*Q16))),Q16) -> 0.98071071 | S16: =R16 -> 0.98071071
A17: Paso 3 · Número de réplicas por corriente | E17: Valor | I17: 14 | J17: =I17-1 -> 13 | K17: =IF(colas=2,TINV(alfa,J17),TINV(2*alfa,J17)) -> 2.1603687 | L17: =IF(ISNUMBER($E$19),$E$19*SQRT(I17),"") -> 0.47485574 | M17: =IF(ISNUMBER($E$19),((1-NORMSDIST((K17*(1-1/(4*J17))-($E$19)*SQRT(I17))/SQRT(1+K17^2/(2*J17))))+IF(colas=2,NORMSDIST((-K17*(1-1/(4*J17))-($E$19)*SQRT(I17))/SQRT(1+K17^2/(2*J17))),0)),"") -> 0.073515801 | N17: =IF(ISNUMBER(M17),IF(M17>=potencia,I17,""),"") | O17: =(K17+TINV(2*(1-potencia),J17))/SQRT(I17) -> 0.93823127 | P17: =IFERROR(O17-(((1-NORMSDIST((K17*(1-1/(4*J17))-(O17)*SQRT(I17))/SQRT(1+K17^2/(2*J17))))+IF(colas=2,NORMSDIST((-K17*(1-1/(4*J17))-(O17)*SQRT(I17))/SQRT(1+K17^2/(2*J17))),0))-potencia)/((((1-NORMSDIST((K17*(1-1/(4*J17))-(O17+(0.001*O17))*SQRT(I17))/SQRT(1+K17^2/(2*J17))))+IF(colas=2,NORMSDIST((-K17*(1-1/(4*J17))-(O17+(0.001*O17))*SQRT(I17))/SQRT(1+K17^2/(2*J17))),0))-((1-NORMSDIST((K17*(1-1/(4*J17))-(O17-(0.001*O17))*SQRT(I17))/SQRT(1+K17^2/(2*J17))))+IF(colas=2,NORMSDIST((-K17*(1-1/(4*J17))-(O17-(0.001*O17))*SQRT(I17))/SQRT(1+K17^2/(2*J17))),0)))/(2*(0.001*O17))),O17) -> 0.93826152 | Q17: =IFERROR(P17-(((1-NORMSDIST((K17*(1-1/(4*J17))-(P17)*SQRT(I17))/SQRT(1+K17^2/(2*J17))))+IF(colas=2,NORMSDIST((-K17*(1-1/(4*J17))-(P17)*SQRT(I17))/SQRT(1+K17^2/(2*J17))),0))-potencia)/((((1-NORMSDIST((K17*(1-1/(4*J17))-(P17+(0.001*P17))*SQRT(I17))/SQRT(1+K17^2/(2*J17))))+IF(colas=2,NORMSDIST((-K17*(1-1/(4*J17))-(P17+(0.001*P17))*SQRT(I17))/SQRT(1+K17^2/(2*J17))),0))-((1-NORMSDIST((K17*(1-1/(4*J17))-(P17-(0.001*P17))*SQRT(I17))/SQRT(1+K17^2/(2*J17))))+IF(colas=2,NORMSDIST((-K17*(1-1/(4*J17))-(P17-(0.001*P17))*SQRT(I17))/SQRT(1+K17^2/(2*J17))),0)))/(2*(0.001*P17))),P17) -> 0.93826153 | R17: =IFERROR(Q17-(((1-NORMSDIST((K17*(1-1/(4*J17))-(Q17)*SQRT(I17))/SQRT(1+K17^2/(2*J17))))+IF(colas=2,NORMSDIST((-K17*(1-1/(4*J17))-(Q17)*SQRT(I17))/SQRT(1+K17^2/(2*J17))),0))-potencia)/((((1-NORMSDIST((K17*(1-1/(4*J17))-(Q17+(0.001*Q17))*SQRT(I17))/SQRT(1+K17^2/(2*J17))))+IF(colas=2,NORMSDIST((-K17*(1-1/(4*J17))-(Q17+(0.001*Q17))*SQRT(I17))/SQRT(1+K17^2/(2*J17))),0))-((1-NORMSDIST((K17*(1-1/(4*J17))-(Q17-(0.001*Q17))*SQRT(I17))/SQRT(1+K17^2/(2*J17))))+IF(colas=2,NORMSDIST((-K17*(1-1/(4*J17))-(Q17-(0.001*Q17))*SQRT(I17))/SQRT(1+K17^2/(2*J17))),0)))/(2*(0.001*Q17))),Q17) -> 0.93826153 | S17: =R17 -> 0.93826153
