Workbook
Name alfa: 'Configuración'!$B$17
Name c_luz: 'Configuración'!$B$10
Name conv: 'Configuración'!$B$11
Name corriente: 'Configuración'!$B$5
Name factor_forma: 'Configuración'!$B$12
Name n_fondo: 'Configuración'!$B$13
Name paso: 'Configuración'!$B$8
Name pasos: 'Configuración'!$B$9
Name pfab: 'Configuración'!$B$7
Name pts_min: 'Configuración'!$B$15
Name rec_min: 'Configuración'!$B$16
Name semi: 'Configuración'!$B$14
Name tau0: 'Configuración'!$B$6

Sheet Instrucciones
A1: Medición definitiva del autocorrelador · corriente 6 A (I2)
A2: Fecha prevista: miércoles 28 oct 2026. Nueve réplicas de la misma corriente, una tras otra.
A4: 1. Encender el láser y dejarlo calentar como en el piloto. Fijar la corriente de bombeo en 6 A y anotar en Registro la fecha, la hora de encendido y la potencia media del láser.
A5: 2. Las posiciones del micrómetro están fijas en todas las hojas R01–R09 (columna A, gris): 22 lecturas, de 0 a 210 µm cada 10 µm, contadas desde el punto de partida del barrido. Escoger el punto de partida de modo que el pico caiga en la mitad del recorrido (≈ 100–110 µm). A 5 A la traza es ancha: si el pico queda en 120 µm o más, el barrido no alcanza el ala derecha (el Estado lo avisa).
A6: 3. Girar el micrómetro siempre en el mismo sentido. En cada posición escribir la potencia óptica en W (columna B, amarilla), tal como la da el medidor: por ejemplo 2.35E-05.
A7: 4. En Registro, escribir la hora de inicio y la hora de fin de cada corrida (hh:mm). La duración y el tiempo entre inicios se calculan solos.
A8: 5. Revisar el «Estado de la traza» (columna L del Registro, o la celda M20 de la hoja). Si dice OK o Aviso, seguir. Si dice Revisar, comprobar los datos escritos antes de seguir.
A9: 6. Una traza solo se marca «No» en ¿Válida? por una causa anotada en el momento (el láser perdió los pulsos, la potencia salió de rango, el barrido se interrumpió). Nunca por dar un valor inesperado. Toda traza descartada se repone en la siguiente hoja de reposición (R10, R11, R12).
A10: 7. La hoja Resumen da n, la media, S, el intervalo de confianza del 95 % y la prueba t de una muestra contra τ0 del fabricante. El análisis definitivo (ajuste sech² de toda la traza) se hace después con scripts/trabajo-practico/analiza_piloto.py; aquí se usa el ancho a media altura × 0,65.
A11: Colores: amarillo con letra azul = se llena; gris = fijo; lo demás son fórmulas. Las hojas de traza están protegidas (sin contraseña) para no borrar las posiciones ni las fórmulas.

Sheet Configuración
A1: Configuración
A2: Valores fijos del protocolo. No cambiarlos durante la medición.
A4: Parámetro | B4: Valor | C4: Nota
A5: Corriente de bombeo (A) | B5: 6 | C5: I2 del protocolo; hoja de pruebas de fábrica, tabla 5.
A6: τ0: ancho de pulso del fabricante (fs) | B6: 76 | C6: Tabla 5 de la hoja de pruebas de fábrica.
A7: Potencia media de fábrica (mW) | B7: 378 | C7: Referencia para comparar con la potencia medida.
A8: Paso del micrómetro (µm) | B8: 10 | C8: Fijo, como en el piloto.
A9: Veces que el haz recorre el desplazamiento | B9: 2 | C9: Retrorreflector: τ = 2Δx/c.
A10: Velocidad de la luz c (m/s) | B10: 299792458 | C10: Valor exacto (SI).
A11: Retardo por µm del micrómetro (fs) | B11: =pasos*10^-6/c_luz*10^15 -> 0 | C11: 6,6713 fs por µm.
A12: Factor de forma sech²: τp = factor × Δτ_AC | B12: 0.65 | C12: El que usa Calmar (teórico 0,648).
A13: Lecturas por ala para el fondo | B13: 2 | C13: Promedio de las 2 primeras y las 2 últimas lecturas.
A14: Semiventana de suavizado | B14: 0 | C14: 0 = sin suavizar (programa de análisis fijo).
A15: Lecturas mínimas dentro del ancho a media altura | B15: 4 | C15: Con paso de 10 µm el piloto tuvo 4–5 lecturas dentro del FWHM.
A16: Recorrido mínimo a cada lado del centro (múltiplos de Δτ_AC) | B16: 2 | C16: Si no se alcanza, el fondo sale alto y el ancho corto.
A17: α de la prueba t (dos colas) | B17: 0.05 | C17: Protocolo.

Sheet Registro
A1: Registro de la medición · 6 A (I2)
A2: Amarillo = llenar. Nueve réplicas seguidas a la misma corriente; R10–R12 solo si hay que reponer una traza descartada.
A4: Fecha | B4: miércoles 28 oct 2026 | D4: Encendido del láser | F4: Corriente (A) | G4: =corriente -> 0 | H4: Temperatura del laboratorio (°C) | J4: Responsables:
A6: N° | B6: Hoja | C6: Hora inicio | D6: Hora fin | E6: Duración (min) | F6: Δ inicio a la siguiente (min) | G6: Potencia media del láser (mW) | H6: Posición del pico (µm) | I6: ¿Válida? | J6: Observaciones (causa si no es válida) | K6: Δτ_AC (fs) | L6: τp (fs) | M6: Estado de la traza | N6: τp usable (fs)
A7: 1 | B7: R01 | E7: =IF(AND(ISNUMBER(C7),ISNUMBER(D7)),(D7-C7)*1440,"") -> 0 | F7: =IF(AND(ISNUMBER(C7),ISNUMBER(C8)),(C8-C7)*1440,"") -> 0 | H7: =IFERROR('R01'!$M$19+0,"") -> 0 | I7: Sí | K7: =IFERROR('R01'!$M$12+0,"") -> 0 | L7: =IFERROR('R01'!$M$13+0,"") -> 0 | M7: ='R01'!$M$20 -> 0 | N7: =IF(AND(ISNUMBER(L7),I7<>"No"),L7,"") -> 0
A8: 2 | B8: R02 | E8: =IF(AND(ISNUMBER(C8),ISNUMBER(D8)),(D8-C8)*1440,"") -> 0 | F8: =IF(AND(ISNUMBER(C8),ISNUMBER(C9)),(C9-C8)*1440,"") -> 0 | H8: =IFERROR('R02'!$M$19+0,"") -> 0 | I8: Sí | K8: =IFERROR('R02'!$M$12+0,"") -> 0 | L8: =IFERROR('R02'!$M$13+0,"") -> 0 | M8: ='R02'!$M$20 -> 0 | N8: =IF(AND(ISNUMBER(L8),I8<>"No"),L8,"") -> 0
A9: 3 | B9: R03 | E9: =IF(AND(ISNUMBER(C9),ISNUMBER(D9)),(D9-C9)*1440,"") -> 0 | F9: =IF(AND(ISNUMBER(C9),ISNUMBER(C10)),(C10-C9)*1440,"") -> 0 | H9: =IFERROR('R03'!$M$19+0,"") -> 0 | I9: Sí | K9: =IFERROR('R03'!$M$12+0,"") -> 0 | L9: =IFERROR('R03'!$M$13+0,"") -> 0 | M9: ='R03'!$M$20 -> 0 | N9: =IF(AND(ISNUMBER(L9),I9<>"No"),L9,"") -> 0
A10: 4 | B10: R04 | E10: =IF(AND(ISNUMBER(C10),ISNUMBER(D10)),(D10-C10)*1440,"") -> 0 | F10: =IF(AND(ISNUMBER(C10),ISNUMBER(C11)),(C11-C10)*1440,"") -> 0 | H10: =IFERROR('R04'!$M$19+0,"") -> 0 | I10: Sí | K10: =IFERROR('R04'!$M$12+0,"") -> 0 | L10: =IFERROR('R04'!$M$13+0,"") -> 0 | M10: ='R04'!$M$20 -> 0 | N10: =IF(AND(ISNUMBER(L10),I10<>"No"),L10,"") -> 0
A11: 5 | B11: R05 | E11: =IF(AND(ISNUMBER(C11),ISNUMBER(D11)),(D11-C11)*1440,"") -> 0 | F11: =IF(AND(ISNUMBER(C11),ISNUMBER(C12)),(C12-C11)*1440,"") -> 0 | H11: =IFERROR('R05'!$M$19+0,"") -> 0 | I11: Sí | K11: =IFERROR('R05'!$M$12+0,"") -> 0 | L11: =IFERROR('R05'!$M$13+0,"") -> 0 | M11: ='R05'!$M$20 -> 0 | N11: =IF(AND(ISNUMBER(L11),I11<>"No"),L11,"") -> 0
A12: 6 | B12: R06 | E12: =IF(AND(ISNUMBER(C12),ISNUMBER(D12)),(D12-C12)*1440,"") -> 0 | F12: =IF(AND(ISNUMBER(C12),ISNUMBER(C13)),(C13-C12)*1440,"") -> 0 | H12: =IFERROR('R06'!$M$19+0,"") -> 0 | I12: Sí | K12: =IFERROR('R06'!$M$12+0,"") -> 0 | L12: =IFERROR('R06'!$M$13+0,"") -> 0 | M12: ='R06'!$M$20 -> 0 | N12: =IF(AND(ISNUMBER(L12),I12<>"No"),L12,"") -> 0
A13: 7 | B13: R07 | E13: =IF(AND(ISNUMBER(C13),ISNUMBER(D13)),(D13-C13)*1440,"") -> 0 | F13: =IF(AND(ISNUMBER(C13),ISNUMBER(C14)),(C14-C13)*1440,"") -> 0 | H13: =IFERROR('R07'!$M$19+0,"") -> 0 | I13: Sí | K13: =IFERROR('R07'!$M$12+0,"") -> 0 | L13: =IFERROR('R07'!$M$13+0,"") -> 0 | M13: ='R07'!$M$20 -> 0 | N13: =IF(AND(ISNUMBER(L13),I13<>"No"),L13,"") -> 0
A14: 8 | B14: R08 | E14: =IF(AND(ISNUMBER(C14),ISNUMBER(D14)),(D14-C14)*1440,"") -> 0 | F14: =IF(AND(ISNUMBER(C14),ISNUMBER(C15)),(C15-C14)*1440,"") -> 0 | H14: =IFERROR('R08'!$M$19+0,"") -> 0 | I14: Sí | K14: =IFERROR('R08'!$M$12+0,"") -> 0 | L14: =IFERROR('R08'!$M$13+0,"") -> 0 | M14: ='R08'!$M$20 -> 0 | N14: =IF(AND(ISNUMBER(L14),I14<>"No"),L14,"") -> 0
A15: 9 | B15: R09 | E15: =IF(AND(ISNUMBER(C15),ISNUMBER(D15)),(D15-C15)*1440,"") -> 0 | F15: =IF(AND(ISNUMBER(C15),ISNUMBER(C16)),(C16-C15)*1440,"") -> 0 | H15: =IFERROR('R09'!$M$19+0,"") -> 0 | I15: Sí | K15: =IFERROR('R09'!$M$12+0,"") -> 0 | L15: =IFERROR('R09'!$M$13+0,"") -> 0 | M15: ='R09'!$M$20 -> 0 | N15: =IF(AND(ISNUMBER(L15),I15<>"No"),L15,"") -> 0
A16: 10 | B16: R10 | E16: =IF(AND(ISNUMBER(C16),ISNUMBER(D16)),(D16-C16)*1440,"") -> 0 | F16: =IF(AND(ISNUMBER(C16),ISNUMBER(C17)),(C17-C16)*1440,"") -> 0 | H16: =IFERROR('R10'!$M$19+0,"") -> 0 | J16: Reposición: anotar qué traza reemplaza | K16: =IFERROR('R10'!$M$12+0,"") -> 0 | L16: =IFERROR('R10'!$M$13+0,"") -> 0 | M16: ='R10'!$M$20 -> 0 | N16: =IF(AND(ISNUMBER(L16),I16<>"No"),L16,"") -> 0
A17: 11 | B17: R11 | E17: =IF(AND(ISNUMBER(C17),ISNUMBER(D17)),(D17-C17)*1440,"") -> 0 | F17: =IF(AND(ISNUMBER(C17),ISNUMBER(C18)),(C18-C17)*1440,"") -> 0 | H17: =IFERROR('R11'!$M$19+0,"") -> 0 | J17: Reposición: anotar qué traza reemplaza | K17: =IFERROR('R11'!$M$12+0,"") -> 0 | L17: =IFERROR('R11'!$M$13+0,"") -> 0 | M17: ='R11'!$M$20 -> 0 | N17: =IF(AND(ISNUMBER(L17),I17<>"No"),L17,"") -> 0
A18: 12 | B18: R12 | E18: =IF(AND(ISNUMBER(C18),ISNUMBER(D18)),(D18-C18)*1440,"") -> 0 | H18: =IFERROR('R12'!$M$19+0,"") -> 0 | J18: Reposición: anotar qué traza reemplaza | K18: =IFERROR('R12'!$M$12+0,"") -> 0 | L18: =IFERROR('R12'!$M$13+0,"") -> 0 | M18: ='R12'!$M$20 -> 0 | N18: =IF(AND(ISNUMBER(L18),I18<>"No"),L18,"") -> 0
D20: Media | E20: =IF(COUNT(E7:E18)=0,"",AVERAGE(E7:E18)) -> 0 | F20: =IF(COUNT(F7:F18)=0,"",AVERAGE(F7:F18)) -> 0
D21: Total (h) | E21: =IF(COUNT(C7:D18)<2,"",(MAX(D7:D18)-MIN(C7:C18))*24) -> 0 | F21: del primer inicio al último fin
A23: Reglas del protocolo (sección 5): una traza solo se marca «No» por una causa anotada en el momento (el láser perdió los pulsos, la potencia salió de rango, el barrido se interrumpió). Nunca por dar un valor inesperado. La traza que la reemplaza va en la siguiente hoja de reposición (R10, R11, R12), y se anota en Observaciones a cuál reemplaza.

Sheet Resumen
A1: Resumen y prueba t de una muestra · 6 A
A2: Cuentan las trazas con τp calculado y no marcadas «No» en el Registro (incluidas las de reposición).
A4: Cálculo | B4: Valor | C4: Nota
A5: Réplicas válidas n | B5: =COUNT('Registro'!$N$7:$N$18) -> 0 | C5: Meta: 9.
A6: Media de τp, ȳ (fs) | B6: =IF(B5=0,"",AVERAGE('Registro'!$N$7:$N$18)) -> 0 | C6: Estimador: ancho a media altura × factor sech².
A7: Desviación estándar S (fs) | B7: =IF(B5<2,"",_xlfn.STDEV.S('Registro'!$N$7:$N$18)) -> 0
A8: Coeficiente de variación (%) | B8: =IF(ISNUMBER(B7),100*B7/B6,"") -> 0
A9: τ0 del fabricante (fs) | B9: =tau0 -> 0 | C9: Tabla 5 de la hoja de pruebas.
A10: ȳ − τ0 (fs) | B10: =IF(ISNUMBER(B6),B6-B9,"") -> 0
A11: Estadístico t0 = (ȳ − τ0) / (S/√n) | B11: =IF(ISNUMBER(B7),B10/(B7/SQRT(B5)),"") -> 0 | C11: H0: μ = τ0 frente a H1: μ ≠ τ0.
A12: Grados de libertad n − 1 | B12: =IF(B5>1,B5-1,"") -> 0
A13: t crítico t(α/2, n − 1) | B13: =IF(ISNUMBER(B12),_xlfn.T.INV.2T(alfa,B12),"") -> 0
A14: Valor P (dos colas) | B14: =IF(ISNUMBER(B11),_xlfn.T.DIST.2T(ABS(B11),B12),"") -> 0
A15: Límite inferior del IC 95 % de μ (fs) | B15: =IF(ISNUMBER(B13),B6-B13*B7/SQRT(B5),"") -> 0
A16: Límite superior del IC 95 % de μ (fs) | B16: =IF(ISNUMBER(B13),B6+B13*B7/SQRT(B5),"") -> 0
A17: Decisión | B17: =IF(ISNUMBER(B14),IF(B14<alfa,"Se rechaza H0: el ancho medido difiere de τ0","No se rechaza H0: no hay evidencia de diferencia con τ0"),"") -> 0
A18: Duración media por corrida (min) | B18: ='Registro'!E20 -> 0 | C18: Desde el Registro.
A20: Prueba preliminar con el estimador de la hoja (FWHM × 0,65). El informe usa el ajuste sech² de toda la traza (analiza_piloto.py) y valida los supuestos (normalidad, sin tendencia en el orden de medición).

Sheet R01
A1: Posición del micrómetro (µm) · fija | B1: Potencia óptica (W) | C1: Retardo τ (fs) | D1: Señal suavizada | E1: Señal normalizada | F1: Cruce izq. (fila) | G1: Cruce der. (fila) | H1: τ de cruce (fs) | I1: Retardo centrado (fs) · gráfica | J1: Normalizada · gráfica | K1: Sentido | L1: Traza R01 | M1: 6 A
A2: 0 | C2: =IF(ISNUMBER(A2),A2*conv,"") -> 0 | D2: =IF(ISNUMBER(B2),AVERAGE(INDEX($B$2:$B$23,MAX(1,1-semi)):INDEX($B$2:$B$23,MIN($M$3,1+semi))),"") -> 0 | E2: =IF(AND(ISNUMBER(D2),ISNUMBER($M$4)),(D2-$M$4)/($M$5-$M$4),"") -> 0 | F2: =IF(AND(ISNUMBER(E2),ISNUMBER(E3),ISNUMBER($M$6)),IF(AND(2<$M$6,E2<0.5,E3>=0.5),2,""),"") -> 0 | G2: =IF(AND(ISNUMBER(E2),ISNUMBER(E3),ISNUMBER($M$6)),IF(AND(2>=$M$6,E2>=0.5,E3<0.5),2,""),"") -> 0 | H2: =IF(OR(ISNUMBER(F2),ISNUMBER(G2)),C2+(0.5-E2)*(C3-C2)/(E3-E2),"") -> 0 | I2: =IF(AND(ISNUMBER(E2),ISNUMBER($M$15)),C2-$M$15,NA()) -> 0 | J2: =IF(ISNUMBER(E2),E2,NA()) -> 0 | K2: =IF(AND(ISNUMBER(C2),ISNUMBER(C3)),SIGN(C3-C2),"") -> 0 | L2: Posiciones de la traza | M2: =COUNT($A$2:$A$23) -> 0
A3: 10 | C3: =IF(ISNUMBER(A3),A3*conv,"") -> 0 | D3: =IF(ISNUMBER(B3),AVERAGE(INDEX($B$2:$B$23,MAX(1,2-semi)):INDEX($B$2:$B$23,MIN($M$3,2+semi))),"") -> 0 | E3: =IF(AND(ISNUMBER(D3),ISNUMBER($M$4)),(D3-$M$4)/($M$5-$M$4),"") -> 0 | F3: =IF(AND(ISNUMBER(E3),ISNUMBER(E4),ISNUMBER($M$6)),IF(AND(3<$M$6,E3<0.5,E4>=0.5),3,""),"") -> 0 | G3: =IF(AND(ISNUMBER(E3),ISNUMBER(E4),ISNUMBER($M$6)),IF(AND(3>=$M$6,E3>=0.5,E4<0.5),3,""),"") -> 0 | H3: =IF(OR(ISNUMBER(F3),ISNUMBER(G3)),C3+(0.5-E3)*(C4-C3)/(E4-E3),"") -> 0 | I3: =IF(AND(ISNUMBER(E3),ISNUMBER($M$15)),C3-$M$15,NA()) -> 0 | J3: =IF(ISNUMBER(E3),E3,NA()) -> 0 | K3: =IF(AND(ISNUMBER(C3),ISNUMBER(C4)),SIGN(C4-C3),"") -> 0 | L3: Lecturas de potencia escritas | M3: =COUNT($B$2:$B$23) -> 0
A4: 20 | C4: =IF(ISNUMBER(A4),A4*conv,"") -> 0 | D4: =IF(ISNUMBER(B4),AVERAGE(INDEX($B$2:$B$23,MAX(1,3-semi)):INDEX($B$2:$B$23,MIN($M$3,3+semi))),"") -> 0 | E4: =IF(AND(ISNUMBER(D4),ISNUMBER($M$4)),(D4-$M$4)/($M$5-$M$4),"") -> 0 | F4: =IF(AND(ISNUMBER(E4),ISNUMBER(E5),ISNUMBER($M$6)),IF(AND(4<$M$6,E4<0.5,E5>=0.5),4,""),"") -> 0 | G4: =IF(AND(ISNUMBER(E4),ISNUMBER(E5),ISNUMBER($M$6)),IF(AND(4>=$M$6,E4>=0.5,E5<0.5),4,""),"") -> 0 | H4: =IF(OR(ISNUMBER(F4),ISNUMBER(G4)),C4+(0.5-E4)*(C5-C4)/(E5-E4),"") -> 0 | I4: =IF(AND(ISNUMBER(E4),ISNUMBER($M$15)),C4-$M$15,NA()) -> 0 | J4: =IF(ISNUMBER(E4),E4,NA()) -> 0 | K4: =IF(AND(ISNUMBER(C4),ISNUMBER(C5)),SIGN(C5-C4),"") -> 0 | L4: Fondo (promedio de las alas, W) | M4: =IF($M$3<$M$2,"",(AVERAGE(INDEX($B$2:$B$23,1):INDEX($B$2:$B$23,n_fondo))+AVERAGE(INDEX($B$2:$B$23,$M$3-n_fondo+1):INDEX($B$2:$B$23,$M$3)))/2) -> 0
A5: 30 | C5: =IF(ISNUMBER(A5),A5*conv,"") -> 0 | D5: =IF(ISNUMBER(B5),AVERAGE(INDEX($B$2:$B$23,MAX(1,4-semi)):INDEX($B$2:$B$23,MIN($M$3,4+semi))),"") -> 0 | E5: =IF(AND(ISNUMBER(D5),ISNUMBER($M$4)),(D5-$M$4)/($M$5-$M$4),"") -> 0 | F5: =IF(AND(ISNUMBER(E5),ISNUMBER(E6),ISNUMBER($M$6)),IF(AND(5<$M$6,E5<0.5,E6>=0.5),5,""),"") -> 0 | G5: =IF(AND(ISNUMBER(E5),ISNUMBER(E6),ISNUMBER($M$6)),IF(AND(5>=$M$6,E5>=0.5,E6<0.5),5,""),"") -> 0 | H5: =IF(OR(ISNUMBER(F5),ISNUMBER(G5)),C5+(0.5-E5)*(C6-C5)/(E6-E5),"") -> 0 | I5: =IF(AND(ISNUMBER(E5),ISNUMBER($M$15)),C5-$M$15,NA()) -> 0 | J5: =IF(ISNUMBER(E5),E5,NA()) -> 0 | K5: =IF(AND(ISNUMBER(C5),ISNUMBER(C6)),SIGN(C6-C5),"") -> 0 | L5: Máximo de la señal (W) | M5: =IF($M$3<$M$2,"",MAX($D$2:$D$23)) -> 0
A6: 40 | C6: =IF(ISNUMBER(A6),A6*conv,"") -> 0 | D6: =IF(ISNUMBER(B6),AVERAGE(INDEX($B$2:$B$23,MAX(1,5-semi)):INDEX($B$2:$B$23,MIN($M$3,5+semi))),"") -> 0 | E6: =IF(AND(ISNUMBER(D6),ISNUMBER($M$4)),(D6-$M$4)/($M$5-$M$4),"") -> 0 | F6: =IF(AND(ISNUMBER(E6),ISNUMBER(E7),ISNUMBER($M$6)),IF(AND(6<$M$6,E6<0.5,E7>=0.5),6,""),"") -> 0 | G6: =IF(AND(ISNUMBER(E6),ISNUMBER(E7),ISNUMBER($M$6)),IF(AND(6>=$M$6,E6>=0.5,E7<0.5),6,""),"") -> 0 | H6: =IF(OR(ISNUMBER(F6),ISNUMBER(G6)),C6+(0.5-E6)*(C7-C6)/(E7-E6),"") -> 0 | I6: =IF(AND(ISNUMBER(E6),ISNUMBER($M$15)),C6-$M$15,NA()) -> 0 | J6: =IF(ISNUMBER(E6),E6,NA()) -> 0 | K6: =IF(AND(ISNUMBER(C6),ISNUMBER(C7)),SIGN(C7-C6),"") -> 0 | L6: Fila del máximo | M6: =IFERROR(MATCH($M$5,$D$2:$D$23,0)+1,"") -> 0
A7: 50 | C7: =IF(ISNUMBER(A7),A7*conv,"") -> 0 | D7: =IF(ISNUMBER(B7),AVERAGE(INDEX($B$2:$B$23,MAX(1,6-semi)):INDEX($B$2:$B$23,MIN($M$3,6+semi))),"") -> 0 | E7: =IF(AND(ISNUMBER(D7),ISNUMBER($M$4)),(D7-$M$4)/($M$5-$M$4),"") -> 0 | F7: =IF(AND(ISNUMBER(E7),ISNUMBER(E8),ISNUMBER($M$6)),IF(AND(7<$M$6,E7<0.5,E8>=0.5),7,""),"") -> 0 | G7: =IF(AND(ISNUMBER(E7),ISNUMBER(E8),ISNUMBER($M$6)),IF(AND(7>=$M$6,E7>=0.5,E8<0.5),7,""),"") -> 0 | H7: =IF(OR(ISNUMBER(F7),ISNUMBER(G7)),C7+(0.5-E7)*(C8-C7)/(E8-E7),"") -> 0 | I7: =IF(AND(ISNUMBER(E7),ISNUMBER($M$15)),C7-$M$15,NA()) -> 0 | J7: =IF(ISNUMBER(E7),E7,NA()) -> 0 | K7: =IF(AND(ISNUMBER(C7),ISNUMBER(C8)),SIGN(C8-C7),"") -> 0 | L7: Retardo del máximo (fs) | M7: =IFERROR(INDEX($C$1:$C$23,$M$6),"") -> 0
A8: 60 | C8: =IF(ISNUMBER(A8),A8*conv,"") -> 0 | D8: =IF(ISNUMBER(B8),AVERAGE(INDEX($B$2:$B$23,MAX(1,7-semi)):INDEX($B$2:$B$23,MIN($M$3,7+semi))),"") -> 0 | E8: =IF(AND(ISNUMBER(D8),ISNUMBER($M$4)),(D8-$M$4)/($M$5-$M$4),"") -> 0 | F8: =IF(AND(ISNUMBER(E8),ISNUMBER(E9),ISNUMBER($M$6)),IF(AND(8<$M$6,E8<0.5,E9>=0.5),8,""),"") -> 0 | G8: =IF(AND(ISNUMBER(E8),ISNUMBER(E9),ISNUMBER($M$6)),IF(AND(8>=$M$6,E8>=0.5,E9<0.5),8,""),"") -> 0 | H8: =IF(OR(ISNUMBER(F8),ISNUMBER(G8)),C8+(0.5-E8)*(C9-C8)/(E9-E8),"") -> 0 | I8: =IF(AND(ISNUMBER(E8),ISNUMBER($M$15)),C8-$M$15,NA()) -> 0 | J8: =IF(ISNUMBER(E8),E8,NA()) -> 0 | K8: =IF(AND(ISNUMBER(C8),ISNUMBER(C9)),SIGN(C9-C8),"") -> 0 | L8: Fila del cruce izquierdo a media altura | M8: =MAX($F$2:$F$23) -> 0
A9: 70 | C9: =IF(ISNUMBER(A9),A9*conv,"") -> 0 | D9: =IF(ISNUMBER(B9),AVERAGE(INDEX($B$2:$B$23,MAX(1,8-semi)):INDEX($B$2:$B$23,MIN($M$3,8+semi))),"") -> 0 | E9: =IF(AND(ISNUMBER(D9),ISNUMBER($M$4)),(D9-$M$4)/($M$5-$M$4),"") -> 0 | F9: =IF(AND(ISNUMBER(E9),ISNUMBER(E10),ISNUMBER($M$6)),IF(AND(9<$M$6,E9<0.5,E10>=0.5),9,""),"") -> 0 | G9: =IF(AND(ISNUMBER(E9),ISNUMBER(E10),ISNUMBER($M$6)),IF(AND(9>=$M$6,E9>=0.5,E10<0.5),9,""),"") -> 0 | H9: =IF(OR(ISNUMBER(F9),ISNUMBER(G9)),C9+(0.5-E9)*(C10-C9)/(E10-E9),"") -> 0 | I9: =IF(AND(ISNUMBER(E9),ISNUMBER($M$15)),C9-$M$15,NA()) -> 0 | J9: =IF(ISNUMBER(E9),E9,NA()) -> 0 | K9: =IF(AND(ISNUMBER(C9),ISNUMBER(C10)),SIGN(C10-C9),"") -> 0 | L9: Fila del cruce derecho a media altura | M9: =MIN($G$2:$G$23) -> 0
A10: 80 | C10: =IF(ISNUMBER(A10),A10*conv,"") -> 0 | D10: =IF(ISNUMBER(B10),AVERAGE(INDEX($B$2:$B$23,MAX(1,9-semi)):INDEX($B$2:$B$23,MIN($M$3,9+semi))),"") -> 0 | E10: =IF(AND(ISNUMBER(D10),ISNUMBER($M$4)),(D10-$M$4)/($M$5-$M$4),"") -> 0 | F10: =IF(AND(ISNUMBER(E10),ISNUMBER(E11),ISNUMBER($M$6)),IF(AND(10<$M$6,E10<0.5,E11>=0.5),10,""),"") -> 0 | G10: =IF(AND(ISNUMBER(E10),ISNUMBER(E11),ISNUMBER($M$6)),IF(AND(10>=$M$6,E10>=0.5,E11<0.5),10,""),"") -> 0 | H10: =IF(OR(ISNUMBER(F10),ISNUMBER(G10)),C10+(0.5-E10)*(C11-C10)/(E11-E10),"") -> 0 | I10: =IF(AND(ISNUMBER(E10),ISNUMBER($M$15)),C10-$M$15,NA()) -> 0 | J10: =IF(ISNUMBER(E10),E10,NA()) -> 0 | K10: =IF(AND(ISNUMBER(C10),ISNUMBER(C11)),SIGN(C11-C10),"") -> 0 | L10: τ del cruce izquierdo (fs) | M10: =IF($M$8>0,INDEX($H$1:$H$23,$M$8),"") -> 0
A11: 90 | C11: =IF(ISNUMBER(A11),A11*conv,"") -> 0 | D11: =IF(ISNUMBER(B11),AVERAGE(INDEX($B$2:$B$23,MAX(1,10-semi)):INDEX($B$2:$B$23,MIN($M$3,10+semi))),"") -> 0 | E11: =IF(AND(ISNUMBER(D11),ISNUMBER($M$4)),(D11-$M$4)/($M$5-$M$4),"") -> 0 | F11: =IF(AND(ISNUMBER(E11),ISNUMBER(E12),ISNUMBER($M$6)),IF(AND(11<$M$6,E11<0.5,E12>=0.5),11,""),"") -> 0 | G11: =IF(AND(ISNUMBER(E11),ISNUMBER(E12),ISNUMBER($M$6)),IF(AND(11>=$M$6,E11>=0.5,E12<0.5),11,""),"") -> 0 | H11: =IF(OR(ISNUMBER(F11),ISNUMBER(G11)),C11+(0.5-E11)*(C12-C11)/(E12-E11),"") -> 0 | I11: =IF(AND(ISNUMBER(E11),ISNUMBER($M$15)),C11-$M$15,NA()) -> 0 | J11: =IF(ISNUMBER(E11),E11,NA()) -> 0 | K11: =IF(AND(ISNUMBER(C11),ISNUMBER(C12)),SIGN(C12-C11),"") -> 0 | L11: τ del cruce derecho (fs) | M11: =IF($M$9>0,INDEX($H$1:$H$23,$M$9),"") -> 0
A12: 100 | C12: =IF(ISNUMBER(A12),A12*conv,"") -> 0 | D12: =IF(ISNUMBER(B12),AVERAGE(INDEX($B$2:$B$23,MAX(1,11-semi)):INDEX($B$2:$B$23,MIN($M$3,11+semi))),"") -> 0 | E12: =IF(AND(ISNUMBER(D12),ISNUMBER($M$4)),(D12-$M$4)/($M$5-$M$4),"") -> 0 | F12: =IF(AND(ISNUMBER(E12),ISNUMBER(E13),ISNUMBER($M$6)),IF(AND(12<$M$6,E12<0.5,E13>=0.5),12,""),"") -> 0 | G12: =IF(AND(ISNUMBER(E12),ISNUMBER(E13),ISNUMBER($M$6)),IF(AND(12>=$M$6,E12>=0.5,E13<0.5),12,""),"") -> 0 | H12: =IF(OR(ISNUMBER(F12),ISNUMBER(G12)),C12+(0.5-E12)*(C13-C12)/(E13-E12),"") -> 0 | I12: =IF(AND(ISNUMBER(E12),ISNUMBER($M$15)),C12-$M$15,NA()) -> 0 | J12: =IF(ISNUMBER(E12),E12,NA()) -> 0 | K12: =IF(AND(ISNUMBER(C12),ISNUMBER(C13)),SIGN(C13-C12),"") -> 0 | L12: Ancho de la traza a media altura Δτ_AC (fs) | M12: =IF(AND($M$8>0,$M$9>0),ABS($M$11-$M$10),"") -> 0
A13: 110 | C13: =IF(ISNUMBER(A13),A13*conv,"") -> 0 | D13: =IF(ISNUMBER(B13),AVERAGE(INDEX($B$2:$B$23,MAX(1,12-semi)):INDEX($B$2:$B$23,MIN($M$3,12+semi))),"") -> 0 | E13: =IF(AND(ISNUMBER(D13),ISNUMBER($M$4)),(D13-$M$4)/($M$5-$M$4),"") -> 0 | F13: =IF(AND(ISNUMBER(E13),ISNUMBER(E14),ISNUMBER($M$6)),IF(AND(13<$M$6,E13<0.5,E14>=0.5),13,""),"") -> 0 | G13: =IF(AND(ISNUMBER(E13),ISNUMBER(E14),ISNUMBER($M$6)),IF(AND(13>=$M$6,E13>=0.5,E14<0.5),13,""),"") -> 0 | H13: =IF(OR(ISNUMBER(F13),ISNUMBER(G13)),C13+(0.5-E13)*(C14-C13)/(E14-E13),"") -> 0 | I13: =IF(AND(ISNUMBER(E13),ISNUMBER($M$15)),C13-$M$15,NA()) -> 0 | J13: =IF(ISNUMBER(E13),E13,NA()) -> 0 | K13: =IF(AND(ISNUMBER(C13),ISNUMBER(C14)),SIGN(C14-C13),"") -> 0 | L13: Ancho de pulso τp = factor × Δτ_AC (fs) | M13: =IF(ISNUMBER($M$12),factor_forma*$M$12,"") -> 0
A14: 120 | C14: =IF(ISNUMBER(A14),A14*conv,"") -> 0 | D14: =IF(ISNUMBER(B14),AVERAGE(INDEX($B$2:$B$23,MAX(1,13-semi)):INDEX($B$2:$B$23,MIN($M$3,13+semi))),"") -> 0 | E14: =IF(AND(ISNUMBER(D14),ISNUMBER($M$4)),(D14-$M$4)/($M$5-$M$4),"") -> 0 | F14: =IF(AND(ISNUMBER(E14),ISNUMBER(E15),ISNUMBER($M$6)),IF(AND(14<$M$6,E14<0.5,E15>=0.5),14,""),"") -> 0 | G14: =IF(AND(ISNUMBER(E14),ISNUMBER(E15),ISNUMBER($M$6)),IF(AND(14>=$M$6,E14>=0.5,E15<0.5),14,""),"") -> 0 | H14: =IF(OR(ISNUMBER(F14),ISNUMBER(G14)),C14+(0.5-E14)*(C15-C14)/(E15-E14),"") -> 0 | I14: =IF(AND(ISNUMBER(E14),ISNUMBER($M$15)),C14-$M$15,NA()) -> 0 | J14: =IF(ISNUMBER(E14),E14,NA()) -> 0 | K14: =IF(AND(ISNUMBER(C14),ISNUMBER(C15)),SIGN(C15-C14),"") -> 0 | L14: Referencia: τp si fuera gaussiano (fs) | M14: =IF(ISNUMBER($M$12),0.7071*$M$12,"") -> 0
A15: 130 | C15: =IF(ISNUMBER(A15),A15*conv,"") -> 0 | D15: =IF(ISNUMBER(B15),AVERAGE(INDEX($B$2:$B$23,MAX(1,14-semi)):INDEX($B$2:$B$23,MIN($M$3,14+semi))),"") -> 0 | E15: =IF(AND(ISNUMBER(D15),ISNUMBER($M$4)),(D15-$M$4)/($M$5-$M$4),"") -> 0 | F15: =IF(AND(ISNUMBER(E15),ISNUMBER(E16),ISNUMBER($M$6)),IF(AND(15<$M$6,E15<0.5,E16>=0.5),15,""),"") -> 0 | G15: =IF(AND(ISNUMBER(E15),ISNUMBER(E16),ISNUMBER($M$6)),IF(AND(15>=$M$6,E15>=0.5,E16<0.5),15,""),"") -> 0 | H15: =IF(OR(ISNUMBER(F15),ISNUMBER(G15)),C15+(0.5-E15)*(C16-C15)/(E16-E15),"") -> 0 | I15: =IF(AND(ISNUMBER(E15),ISNUMBER($M$15)),C15-$M$15,NA()) -> 0 | J15: =IF(ISNUMBER(E15),E15,NA()) -> 0 | K15: =IF(AND(ISNUMBER(C15),ISNUMBER(C16)),SIGN(C16-C15),"") -> 0 | L15: Centro de la traza (fs) | M15: =IF(ISNUMBER($M$12),($M$10+$M$11)/2,$M$7) -> 0
A16: 140 | C16: =IF(ISNUMBER(A16),A16*conv,"") -> 0 | D16: =IF(ISNUMBER(B16),AVERAGE(INDEX($B$2:$B$23,MAX(1,15-semi)):INDEX($B$2:$B$23,MIN($M$3,15+semi))),"") -> 0 | E16: =IF(AND(ISNUMBER(D16),ISNUMBER($M$4)),(D16-$M$4)/($M$5-$M$4),"") -> 0 | F16: =IF(AND(ISNUMBER(E16),ISNUMBER(E17),ISNUMBER($M$6)),IF(AND(16<$M$6,E16<0.5,E17>=0.5),16,""),"") -> 0 | G16: =IF(AND(ISNUMBER(E16),ISNUMBER(E17),ISNUMBER($M$6)),IF(AND(16>=$M$6,E16>=0.5,E17<0.5),16,""),"") -> 0 | H16: =IF(OR(ISNUMBER(F16),ISNUMBER(G16)),C16+(0.5-E16)*(C17-C16)/(E17-E16),"") -> 0 | I16: =IF(AND(ISNUMBER(E16),ISNUMBER($M$15)),C16-$M$15,NA()) -> 0 | J16: =IF(ISNUMBER(E16),E16,NA()) -> 0 | K16: =IF(AND(ISNUMBER(C16),ISNUMBER(C17)),SIGN(C17-C16),"") -> 0 | L16: Lecturas dentro del ancho a media altura | M16: =COUNTIF($E$2:$E$23,">=0.5") -> 0
A17: 150 | C17: =IF(ISNUMBER(A17),A17*conv,"") -> 0 | D17: =IF(ISNUMBER(B17),AVERAGE(INDEX($B$2:$B$23,MAX(1,16-semi)):INDEX($B$2:$B$23,MIN($M$3,16+semi))),"") -> 0 | E17: =IF(AND(ISNUMBER(D17),ISNUMBER($M$4)),(D17-$M$4)/($M$5-$M$4),"") -> 0 | F17: =IF(AND(ISNUMBER(E17),ISNUMBER(E18),ISNUMBER($M$6)),IF(AND(17<$M$6,E17<0.5,E18>=0.5),17,""),"") -> 0 | G17: =IF(AND(ISNUMBER(E17),ISNUMBER(E18),ISNUMBER($M$6)),IF(AND(17>=$M$6,E17>=0.5,E18<0.5),17,""),"") -> 0 | H17: =IF(OR(ISNUMBER(F17),ISNUMBER(G17)),C17+(0.5-E17)*(C18-C17)/(E18-E17),"") -> 0 | I17: =IF(AND(ISNUMBER(E17),ISNUMBER($M$15)),C17-$M$15,NA()) -> 0 | J17: =IF(ISNUMBER(E17),E17,NA()) -> 0 | K17: =IF(AND(ISNUMBER(C17),ISNUMBER(C18)),SIGN(C18-C17),"") -> 0 | L17: Recorrido a la izquierda del centro (fs) | M17: =IFERROR($M$15-MIN($C$2:$C$23),"") -> 0
A18: 160 | C18: =IF(ISNUMBER(A18),A18*conv,"") -> 0 | D18: =IF(ISNUMBER(B18),AVERAGE(INDEX($B$2:$B$23,MAX(1,17-semi)):INDEX($B$2:$B$23,MIN($M$3,17+semi))),"") -> 0 | E18: =IF(AND(ISNUMBER(D18),ISNUMBER($M$4)),(D18-$M$4)/($M$5-$M$4),"") -> 0 | F18: =IF(AND(ISNUMBER(E18),ISNUMBER(E19),ISNUMBER($M$6)),IF(AND(18<$M$6,E18<0.5,E19>=0.5),18,""),"") -> 0 | G18: =IF(AND(ISNUMBER(E18),ISNUMBER(E19),ISNUMBER($M$6)),IF(AND(18>=$M$6,E18>=0.5,E19<0.5),18,""),"") -> 0 | H18: =IF(OR(ISNUMBER(F18),ISNUMBER(G18)),C18+(0.5-E18)*(C19-C18)/(E19-E18),"") -> 0 | I18: =IF(AND(ISNUMBER(E18),ISNUMBER($M$15)),C18-$M$15,NA()) -> 0 | J18: =IF(ISNUMBER(E18),E18,NA()) -> 0 | K18: =IF(AND(ISNUMBER(C18),ISNUMBER(C19)),SIGN(C19-C18),"") -> 0 | L18: Recorrido a la derecha del centro (fs) | M18: =IFERROR(MAX($C$2:$C$23)-$M$15,"") -> 0
A19: 170 | C19: =IF(ISNUMBER(A19),A19*conv,"") -> 0 | D19: =IF(ISNUMBER(B19),AVERAGE(INDEX($B$2:$B$23,MAX(1,18-semi)):INDEX($B$2:$B$23,MIN($M$3,18+semi))),"") -> 0 | E19: =IF(AND(ISNUMBER(D19),ISNUMBER($M$4)),(D19-$M$4)/($M$5-$M$4),"") -> 0 | F19: =IF(AND(ISNUMBER(E19),ISNUMBER(E20),ISNUMBER($M$6)),IF(AND(19<$M$6,E19<0.5,E20>=0.5),19,""),"") -> 0 | G19: =IF(AND(ISNUMBER(E19),ISNUMBER(E20),ISNUMBER($M$6)),IF(AND(19>=$M$6,E19>=0.5,E20<0.5),19,""),"") -> 0 | H19: =IF(OR(ISNUMBER(F19),ISNUMBER(G19)),C19+(0.5-E19)*(C20-C19)/(E20-E19),"") -> 0 | I19: =IF(AND(ISNUMBER(E19),ISNUMBER($M$15)),C19-$M$15,NA()) -> 0 | J19: =IF(ISNUMBER(E19),E19,NA()) -> 0 | K19: =IF(AND(ISNUMBER(C19),ISNUMBER(C20)),SIGN(C20-C19),"") -> 0 | L19: Posición del pico (µm) | M19: =IF($M$3<$M$2,"",IFERROR(INDEX($A$1:$A$23,$M$6),"")) -> 0
A20: 180 | C20: =IF(ISNUMBER(A20),A20*conv,"") -> 0 | D20: =IF(ISNUMBER(B20),AVERAGE(INDEX($B$2:$B$23,MAX(1,19-semi)):INDEX($B$2:$B$23,MIN($M$3,19+semi))),"") -> 0 | E20: =IF(AND(ISNUMBER(D20),ISNUMBER($M$4)),(D20-$M$4)/($M$5-$M$4),"") -> 0 | F20: =IF(AND(ISNUMBER(E20),ISNUMBER(E21),ISNUMBER($M$6)),IF(AND(20<$M$6,E20<0.5,E21>=0.5),20,""),"") -> 0 | G20: =IF(AND(ISNUMBER(E20),ISNUMBER(E21),ISNUMBER($M$6)),IF(AND(20>=$M$6,E20>=0.5,E21<0.5),20,""),"") -> 0 | H20: =IF(OR(ISNUMBER(F20),ISNUMBER(G20)),C20+(0.5-E20)*(C21-C20)/(E21-E20),"") -> 0 | I20: =IF(AND(ISNUMBER(E20),ISNUMBER($M$15)),C20-$M$15,NA()) -> 0 | J20: =IF(ISNUMBER(E20),E20,NA()) -> 0 | K20: =IF(AND(ISNUMBER(C20),ISNUMBER(C21)),SIGN(C21-C20),"") -> 0 | L20: Estado de la traza | M20: =IF($M$3=0,"Sin datos",IF($M$3<$M$2,"Incompleta: faltan lecturas de potencia",IF(OR($M$8=0,$M$9=0),"Revisar: no se hallaron los dos cruces de media altura",IF($M$16<pts_min,"Aviso: pocas lecturas dentro del ancho a media altura",IF(MIN($M$17,$M$18)<rec_min*$M$12,"Aviso: el pico está corrido; el barrido no llega a una de las alas","OK"))))) -> 0
A21: 190 | C21: =IF(ISNUMBER(A21),A21*conv,"") -> 0 | D21: =IF(ISNUMBER(B21),AVERAGE(INDEX($B$2:$B$23,MAX(1,20-semi)):INDEX($B$2:$B$23,MIN($M$3,20+semi))),"") -> 0 | E21: =IF(AND(ISNUMBER(D21),ISNUMBER($M$4)),(D21-$M$4)/($M$5-$M$4),"") -> 0 | F21: =IF(AND(ISNUMBER(E21),ISNUMBER(E22),ISNUMBER($M$6)),IF(AND(21<$M$6,E21<0.5,E22>=0.5),21,""),"") -> 0 | G21: =IF(AND(ISNUMBER(E21),ISNUMBER(E22),ISNUMBER($M$6)),IF(AND(21>=$M$6,E21>=0.5,E22<0.5),21,""),"") -> 0 | H21: =IF(OR(ISNUMBER(F21),ISNUMBER(G21)),C21+(0.5-E21)*(C22-C21)/(E22-E21),"") -> 0 | I21: =IF(AND(ISNUMBER(E21),ISNUMBER($M$15)),C21-$M$15,NA()) -> 0 | J21: =IF(ISNUMBER(E21),E21,NA()) -> 0 | K21: =IF(AND(ISNUMBER(C21),ISNUMBER(C22)),SIGN(C22-C21),"") -> 0
A22: 200 | C22: =IF(ISNUMBER(A22),A22*conv,"") -> 0 | D22: =IF(ISNUMBER(B22),AVERAGE(INDEX($B$2:$B$23,MAX(1,21-semi)):INDEX($B$2:$B$23,MIN($M$3,21+semi))),"") -> 0 | E22: =IF(AND(ISNUMBER(D22),ISNUMBER($M$4)),(D22-$M$4)/($M$5-$M$4),"") -> 0 | F22: =IF(AND(ISNUMBER(E22),ISNUMBER(E23),ISNUMBER($M$6)),IF(AND(22<$M$6,E22<0.5,E23>=0.5),22,""),"") -> 0 | G22: =IF(AND(ISNUMBER(E22),ISNUMBER(E23),ISNUMBER($M$6)),IF(AND(22>=$M$6,E22>=0.5,E23<0.5),22,""),"") -> 0 | H22: =IF(OR(ISNUMBER(F22),ISNUMBER(G22)),C22+(0.5-E22)*(C23-C22)/(E23-E22),"") -> 0 | I22: =IF(AND(ISNUMBER(E22),ISNUMBER($M$15)),C22-$M$15,NA()) -> 0 | J22: =IF(ISNUMBER(E22),E22,NA()) -> 0 | K22: =IF(AND(ISNUMBER(C22),ISNUMBER(C23)),SIGN(C23-C22),"") -> 0 | L22: Línea de media altura (gráfica)
A23: 210 | C23: =IF(ISNUMBER(A23),A23*conv,"") -> 0 | D23: =IF(ISNUMBER(B23),AVERAGE(INDEX($B$2:$B$23,MAX(1,22-semi)):INDEX($B$2:$B$23,MIN($M$3,22+semi))),"") -> 0 | E23: =IF(AND(ISNUMBER(D23),ISNUMBER($M$4)),(D23-$M$4)/($M$5-$M$4),"") -> 0 | F23: =IF(AND(ISNUMBER(E23),ISNUMBER(E24),ISNUMBER($M$6)),IF(AND(23<$M$6,E23<0.5,E24>=0.5),23,""),"") -> 0 | G23: =IF(AND(ISNUMBER(E23),ISNUMBER(E24),ISNUMBER($M$6)),IF(AND(23>=$M$6,E23>=0.5,E24<0.5),23,""),"") -> 0 | H23: =IF(OR(ISNUMBER(F23),ISNUMBER(G23)),C23+(0.5-E23)*(C24-C23)/(E24-E23),"") -> 0 | I23: =IF(AND(ISNUMBER(E23),ISNUMBER($M$15)),C23-$M$15,NA()) -> 0 | J23: =IF(ISNUMBER(E23),E23,NA()) -> 0 | K23: =IF(AND(ISNUMBER(C23),ISNUMBER(C24)),SIGN(C24-C23),"") -> 0 | L23: =IF(ISNUMBER($M$12),$M$10-$M$15,NA()) -> 0 | M23: =IF(ISNUMBER($M$12),0.5,NA()) -> 0
L24: =IF(ISNUMBER($M$12),$M$11-$M$15,NA()) -> 0 | M24: =IF(ISNUMBER($M$12),0.5,NA()) -> 0
L26: Solo se llena la columna B (potencia en W), en el orden de las posiciones.

Sheet R02
A1: Posición del micrómetro (µm) · fija | B1: Potencia óptica (W) | C1: Retardo τ (fs) | D1: Señal suavizada | E1: Señal normalizada | F1: Cruce izq. (fila) | G1: Cruce der. (fila) | H1: τ de cruce (fs) | I1: Retardo centrado (fs) · gráfica | J1: Normalizada · gráfica | K1: Sentido | L1: Traza R02 | M1: 6 A
A2: 0 | C2: =IF(ISNUMBER(A2),A2*conv,"") -> 0 | D2: =IF(ISNUMBER(B2),AVERAGE(INDEX($B$2:$B$23,MAX(1,1-semi)):INDEX($B$2:$B$23,MIN($M$3,1+semi))),"") -> 0 | E2: =IF(AND(ISNUMBER(D2),ISNUMBER($M$4)),(D2-$M$4)/($M$5-$M$4),"") -> 0 | F2: =IF(AND(ISNUMBER(E2),ISNUMBER(E3),ISNUMBER($M$6)),IF(AND(2<$M$6,E2<0.5,E3>=0.5),2,""),"") -> 0 | G2: =IF(AND(ISNUMBER(E2),ISNUMBER(E3),ISNUMBER($M$6)),IF(AND(2>=$M$6,E2>=0.5,E3<0.5),2,""),"") -> 0 | H2: =IF(OR(ISNUMBER(F2),ISNUMBER(G2)),C2+(0.5-E2)*(C3-C2)/(E3-E2),"") -> 0 | I2: =IF(AND(ISNUMBER(E2),ISNUMBER($M$15)),C2-$M$15,NA()) -> 0 | J2: =IF(ISNUMBER(E2),E2,NA()) -> 0 | K2: =IF(AND(ISNUMBER(C2),ISNUMBER(C3)),SIGN(C3-C2),"") -> 0 | L2: Posiciones de la traza | M2: =COUNT($A$2:$A$23) -> 0
A3: 10 | C3: =IF(ISNUMBER(A3),A3*conv,"") -> 0 | D3: =IF(ISNUMBER(B3),AVERAGE(INDEX($B$2:$B$23,MAX(1,2-semi)):INDEX($B$2:$B$23,MIN($M$3,2+semi))),"") -> 0 | E3: =IF(AND(ISNUMBER(D3),ISNUMBER($M$4)),(D3-$M$4)/($M$5-$M$4),"") -> 0 | F3: =IF(AND(ISNUMBER(E3),ISNUMBER(E4),ISNUMBER($M$6)),IF(AND(3<$M$6,E3<0.5,E4>=0.5),3,""),"") -> 0 | G3: =IF(AND(ISNUMBER(E3),ISNUMBER(E4),ISNUMBER($M$6)),IF(AND(3>=$M$6,E3>=0.5,E4<0.5),3,""),"") -> 0 | H3: =IF(OR(ISNUMBER(F3),ISNUMBER(G3)),C3+(0.5-E3)*(C4-C3)/(E4-E3),"") -> 0 | I3: =IF(AND(ISNUMBER(E3),ISNUMBER($M$15)),C3-$M$15,NA()) -> 0 | J3: =IF(ISNUMBER(E3),E3,NA()) -> 0 | K3: =IF(AND(ISNUMBER(C3),ISNUMBER(C4)),SIGN(C4-C3),"") -> 0 | L3: Lecturas de potencia escritas | M3: =COUNT($B$2:$B$23) -> 0
A4: 20 | C4: =IF(ISNUMBER(A4),A4*conv,"") -> 0 | D4: =IF(ISNUMBER(B4),AVERAGE(INDEX($B$2:$B$23,MAX(1,3-semi)):INDEX($B$2:$B$23,MIN($M$3,3+semi))),"") -> 0 | E4: =IF(AND(ISNUMBER(D4),ISNUMBER($M$4)),(D4-$M$4)/($M$5-$M$4),"") -> 0 | F4: =IF(AND(ISNUMBER(E4),ISNUMBER(E5),ISNUMBER($M$6)),IF(AND(4<$M$6,E4<0.5,E5>=0.5),4,""),"") -> 0 | G4: =IF(AND(ISNUMBER(E4),ISNUMBER(E5),ISNUMBER($M$6)),IF(AND(4>=$M$6,E4>=0.5,E5<0.5),4,""),"") -> 0 | H4: =IF(OR(ISNUMBER(F4),ISNUMBER(G4)),C4+(0.5-E4)*(C5-C4)/(E5-E4),"") -> 0 | I4: =IF(AND(ISNUMBER(E4),ISNUMBER($M$15)),C4-$M$15,NA()) -> 0 | J4: =IF(ISNUMBER(E4),E4,NA()) -> 0 | K4: =IF(AND(ISNUMBER(C4),ISNUMBER(C5)),SIGN(C5-C4),"") -> 0 | L4: Fondo (promedio de las alas, W) | M4: =IF($M$3<$M$2,"",(AVERAGE(INDEX($B$2:$B$23,1):INDEX($B$2:$B$23,n_fondo))+AVERAGE(INDEX($B$2:$B$23,$M$3-n_fondo+1):INDEX($B$2:$B$23,$M$3)))/2) -> 0
A5: 30 | C5: =IF(ISNUMBER(A5),A5*conv,"") -> 0 | D5: =IF(ISNUMBER(B5),AVERAGE(INDEX($B$2:$B$23,MAX(1,4-semi)):INDEX($B$2:$B$23,MIN($M$3,4+semi))),"") -> 0 | E5: =IF(AND(ISNUMBER(D5),ISNUMBER($M$4)),(D5-$M$4)/($M$5-$M$4),"") -> 0 | F5: =IF(AND(ISNUMBER(E5),ISNUMBER(E6),ISNUMBER($M$6)),IF(AND(5<$M$6,E5<0.5,E6>=0.5),5,""),"") -> 0 | G5: =IF(AND(ISNUMBER(E5),ISNUMBER(E6),ISNUMBER($M$6)),IF(AND(5>=$M$6,E5>=0.5,E6<0.5),5,""),"") -> 0 | H5: =IF(OR(ISNUMBER(F5),ISNUMBER(G5)),C5+(0.5-E5)*(C6-C5)/(E6-E5),"") -> 0 | I5: =IF(AND(ISNUMBER(E5),ISNUMBER($M$15)),C5-$M$15,NA()) -> 0 | J5: =IF(ISNUMBER(E5),E5,NA()) -> 0 | K5: =IF(AND(ISNUMBER(C5),ISNUMBER(C6)),SIGN(C6-C5),"") -> 0 | L5: Máximo de la señal (W) | M5: =IF($M$3<$M$2,"",MAX($D$2:$D$23)) -> 0
A6: 40 | C6: =IF(ISNUMBER(A6),A6*conv,"") -> 0 | D6: =IF(ISNUMBER(B6),AVERAGE(INDEX($B$2:$B$23,MAX(1,5-semi)):INDEX($B$2:$B$23,MIN($M$3,5+semi))),"") -> 0 | E6: =IF(AND(ISNUMBER(D6),ISNUMBER($M$4)),(D6-$M$4)/($M$5-$M$4),"") -> 0 | F6: =IF(AND(ISNUMBER(E6),ISNUMBER(E7),ISNUMBER($M$6)),IF(AND(6<$M$6,E6<0.5,E7>=0.5),6,""),"") -> 0 | G6: =IF(AND(ISNUMBER(E6),ISNUMBER(E7),ISNUMBER($M$6)),IF(AND(6>=$M$6,E6>=0.5,E7<0.5),6,""),"") -> 0 | H6: =IF(OR(ISNUMBER(F6),ISNUMBER(G6)),C6+(0.5-E6)*(C7-C6)/(E7-E6),"") -> 0 | I6: =IF(AND(ISNUMBER(E6),ISNUMBER($M$15)),C6-$M$15,NA()) -> 0 | J6: =IF(ISNUMBER(E6),E6,NA()) -> 0 | K6: =IF(AND(ISNUMBER(C6),ISNUMBER(C7)),SIGN(C7-C6),"") -> 0 | L6: Fila del máximo | M6: =IFERROR(MATCH($M$5,$D$2:$D$23,0)+1,"") -> 0
A7: 50 | C7: =IF(ISNUMBER(A7),A7*conv,"") -> 0 | D7: =IF(ISNUMBER(B7),AVERAGE(INDEX($B$2:$B$23,MAX(1,6-semi)):INDEX($B$2:$B$23,MIN($M$3,6+semi))),"") -> 0 | E7: =IF(AND(ISNUMBER(D7),ISNUMBER($M$4)),(D7-$M$4)/($M$5-$M$4),"") -> 0 | F7: =IF(AND(ISNUMBER(E7),ISNUMBER(E8),ISNUMBER($M$6)),IF(AND(7<$M$6,E7<0.5,E8>=0.5),7,""),"") -> 0 | G7: =IF(AND(ISNUMBER(E7),ISNUMBER(E8),ISNUMBER($M$6)),IF(AND(7>=$M$6,E7>=0.5,E8<0.5),7,""),"") -> 0 | H7: =IF(OR(ISNUMBER(F7),ISNUMBER(G7)),C7+(0.5-E7)*(C8-C7)/(E8-E7),"") -> 0 | I7: =IF(AND(ISNUMBER(E7),ISNUMBER($M$15)),C7-$M$15,NA()) -> 0 | J7: =IF(ISNUMBER(E7),E7,NA()) -> 0 | K7: =IF(AND(ISNUMBER(C7),ISNUMBER(C8)),SIGN(C8-C7),"") -> 0 | L7: Retardo del máximo (fs) | M7: =IFERROR(INDEX($C$1:$C$23,$M$6),"") -> 0
A8: 60 | C8: =IF(ISNUMBER(A8),A8*conv,"") -> 0 | D8: =IF(ISNUMBER(B8),AVERAGE(INDEX($B$2:$B$23,MAX(1,7-semi)):INDEX($B$2:$B$23,MIN($M$3,7+semi))),"") -> 0 | E8: =IF(AND(ISNUMBER(D8),ISNUMBER($M$4)),(D8-$M$4)/($M$5-$M$4),"") -> 0 | F8: =IF(AND(ISNUMBER(E8),ISNUMBER(E9),ISNUMBER($M$6)),IF(AND(8<$M$6,E8<0.5,E9>=0.5),8,""),"") -> 0 | G8: =IF(AND(ISNUMBER(E8),ISNUMBER(E9),ISNUMBER($M$6)),IF(AND(8>=$M$6,E8>=0.5,E9<0.5),8,""),"") -> 0 | H8: =IF(OR(ISNUMBER(F8),ISNUMBER(G8)),C8+(0.5-E8)*(C9-C8)/(E9-E8),"") -> 0 | I8: =IF(AND(ISNUMBER(E8),ISNUMBER($M$15)),C8-$M$15,NA()) -> 0 | J8: =IF(ISNUMBER(E8),E8,NA()) -> 0 | K8: =IF(AND(ISNUMBER(C8),ISNUMBER(C9)),SIGN(C9-C8),"") -> 0 | L8: Fila del cruce izquierdo a media altura | M8: =MAX($F$2:$F$23) -> 0
A9: 70 | C9: =IF(ISNUMBER(A9),A9*conv,"") -> 0 | D9: =IF(ISNUMBER(B9),AVERAGE(INDEX($B$2:$B$23,MAX(1,8-semi)):INDEX($B$2:$B$23,MIN($M$3,8+semi))),"") -> 0 | E9: =IF(AND(ISNUMBER(D9),ISNUMBER($M$4)),(D9-$M$4)/($M$5-$M$4),"") -> 0 | F9: =IF(AND(ISNUMBER(E9),ISNUMBER(E10),ISNUMBER($M$6)),IF(AND(9<$M$6,E9<0.5,E10>=0.5),9,""),"") -> 0 | G9: =IF(AND(ISNUMBER(E9),ISNUMBER(E10),ISNUMBER($M$6)),IF(AND(9>=$M$6,E9>=0.5,E10<0.5),9,""),"") -> 0 | H9: =IF(OR(ISNUMBER(F9),ISNUMBER(G9)),C9+(0.5-E9)*(C10-C9)/(E10-E9),"") -> 0 | I9: =IF(AND(ISNUMBER(E9),ISNUMBER($M$15)),C9-$M$15,NA()) -> 0 | J9: =IF(ISNUMBER(E9),E9,NA()) -> 0 | K9: =IF(AND(ISNUMBER(C9),ISNUMBER(C10)),SIGN(C10-C9),"") -> 0 | L9: Fila del cruce derecho a media altura | M9: =MIN($G$2:$G$23) -> 0
A10: 80 | C10: =IF(ISNUMBER(A10),A10*conv,"") -> 0 | D10: =IF(ISNUMBER(B10),AVERAGE(INDEX($B$2:$B$23,MAX(1,9-semi)):INDEX($B$2:$B$23,MIN($M$3,9+semi))),"") -> 0 | E10: =IF(AND(ISNUMBER(D10),ISNUMBER($M$4)),(D10-$M$4)/($M$5-$M$4),"") -> 0 | F10: =IF(AND(ISNUMBER(E10),ISNUMBER(E11),ISNUMBER($M$6)),IF(AND(10<$M$6,E10<0.5,E11>=0.5),10,""),"") -> 0 | G10: =IF(AND(ISNUMBER(E10),ISNUMBER(E11),ISNUMBER($M$6)),IF(AND(10>=$M$6,E10>=0.5,E11<0.5),10,""),"") -> 0 | H10: =IF(OR(ISNUMBER(F10),ISNUMBER(G10)),C10+(0.5-E10)*(C11-C10)/(E11-E10),"") -> 0 | I10: =IF(AND(ISNUMBER(E10),ISNUMBER($M$15)),C10-$M$15,NA()) -> 0 | J10: =IF(ISNUMBER(E10),E10,NA()) -> 0 | K10: =IF(AND(ISNUMBER(C10),ISNUMBER(C11)),SIGN(C11-C10),"") -> 0 | L10: τ del cruce izquierdo (fs) | M10: =IF($M$8>0,INDEX($H$1:$H$23,$M$8),"") -> 0
A11: 90 | C11: =IF(ISNUMBER(A11),A11*conv,"") -> 0 | D11: =IF(ISNUMBER(B11),AVERAGE(INDEX($B$2:$B$23,MAX(1,10-semi)):INDEX($B$2:$B$23,MIN($M$3,10+semi))),"") -> 0 | E11: =IF(AND(ISNUMBER(D11),ISNUMBER($M$4)),(D11-$M$4)/($M$5-$M$4),"") -> 0 | F11: =IF(AND(ISNUMBER(E11),ISNUMBER(E12),ISNUMBER($M$6)),IF(AND(11<$M$6,E11<0.5,E12>=0.5),11,""),"") -> 0 | G11: =IF(AND(ISNUMBER(E11),ISNUMBER(E12),ISNUMBER($M$6)),IF(AND(11>=$M$6,E11>=0.5,E12<0.5),11,""),"") -> 0 | H11: =IF(OR(ISNUMBER(F11),ISNUMBER(G11)),C11+(0.5-E11)*(C12-C11)/(E12-E11),"") -> 0 | I11: =IF(AND(ISNUMBER(E11),ISNUMBER($M$15)),C11-$M$15,NA()) -> 0 | J11: =IF(ISNUMBER(E11),E11,NA()) -> 0 | K11: =IF(AND(ISNUMBER(C11),ISNUMBER(C12)),SIGN(C12-C11),"") -> 0 | L11: τ del cruce derecho (fs) | M11: =IF($M$9>0,INDEX($H$1:$H$23,$M$9),"") -> 0
A12: 100 | C12: =IF(ISNUMBER(A12),A12*conv,"") -> 0 | D12: =IF(ISNUMBER(B12),AVERAGE(INDEX($B$2:$B$23,MAX(1,11-semi)):INDEX($B$2:$B$23,MIN($M$3,11+semi))),"") -> 0 | E12: =IF(AND(ISNUMBER(D12),ISNUMBER($M$4)),(D12-$M$4)/($M$5-$M$4),"") -> 0 | F12: =IF(AND(ISNUMBER(E12),ISNUMBER(E13),ISNUMBER($M$6)),IF(AND(12<$M$6,E12<0.5,E13>=0.5),12,""),"") -> 0 | G12: =IF(AND(ISNUMBER(E12),ISNUMBER(E13),ISNUMBER($M$6)),IF(AND(12>=$M$6,E12>=0.5,E13<0.5),12,""),"") -> 0 | H12: =IF(OR(ISNUMBER(F12),ISNUMBER(G12)),C12+(0.5-E12)*(C13-C12)/(E13-E12),"") -> 0 | I12: =IF(AND(ISNUMBER(E12),ISNUMBER($M$15)),C12-$M$15,NA()) -> 0 | J12: =IF(ISNUMBER(E12),E12,NA()) -> 0 | K12: =IF(AND(ISNUMBER(C12),ISNUMBER(C13)),SIGN(C13-C12),"") -> 0 | L12: Ancho de la traza a media altura Δτ_AC (fs) | M12: =IF(AND($M$8>0,$M$9>0),ABS($M$11-$M$10),"") -> 0
A13: 110 | C13: =IF(ISNUMBER(A13),A13*conv,"") -> 0 | D13: =IF(ISNUMBER(B13),AVERAGE(INDEX($B$2:$B$23,MAX(1,12-semi)):INDEX($B$2:$B$23,MIN($M$3,12+semi))),"") -> 0 | E13: =IF(AND(ISNUMBER(D13),ISNUMBER($M$4)),(D13-$M$4)/($M$5-$M$4),"") -> 0 | F13: =IF(AND(ISNUMBER(E13),ISNUMBER(E14),ISNUMBER($M$6)),IF(AND(13<$M$6,E13<0.5,E14>=0.5),13,""),"") -> 0 | G13: =IF(AND(ISNUMBER(E13),ISNUMBER(E14),ISNUMBER($M$6)),IF(AND(13>=$M$6,E13>=0.5,E14<0.5),13,""),"") -> 0 | H13: =IF(OR(ISNUMBER(F13),ISNUMBER(G13)),C13+(0.5-E13)*(C14-C13)/(E14-E13),"") -> 0 | I13: =IF(AND(ISNUMBER(E13),ISNUMBER($M$15)),C13-$M$15,NA()) -> 0 | J13: =IF(ISNUMBER(E13),E13,NA()) -> 0 | K13: =IF(AND(ISNUMBER(C13),ISNUMBER(C14)),SIGN(C14-C13),"") -> 0 | L13: Ancho de pulso τp = factor × Δτ_AC (fs) | M13: =IF(ISNUMBER($M$12),factor_forma*$M$12,"") -> 0
A14: 120 | C14: =IF(ISNUMBER(A14),A14*conv,"") -> 0 | D14: =IF(ISNUMBER(B14),AVERAGE(INDEX($B$2:$B$23,MAX(1,13-semi)):INDEX($B$2:$B$23,MIN($M$3,13+semi))),"") -> 0 | E14: =IF(AND(ISNUMBER(D14),ISNUMBER($M$4)),(D14-$M$4)/($M$5-$M$4),"") -> 0 | F14: =IF(AND(ISNUMBER(E14),ISNUMBER(E15),ISNUMBER($M$6)),IF(AND(14<$M$6,E14<0.5,E15>=0.5),14,""),"") -> 0 | G14: =IF(AND(ISNUMBER(E14),ISNUMBER(E15),ISNUMBER($M$6)),IF(AND(14>=$M$6,E14>=0.5,E15<0.5),14,""),"") -> 0 | H14: =IF(OR(ISNUMBER(F14),ISNUMBER(G14)),C14+(0.5-E14)*(C15-C14)/(E15-E14),"") -> 0 | I14: =IF(AND(ISNUMBER(E14),ISNUMBER($M$15)),C14-$M$15,NA()) -> 0 | J14: =IF(ISNUMBER(E14),E14,NA()) -> 0 | K14: =IF(AND(ISNUMBER(C14),ISNUMBER(C15)),SIGN(C15-C14),"") -> 0 | L14: Referencia: τp si fuera gaussiano (fs) | M14: =IF(ISNUMBER($M$12),0.7071*$M$12,"") -> 0
A15: 130 | C15: =IF(ISNUMBER(A15),A15*conv,"") -> 0 | D15: =IF(ISNUMBER(B15),AVERAGE(INDEX($B$2:$B$23,MAX(1,14-semi)):INDEX($B$2:$B$23,MIN($M$3,14+semi))),"") -> 0 | E15: =IF(AND(ISNUMBER(D15),ISNUMBER($M$4)),(D15-$M$4)/($M$5-$M$4),"") -> 0 | F15: =IF(AND(ISNUMBER(E15),ISNUMBER(E16),ISNUMBER($M$6)),IF(AND(15<$M$6,E15<0.5,E16>=0.5),15,""),"") -> 0 | G15: =IF(AND(ISNUMBER(E15),ISNUMBER(E16),ISNUMBER($M$6)),IF(AND(15>=$M$6,E15>=0.5,E16<0.5),15,""),"") -> 0 | H15: =IF(OR(ISNUMBER(F15),ISNUMBER(G15)),C15+(0.5-E15)*(C16-C15)/(E16-E15),"") -> 0 | I15: =IF(AND(ISNUMBER(E15),ISNUMBER($M$15)),C15-$M$15,NA()) -> 0 | J15: =IF(ISNUMBER(E15),E15,NA()) -> 0 | K15: =IF(AND(ISNUMBER(C15),ISNUMBER(C16)),SIGN(C16-C15),"") -> 0 | L15: Centro de la traza (fs) | M15: =IF(ISNUMBER($M$12),($M$10+$M$11)/2,$M$7) -> 0
A16: 140 | C16: =IF(ISNUMBER(A16),A16*conv,"") -> 0 | D16: =IF(ISNUMBER(B16),AVERAGE(INDEX($B$2:$B$23,MAX(1,15-semi)):INDEX($B$2:$B$23,MIN($M$3,15+semi))),"") -> 0 | E16: =IF(AND(ISNUMBER(D16),ISNUMBER($M$4)),(D16-$M$4)/($M$5-$M$4),"") -> 0 | F16: =IF(AND(ISNUMBER(E16),ISNUMBER(E17),ISNUMBER($M$6)),IF(AND(16<$M$6,E16<0.5,E17>=0.5),16,""),"") -> 0 | G16: =IF(AND(ISNUMBER(E16),ISNUMBER(E17),ISNUMBER($M$6)),IF(AND(16>=$M$6,E16>=0.5,E17<0.5),16,""),"") -> 0 | H16: =IF(OR(ISNUMBER(F16),ISNUMBER(G16)),C16+(0.5-E16)*(C17-C16)/(E17-E16),"") -> 0 | I16: =IF(AND(ISNUMBER(E16),ISNUMBER($M$15)),C16-$M$15,NA()) -> 0 | J16: =IF(ISNUMBER(E16),E16,NA()) -> 0 | K16: =IF(AND(ISNUMBER(C16),ISNUMBER(C17)),SIGN(C17-C16),"") -> 0 | L16: Lecturas dentro del ancho a media altura | M16: =COUNTIF($E$2:$E$23,">=0.5") -> 0
A17: 150 | C17: =IF(ISNUMBER(A17),A17*conv,"") -> 0 | D17: =IF(ISNUMBER(B17),AVERAGE(INDEX($B$2:$B$23,MAX(1,16-semi)):INDEX($B$2:$B$23,MIN($M$3,16+semi))),"") -> 0 | E17: =IF(AND(ISNUMBER(D17),ISNUMBER($M$4)),(D17-$M$4)/($M$5-$M$4),"") -> 0 | F17: =IF(AND(ISNUMBER(E17),ISNUMBER(E18),ISNUMBER($M$6)),IF(AND(17<$M$6,E17<0.5,E18>=0.5),17,""),"") -> 0 | G17: =IF(AND(ISNUMBER(E17),ISNUMBER(E18),ISNUMBER($M$6)),IF(AND(17>=$M$6,E17>=0.5,E18<0.5),17,""),"") -> 0 | H17: =IF(OR(ISNUMBER(F17),ISNUMBER(G17)),C17+(0.5-E17)*(C18-C17)/(E18-E17),"") -> 0 | I17: =IF(AND(ISNUMBER(E17),ISNUMBER($M$15)),C17-$M$15,NA()) -> 0 | J17: =IF(ISNUMBER(E17),E17,NA()) -> 0 | K17: =IF(AND(ISNUMBER(C17),ISNUMBER(C18)),SIGN(C18-C17),"") -> 0 | L17: Recorrido a la izquierda del centro (fs) | M17: =IFERROR($M$15-MIN($C$2:$C$23),"") -> 0
A18: 160 | C18: =IF(ISNUMBER(A18),A18*conv,"") -> 0 | D18: =IF(ISNUMBER(B18),AVERAGE(INDEX($B$2:$B$23,MAX(1,17-semi)):INDEX($B$2:$B$23,MIN($M$3,17+semi))),"") -> 0 | E18: =IF(AND(ISNUMBER(D18),ISNUMBER($M$4)),(D18-$M$4)/($M$5-$M$4),"") -> 0 | F18: =IF(AND(ISNUMBER(E18),ISNUMBER(E19),ISNUMBER($M$6)),IF(AND(18<$M$6,E18<0.5,E19>=0.5),18,""),"") -> 0 | G18: =IF(AND(ISNUMBER(E18),ISNUMBER(E19),ISNUMBER($M$6)),IF(AND(18>=$M$6,E18>=0.5,E19<0.5),18,""),"") -> 0 | H18: =IF(OR(ISNUMBER(F18),ISNUMBER(G18)),C18+(0.5-E18)*(C19-C18)/(E19-E18),"") -> 0 | I18: =IF(AND(ISNUMBER(E18),ISNUMBER($M$15)),C18-$M$15,NA()) -> 0 | J18: =IF(ISNUMBER(E18),E18,NA()) -> 0 | K18: =IF(AND(ISNUMBER(C18),ISNUMBER(C19)),SIGN(C19-C18),"") -> 0 | L18: Recorrido a la derecha del centro (fs) | M18: =IFERROR(MAX($C$2:$C$23)-$M$15,"") -> 0
A19: 170 | C19: =IF(ISNUMBER(A19),A19*conv,"") -> 0 | D19: =IF(ISNUMBER(B19),AVERAGE(INDEX($B$2:$B$23,MAX(1,18-semi)):INDEX($B$2:$B$23,MIN($M$3,18+semi))),"") -> 0 | E19: =IF(AND(ISNUMBER(D19),ISNUMBER($M$4)),(D19-$M$4)/($M$5-$M$4),"") -> 0 | F19: =IF(AND(ISNUMBER(E19),ISNUMBER(E20),ISNUMBER($M$6)),IF(AND(19<$M$6,E19<0.5,E20>=0.5),19,""),"") -> 0 | G19: =IF(AND(ISNUMBER(E19),ISNUMBER(E20),ISNUMBER($M$6)),IF(AND(19>=$M$6,E19>=0.5,E20<0.5),19,""),"") -> 0 | H19: =IF(OR(ISNUMBER(F19),ISNUMBER(G19)),C19+(0.5-E19)*(C20-C19)/(E20-E19),"") -> 0 | I19: =IF(AND(ISNUMBER(E19),ISNUMBER($M$15)),C19-$M$15,NA()) -> 0 | J19: =IF(ISNUMBER(E19),E19,NA()) -> 0 | K19: =IF(AND(ISNUMBER(C19),ISNUMBER(C20)),SIGN(C20-C19),"") -> 0 | L19: Posición del pico (µm) | M19: =IF($M$3<$M$2,"",IFERROR(INDEX($A$1:$A$23,$M$6),"")) -> 0
A20: 180 | C20: =IF(ISNUMBER(A20),A20*conv,"") -> 0 | D20: =IF(ISNUMBER(B20),AVERAGE(INDEX($B$2:$B$23,MAX(1,19-semi)):INDEX($B$2:$B$23,MIN($M$3,19+semi))),"") -> 0 | E20: =IF(AND(ISNUMBER(D20),ISNUMBER($M$4)),(D20-$M$4)/($M$5-$M$4),"") -> 0 | F20: =IF(AND(ISNUMBER(E20),ISNUMBER(E21),ISNUMBER($M$6)),IF(AND(20<$M$6,E20<0.5,E21>=0.5),20,""),"") -> 0 | G20: =IF(AND(ISNUMBER(E20),ISNUMBER(E21),ISNUMBER($M$6)),IF(AND(20>=$M$6,E20>=0.5,E21<0.5),20,""),"") -> 0 | H20: =IF(OR(ISNUMBER(F20),ISNUMBER(G20)),C20+(0.5-E20)*(C21-C20)/(E21-E20),"") -> 0 | I20: =IF(AND(ISNUMBER(E20),ISNUMBER($M$15)),C20-$M$15,NA()) -> 0 | J20: =IF(ISNUMBER(E20),E20,NA()) -> 0 | K20: =IF(AND(ISNUMBER(C20),ISNUMBER(C21)),SIGN(C21-C20),"") -> 0 | L20: Estado de la traza | M20: =IF($M$3=0,"Sin datos",IF($M$3<$M$2,"Incompleta: faltan lecturas de potencia",IF(OR($M$8=0,$M$9=0),"Revisar: no se hallaron los dos cruces de media altura",IF($M$16<pts_min,"Aviso: pocas lecturas dentro del ancho a media altura",IF(MIN($M$17,$M$18)<rec_min*$M$12,"Aviso: el pico está corrido; el barrido no llega a una de las alas","OK"))))) -> 0
A21: 190 | C21: =IF(ISNUMBER(A21),A21*conv,"") -> 0 | D21: =IF(ISNUMBER(B21),AVERAGE(INDEX($B$2:$B$23,MAX(1,20-semi)):INDEX($B$2:$B$23,MIN($M$3,20+semi))),"") -> 0 | E21: =IF(AND(ISNUMBER(D21),ISNUMBER($M$4)),(D21-$M$4)/($M$5-$M$4),"") -> 0 | F21: =IF(AND(ISNUMBER(E21),ISNUMBER(E22),ISNUMBER($M$6)),IF(AND(21<$M$6,E21<0.5,E22>=0.5),21,""),"") -> 0 | G21: =IF(AND(ISNUMBER(E21),ISNUMBER(E22),ISNUMBER($M$6)),IF(AND(21>=$M$6,E21>=0.5,E22<0.5),21,""),"") -> 0 | H21: =IF(OR(ISNUMBER(F21),ISNUMBER(G21)),C21+(0.5-E21)*(C22-C21)/(E22-E21),"") -> 0 | I21: =IF(AND(ISNUMBER(E21),ISNUMBER($M$15)),C21-$M$15,NA()) -> 0 | J21: =IF(ISNUMBER(E21),E21,NA()) -> 0 | K21: =IF(AND(ISNUMBER(C21),ISNUMBER(C22)),SIGN(C22-C21),"") -> 0
A22: 200 | C22: =IF(ISNUMBER(A22),A22*conv,"") -> 0 | D22: =IF(ISNUMBER(B22),AVERAGE(INDEX($B$2:$B$23,MAX(1,21-semi)):INDEX($B$2:$B$23,MIN($M$3,21+semi))),"") -> 0 | E22: =IF(AND(ISNUMBER(D22),ISNUMBER($M$4)),(D22-$M$4)/($M$5-$M$4),"") -> 0 | F22: =IF(AND(ISNUMBER(E22),ISNUMBER(E23),ISNUMBER($M$6)),IF(AND(22<$M$6,E22<0.5,E23>=0.5),22,""),"") -> 0 | G22: =IF(AND(ISNUMBER(E22),ISNUMBER(E23),ISNUMBER($M$6)),IF(AND(22>=$M$6,E22>=0.5,E23<0.5),22,""),"") -> 0 | H22: =IF(OR(ISNUMBER(F22),ISNUMBER(G22)),C22+(0.5-E22)*(C23-C22)/(E23-E22),"") -> 0 | I22: =IF(AND(ISNUMBER(E22),ISNUMBER($M$15)),C22-$M$15,NA()) -> 0 | J22: =IF(ISNUMBER(E22),E22,NA()) -> 0 | K22: =IF(AND(ISNUMBER(C22),ISNUMBER(C23)),SIGN(C23-C22),"") -> 0 | L22: Línea de media altura (gráfica)
A23: 210 | C23: =IF(ISNUMBER(A23),A23*conv,"") -> 0 | D23: =IF(ISNUMBER(B23),AVERAGE(INDEX($B$2:$B$23,MAX(1,22-semi)):INDEX($B$2:$B$23,MIN($M$3,22+semi))),"") -> 0 | E23: =IF(AND(ISNUMBER(D23),ISNUMBER($M$4)),(D23-$M$4)/($M$5-$M$4),"") -> 0 | F23: =IF(AND(ISNUMBER(E23),ISNUMBER(E24),ISNUMBER($M$6)),IF(AND(23<$M$6,E23<0.5,E24>=0.5),23,""),"") -> 0 | G23: =IF(AND(ISNUMBER(E23),ISNUMBER(E24),ISNUMBER($M$6)),IF(AND(23>=$M$6,E23>=0.5,E24<0.5),23,""),"") -> 0 | H23: =IF(OR(ISNUMBER(F23),ISNUMBER(G23)),C23+(0.5-E23)*(C24-C23)/(E24-E23),"") -> 0 | I23: =IF(AND(ISNUMBER(E23),ISNUMBER($M$15)),C23-$M$15,NA()) -> 0 | J23: =IF(ISNUMBER(E23),E23,NA()) -> 0 | K23: =IF(AND(ISNUMBER(C23),ISNUMBER(C24)),SIGN(C24-C23),"") -> 0 | L23: =IF(ISNUMBER($M$12),$M$10-$M$15,NA()) -> 0 | M23: =IF(ISNUMBER($M$12),0.5,NA()) -> 0
L24: =IF(ISNUMBER($M$12),$M$11-$M$15,NA()) -> 0 | M24: =IF(ISNUMBER($M$12),0.5,NA()) -> 0
L26: Solo se llena la columna B (potencia en W), en el orden de las posiciones.

Sheet R03
A1: Posición del micrómetro (µm) · fija | B1: Potencia óptica (W) | C1: Retardo τ (fs) | D1: Señal suavizada | E1: Señal normalizada | F1: Cruce izq. (fila) | G1: Cruce der. (fila) | H1: τ de cruce (fs) | I1: Retardo centrado (fs) · gráfica | J1: Normalizada · gráfica | K1: Sentido | L1: Traza R03 | M1: 6 A
A2: 0 | C2: =IF(ISNUMBER(A2),A2*conv,"") -> 0 | D2: =IF(ISNUMBER(B2),AVERAGE(INDEX($B$2:$B$23,MAX(1,1-semi)):INDEX($B$2:$B$23,MIN($M$3,1+semi))),"") -> 0 | E2: =IF(AND(ISNUMBER(D2),ISNUMBER($M$4)),(D2-$M$4)/($M$5-$M$4),"") -> 0 | F2: =IF(AND(ISNUMBER(E2),ISNUMBER(E3),ISNUMBER($M$6)),IF(AND(2<$M$6,E2<0.5,E3>=0.5),2,""),"") -> 0 | G2: =IF(AND(ISNUMBER(E2),ISNUMBER(E3),ISNUMBER($M$6)),IF(AND(2>=$M$6,E2>=0.5,E3<0.5),2,""),"") -> 0 | H2: =IF(OR(ISNUMBER(F2),ISNUMBER(G2)),C2+(0.5-E2)*(C3-C2)/(E3-E2),"") -> 0 | I2: =IF(AND(ISNUMBER(E2),ISNUMBER($M$15)),C2-$M$15,NA()) -> 0 | J2: =IF(ISNUMBER(E2),E2,NA()) -> 0 | K2: =IF(AND(ISNUMBER(C2),ISNUMBER(C3)),SIGN(C3-C2),"") -> 0 | L2: Posiciones de la traza | M2: =COUNT($A$2:$A$23) -> 0
A3: 10 | C3: =IF(ISNUMBER(A3),A3*conv,"") -> 0 | D3: =IF(ISNUMBER(B3),AVERAGE(INDEX($B$2:$B$23,MAX(1,2-semi)):INDEX($B$2:$B$23,MIN($M$3,2+semi))),"") -> 0 | E3: =IF(AND(ISNUMBER(D3),ISNUMBER($M$4)),(D3-$M$4)/($M$5-$M$4),"") -> 0 | F3: =IF(AND(ISNUMBER(E3),ISNUMBER(E4),ISNUMBER($M$6)),IF(AND(3<$M$6,E3<0.5,E4>=0.5),3,""),"") -> 0 | G3: =IF(AND(ISNUMBER(E3),ISNUMBER(E4),ISNUMBER($M$6)),IF(AND(3>=$M$6,E3>=0.5,E4<0.5),3,""),"") -> 0 | H3: =IF(OR(ISNUMBER(F3),ISNUMBER(G3)),C3+(0.5-E3)*(C4-C3)/(E4-E3),"") -> 0 | I3: =IF(AND(ISNUMBER(E3),ISNUMBER($M$15)),C3-$M$15,NA()) -> 0 | J3: =IF(ISNUMBER(E3),E3,NA()) -> 0 | K3: =IF(AND(ISNUMBER(C3),ISNUMBER(C4)),SIGN(C4-C3),"") -> 0 | L3: Lecturas de potencia escritas | M3: =COUNT($B$2:$B$23) -> 0
A4: 20 | C4: =IF(ISNUMBER(A4),A4*conv,"") -> 0 | D4: =IF(ISNUMBER(B4),AVERAGE(INDEX($B$2:$B$23,MAX(1,3-semi)):INDEX($B$2:$B$23,MIN($M$3,3+semi))),"") -> 0 | E4: =IF(AND(ISNUMBER(D4),ISNUMBER($M$4)),(D4-$M$4)/($M$5-$M$4),"") -> 0 | F4: =IF(AND(ISNUMBER(E4),ISNUMBER(E5),ISNUMBER($M$6)),IF(AND(4<$M$6,E4<0.5,E5>=0.5),4,""),"") -> 0 | G4: =IF(AND(ISNUMBER(E4),ISNUMBER(E5),ISNUMBER($M$6)),IF(AND(4>=$M$6,E4>=0.5,E5<0.5),4,""),"") -> 0 | H4: =IF(OR(ISNUMBER(F4),ISNUMBER(G4)),C4+(0.5-E4)*(C5-C4)/(E5-E4),"") -> 0 | I4: =IF(AND(ISNUMBER(E4),ISNUMBER($M$15)),C4-$M$15,NA()) -> 0 | J4: =IF(ISNUMBER(E4),E4,NA()) -> 0 | K4: =IF(AND(ISNUMBER(C4),ISNUMBER(C5)),SIGN(C5-C4),"") -> 0 | L4: Fondo (promedio de las alas, W) | M4: =IF($M$3<$M$2,"",(AVERAGE(INDEX($B$2:$B$23,1):INDEX($B$2:$B$23,n_fondo))+AVERAGE(INDEX($B$2:$B$23,$M$3-n_fondo+1):INDEX($B$2:$B$23,$M$3)))/2) -> 0
A5: 30 | C5: =IF(ISNUMBER(A5),A5*conv,"") -> 0 | D5: =IF(ISNUMBER(B5),AVERAGE(INDEX($B$2:$B$23,MAX(1,4-semi)):INDEX($B$2:$B$23,MIN($M$3,4+semi))),"") -> 0 | E5: =IF(AND(ISNUMBER(D5),ISNUMBER($M$4)),(D5-$M$4)/($M$5-$M$4),"") -> 0 | F5: =IF(AND(ISNUMBER(E5),ISNUMBER(E6),ISNUMBER($M$6)),IF(AND(5<$M$6,E5<0.5,E6>=0.5),5,""),"") -> 0 | G5: =IF(AND(ISNUMBER(E5),ISNUMBER(E6),ISNUMBER($M$6)),IF(AND(5>=$M$6,E5>=0.5,E6<0.5),5,""),"") -> 0 | H5: =IF(OR(ISNUMBER(F5),ISNUMBER(G5)),C5+(0.5-E5)*(C6-C5)/(E6-E5),"") -> 0 | I5: =IF(AND(ISNUMBER(E5),ISNUMBER($M$15)),C5-$M$15,NA()) -> 0 | J5: =IF(ISNUMBER(E5),E5,NA()) -> 0 | K5: =IF(AND(ISNUMBER(C5),ISNUMBER(C6)),SIGN(C6-C5),"") -> 0 | L5: Máximo de la señal (W) | M5: =IF($M$3<$M$2,"",MAX($D$2:$D$23)) -> 0
A6: 40 | C6: =IF(ISNUMBER(A6),A6*conv,"") -> 0 | D6: =IF(ISNUMBER(B6),AVERAGE(INDEX($B$2:$B$23,MAX(1,5-semi)):INDEX($B$2:$B$23,MIN($M$3,5+semi))),"") -> 0 | E6: =IF(AND(ISNUMBER(D6),ISNUMBER($M$4)),(D6-$M$4)/($M$5-$M$4),"") -> 0 | F6: =IF(AND(ISNUMBER(E6),ISNUMBER(E7),ISNUMBER($M$6)),IF(AND(6<$M$6,E6<0.5,E7>=0.5),6,""),"") -> 0 | G6: =IF(AND(ISNUMBER(E6),ISNUMBER(E7),ISNUMBER($M$6)),IF(AND(6>=$M$6,E6>=0.5,E7<0.5),6,""),"") -> 0 | H6: =IF(OR(ISNUMBER(F6),ISNUMBER(G6)),C6+(0.5-E6)*(C7-C6)/(E7-E6),"") -> 0 | I6: =IF(AND(ISNUMBER(E6),ISNUMBER($M$15)),C6-$M$15,NA()) -> 0 | J6: =IF(ISNUMBER(E6),E6,NA()) -> 0 | K6: =IF(AND(ISNUMBER(C6),ISNUMBER(C7)),SIGN(C7-C6),"") -> 0 | L6: Fila del máximo | M6: =IFERROR(MATCH($M$5,$D$2:$D$23,0)+1,"") -> 0
A7: 50 | C7: =IF(ISNUMBER(A7),A7*conv,"") -> 0 | D7: =IF(ISNUMBER(B7),AVERAGE(INDEX($B$2:$B$23,MAX(1,6-semi)):INDEX($B$2:$B$23,MIN($M$3,6+semi))),"") -> 0 | E7: =IF(AND(ISNUMBER(D7),ISNUMBER($M$4)),(D7-$M$4)/($M$5-$M$4),"") -> 0 | F7: =IF(AND(ISNUMBER(E7),ISNUMBER(E8),ISNUMBER($M$6)),IF(AND(7<$M$6,E7<0.5,E8>=0.5),7,""),"") -> 0 | G7: =IF(AND(ISNUMBER(E7),ISNUMBER(E8),ISNUMBER($M$6)),IF(AND(7>=$M$6,E7>=0.5,E8<0.5),7,""),"") -> 0 | H7: =IF(OR(ISNUMBER(F7),ISNUMBER(G7)),C7+(0.5-E7)*(C8-C7)/(E8-E7),"") -> 0 | I7: =IF(AND(ISNUMBER(E7),ISNUMBER($M$15)),C7-$M$15,NA()) -> 0 | J7: =IF(ISNUMBER(E7),E7,NA()) -> 0 | K7: =IF(AND(ISNUMBER(C7),ISNUMBER(C8)),SIGN(C8-C7),"") -> 0 | L7: Retardo del máximo (fs) | M7: =IFERROR(INDEX($C$1:$C$23,$M$6),"") -> 0
A8: 60 | C8: =IF(ISNUMBER(A8),A8*conv,"") -> 0 | D8: =IF(ISNUMBER(B8),AVERAGE(INDEX($B$2:$B$23,MAX(1,7-semi)):INDEX($B$2:$B$23,MIN($M$3,7+semi))),"") -> 0 | E8: =IF(AND(ISNUMBER(D8),ISNUMBER($M$4)),(D8-$M$4)/($M$5-$M$4),"") -> 0 | F8: =IF(AND(ISNUMBER(E8),ISNUMBER(E9),ISNUMBER($M$6)),IF(AND(8<$M$6,E8<0.5,E9>=0.5),8,""),"") -> 0 | G8: =IF(AND(ISNUMBER(E8),ISNUMBER(E9),ISNUMBER($M$6)),IF(AND(8>=$M$6,E8>=0.5,E9<0.5),8,""),"") -> 0 | H8: =IF(OR(ISNUMBER(F8),ISNUMBER(G8)),C8+(0.5-E8)*(C9-C8)/(E9-E8),"") -> 0 | I8: =IF(AND(ISNUMBER(E8),ISNUMBER($M$15)),C8-$M$15,NA()) -> 0 | J8: =IF(ISNUMBER(E8),E8,NA()) -> 0 | K8: =IF(AND(ISNUMBER(C8),ISNUMBER(C9)),SIGN(C9-C8),"") -> 0 | L8: Fila del cruce izquierdo a media altura | M8: =MAX($F$2:$F$23) -> 0
A9: 70 | C9: =IF(ISNUMBER(A9),A9*conv,"") -> 0 | D9: =IF(ISNUMBER(B9),AVERAGE(INDEX($B$2:$B$23,MAX(1,8-semi)):INDEX($B$2:$B$23,MIN($M$3,8+semi))),"") -> 0 | E9: =IF(AND(ISNUMBER(D9),ISNUMBER($M$4)),(D9-$M$4)/($M$5-$M$4),"") -> 0 | F9: =IF(AND(ISNUMBER(E9),ISNUMBER(E10),ISNUMBER($M$6)),IF(AND(9<$M$6,E9<0.5,E10>=0.5),9,""),"") -> 0 | G9: =IF(AND(ISNUMBER(E9),ISNUMBER(E10),ISNUMBER($M$6)),IF(AND(9>=$M$6,E9>=0.5,E10<0.5),9,""),"") -> 0 | H9: =IF(OR(ISNUMBER(F9),ISNUMBER(G9)),C9+(0.5-E9)*(C10-C9)/(E10-E9),"") -> 0 | I9: =IF(AND(ISNUMBER(E9),ISNUMBER($M$15)),C9-$M$15,NA()) -> 0 | J9: =IF(ISNUMBER(E9),E9,NA()) -> 0 | K9: =IF(AND(ISNUMBER(C9),ISNUMBER(C10)),SIGN(C10-C9),"") -> 0 | L9: Fila del cruce derecho a media altura | M9: =MIN($G$2:$G$23) -> 0
A10: 80 | C10: =IF(ISNUMBER(A10),A10*conv,"") -> 0 | D10: =IF(ISNUMBER(B10),AVERAGE(INDEX($B$2:$B$23,MAX(1,9-semi)):INDEX($B$2:$B$23,MIN($M$3,9+semi))),"") -> 0 | E10: =IF(AND(ISNUMBER(D10),ISNUMBER($M$4)),(D10-$M$4)/($M$5-$M$4),"") -> 0 | F10: =IF(AND(ISNUMBER(E10),ISNUMBER(E11),ISNUMBER($M$6)),IF(AND(10<$M$6,E10<0.5,E11>=0.5),10,""),"") -> 0 | G10: =IF(AND(ISNUMBER(E10),ISNUMBER(E11),ISNUMBER($M$6)),IF(AND(10>=$M$6,E10>=0.5,E11<0.5),10,""),"") -> 0 | H10: =IF(OR(ISNUMBER(F10),ISNUMBER(G10)),C10+(0.5-E10)*(C11-C10)/(E11-E10),"") -> 0 | I10: =IF(AND(ISNUMBER(E10),ISNUMBER($M$15)),C10-$M$15,NA()) -> 0 | J10: =IF(ISNUMBER(E10),E10,NA()) -> 0 | K10: =IF(AND(ISNUMBER(C10),ISNUMBER(C11)),SIGN(C11-C10),"") -> 0 | L10: τ del cruce izquierdo (fs) | M10: =IF($M$8>0,INDEX($H$1:$H$23,$M$8),"") -> 0
A11: 90 | C11: =IF(ISNUMBER(A11),A11*conv,"") -> 0 | D11: =IF(ISNUMBER(B11),AVERAGE(INDEX($B$2:$B$23,MAX(1,10-semi)):INDEX($B$2:$B$23,MIN($M$3,10+semi))),"") -> 0 | E11: =IF(AND(ISNUMBER(D11),ISNUMBER($M$4)),(D11-$M$4)/($M$5-$M$4),"") -> 0 | F11: =IF(AND(ISNUMBER(E11),ISNUMBER(E12),ISNUMBER($M$6)),IF(AND(11<$M$6,E11<0.5,E12>=0.5),11,""),"") -> 0 | G11: =IF(AND(ISNUMBER(E11),ISNUMBER(E12),ISNUMBER($M$6)),IF(AND(11>=$M$6,E11>=0.5,E12<0.5),11,""),"") -> 0 | H11: =IF(OR(ISNUMBER(F11),ISNUMBER(G11)),C11+(0.5-E11)*(C12-C11)/(E12-E11),"") -> 0 | I11: =IF(AND(ISNUMBER(E11),ISNUMBER($M$15)),C11-$M$15,NA()) -> 0 | J11: =IF(ISNUMBER(E11),E11,NA()) -> 0 | K11: =IF(AND(ISNUMBER(C11),ISNUMBER(C12)),SIGN(C12-C11),"") -> 0 | L11: τ del cruce derecho (fs) | M11: =IF($M$9>0,INDEX($H$1:$H$23,$M$9),"") -> 0
A12: 100 | C12: =IF(ISNUMBER(A12),A12*conv,"") -> 0 | D12: =IF(ISNUMBER(B12),AVERAGE(INDEX($B$2:$B$23,MAX(1,11-semi)):INDEX($B$2:$B$23,MIN($M$3,11+semi))),"") -> 0 | E12: =IF(AND(ISNUMBER(D12),ISNUMBER($M$4)),(D12-$M$4)/($M$5-$M$4),"") -> 0 | F12: =IF(AND(ISNUMBER(E12),ISNUMBER(E13),ISNUMBER($M$6)),IF(AND(12<$M$6,E12<0.5,E13>=0.5),12,""),"") -> 0 | G12: =IF(AND(ISNUMBER(E12),ISNUMBER(E13),ISNUMBER($M$6)),IF(AND(12>=$M$6,E12>=0.5,E13<0.5),12,""),"") -> 0 | H12: =IF(OR(ISNUMBER(F12),ISNUMBER(G12)),C12+(0.5-E12)*(C13-C12)/(E13-E12),"") -> 0 | I12: =IF(AND(ISNUMBER(E12),ISNUMBER($M$15)),C12-$M$15,NA()) -> 0 | J12: =IF(ISNUMBER(E12),E12,NA()) -> 0 | K12: =IF(AND(ISNUMBER(C12),ISNUMBER(C13)),SIGN(C13-C12),"") -> 0 | L12: Ancho de la traza a media altura Δτ_AC (fs) | M12: =IF(AND($M$8>0,$M$9>0),ABS($M$11-$M$10),"") -> 0
A13: 110 | C13: =IF(ISNUMBER(A13),A13*conv,"") -> 0 | D13: =IF(ISNUMBER(B13),AVERAGE(INDEX($B$2:$B$23,MAX(1,12-semi)):INDEX($B$2:$B$23,MIN($M$3,12+semi))),"") -> 0 | E13: =IF(AND(ISNUMBER(D13),ISNUMBER($M$4)),(D13-$M$4)/($M$5-$M$4),"") -> 0 | F13: =IF(AND(ISNUMBER(E13),ISNUMBER(E14),ISNUMBER($M$6)),IF(AND(13<$M$6,E13<0.5,E14>=0.5),13,""),"") -> 0 | G13: =IF(AND(ISNUMBER(E13),ISNUMBER(E14),ISNUMBER($M$6)),IF(AND(13>=$M$6,E13>=0.5,E14<0.5),13,""),"") -> 0 | H13: =IF(OR(ISNUMBER(F13),ISNUMBER(G13)),C13+(0.5-E13)*(C14-C13)/(E14-E13),"") -> 0 | I13: =IF(AND(ISNUMBER(E13),ISNUMBER($M$15)),C13-$M$15,NA()) -> 0 | J13: =IF(ISNUMBER(E13),E13,NA()) -> 0 | K13: =IF(AND(ISNUMBER(C13),ISNUMBER(C14)),SIGN(C14-C13),"") -> 0 | L13: Ancho de pulso τp = factor × Δτ_AC (fs) | M13: =IF(ISNUMBER($M$12),factor_forma*$M$12,"") -> 0
A14: 120 | C14: =IF(ISNUMBER(A14),A14*conv,"") -> 0 | D14: =IF(ISNUMBER(B14),AVERAGE(INDEX($B$2:$B$23,MAX(1,13-semi)):INDEX($B$2:$B$23,MIN($M$3,13+semi))),"") -> 0 | E14: =IF(AND(ISNUMBER(D14),ISNUMBER($M$4)),(D14-$M$4)/($M$5-$M$4),"") -> 0 | F14: =IF(AND(ISNUMBER(E14),ISNUMBER(E15),ISNUMBER($M$6)),IF(AND(14<$M$6,E14<0.5,E15>=0.5),14,""),"") -> 0 | G14: =IF(AND(ISNUMBER(E14),ISNUMBER(E15),ISNUMBER($M$6)),IF(AND(14>=$M$6,E14>=0.5,E15<0.5),14,""),"") -> 0 | H14: =IF(OR(ISNUMBER(F14),ISNUMBER(G14)),C14+(0.5-E14)*(C15-C14)/(E15-E14),"") -> 0 | I14: =IF(AND(ISNUMBER(E14),ISNUMBER($M$15)),C14-$M$15,NA()) -> 0 | J14: =IF(ISNUMBER(E14),E14,NA()) -> 0 | K14: =IF(AND(ISNUMBER(C14),ISNUMBER(C15)),SIGN(C15-C14),"") -> 0 | L14: Referencia: τp si fuera gaussiano (fs) | M14: =IF(ISNUMBER($M$12),0.7071*$M$12,"") -> 0
A15: 130 | C15: =IF(ISNUMBER(A15),A15*conv,"") -> 0 | D15: =IF(ISNUMBER(B15),AVERAGE(INDEX($B$2:$B$23,MAX(1,14-semi)):INDEX($B$2:$B$23,MIN($M$3,14+semi))),"") -> 0 | E15: =IF(AND(ISNUMBER(D15),ISNUMBER($M$4)),(D15-$M$4)/($M$5-$M$4),"") -> 0 | F15: =IF(AND(ISNUMBER(E15),ISNUMBER(E16),ISNUMBER($M$6)),IF(AND(15<$M$6,E15<0.5,E16>=0.5),15,""),"") -> 0 | G15: =IF(AND(ISNUMBER(E15),ISNUMBER(E16),ISNUMBER($M$6)),IF(AND(15>=$M$6,E15>=0.5,E16<0.5),15,""),"") -> 0 | H15: =IF(OR(ISNUMBER(F15),ISNUMBER(G15)),C15+(0.5-E15)*(C16-C15)/(E16-E15),"") -> 0 | I15: =IF(AND(ISNUMBER(E15),ISNUMBER($M$15)),C15-$M$15,NA()) -> 0 | J15: =IF(ISNUMBER(E15),E15,NA()) -> 0 | K15: =IF(AND(ISNUMBER(C15),ISNUMBER(C16)),SIGN(C16-C15),"") -> 0 | L15: Centro de la traza (fs) | M15: =IF(ISNUMBER($M$12),($M$10+$M$11)/2,$M$7) -> 0
A16: 140 | C16: =IF(ISNUMBER(A16),A16*conv,"") -> 0 | D16: =IF(ISNUMBER(B16),AVERAGE(INDEX($B$2:$B$23,MAX(1,15-semi)):INDEX($B$2:$B$23,MIN($M$3,15+semi))),"") -> 0 | E16: =IF(AND(ISNUMBER(D16),ISNUMBER($M$4)),(D16-$M$4)/($M$5-$M$4),"") -> 0 | F16: =IF(AND(ISNUMBER(E16),ISNUMBER(E17),ISNUMBER($M$6)),IF(AND(16<$M$6,E16<0.5,E17>=0.5),16,""),"") -> 0 | G16: =IF(AND(ISNUMBER(E16),ISNUMBER(E17),ISNUMBER($M$6)),IF(AND(16>=$M$6,E16>=0.5,E17<0.5),16,""),"") -> 0 | H16: =IF(OR(ISNUMBER(F16),ISNUMBER(G16)),C16+(0.5-E16)*(C17-C16)/(E17-E16),"") -> 0 | I16: =IF(AND(ISNUMBER(E16),ISNUMBER($M$15)),C16-$M$15,NA()) -> 0 | J16: =IF(ISNUMBER(E16),E16,NA()) -> 0 | K16: =IF(AND(ISNUMBER(C16),ISNUMBER(C17)),SIGN(C17-C16),"") -> 0 | L16: Lecturas dentro del ancho a media altura | M16: =COUNTIF($E$2:$E$23,">=0.5") -> 0
