Workbook
Name alfa: Configuración!$B$17
Name c_luz: Configuración!$B$10
Name conv: Configuración!$B$11
Name corriente: Configuración!$B$5
Name factor_forma: Configuración!$B$12
Name n_fondo: Configuración!$B$13
Name paso: Configuración!$B$8
Name pasos: Configuración!$B$9
Name pfab: Configuración!$B$7
Name pts_min: Configuración!$B$15
Name rec_min: Configuración!$B$16
Name semi: Configuración!$B$14
Name tau0: Configuración!$B$6

Sheet Instrucciones
A1: Medición definitiva del autocorrelador · corriente 5 A (I1)
A2: Fecha prevista: martes 27 oct 2026. Nueve réplicas de la misma corriente, una tras otra.
A4: 1. Encender el láser y dejarlo calentar como en el piloto. Fijar la corriente de bombeo en 5 A y anotar en Registro la fecha, la hora de encendido y la potencia media del láser.
A5: 2. Las posiciones del micrómetro están fijas en todas las hojas R01–R09 (columna A, gris): 22 lecturas, de 0 a 210 µm cada 10 µm, contadas desde el punto de partida del barrido. Escoger el punto de partida de modo que el pico caiga en la mitad del recorrido (≈ 100–110 µm). A 5 A la traza es ancha: si el pico queda en 120 µm o más, el barrido no alcanza el ala derecha (el Estado lo avisa).
A6: 3. Girar el micrómetro siempre en el mismo sentido. En cada posición escribir la potencia óptica en W (columna B, amarilla), tal como la da el medidor: por ejemplo 2.35E-05.
A7: 4. En Registro, escribir la hora de inicio y la hora de fin de cada corrida (hh:mm). La duración y el tiempo entre inicios se calculan solos.
A8: 5. Revisar el «Estado de la traza» (columna L del Registro, o la celda M20 de la hoja). Si dice OK o Aviso, seguir. Si dice Revisar, comprobar los datos escritos antes de seguir.
A9: 6. Una traza solo se marca «No» en ¿Válida? por una causa anotada en el momento (el láser perdió los pulsos, la potencia salió de rango, el barrido se interrumpió). Nunca por dar un valor inesperado. Toda traza descartada se repone en la siguiente hoja de reposición (R10, R11, R12).
A10: 7. La hoja Resumen da n, la media, S, el intervalo de confianza del 95 % y la prueba t de una muestra contra τ0 del fabricante. El análisis definitivo (ajuste sech² de toda la traza) se hace después con scripts/trabajo-practico/analiza_piloto.py; aquí se usa el ancho a media altura × 0,65.
A11: Colores: amarillo con letra azul = se llena; gris = fijo; lo demás son fórmulas. Las hojas de traza están protegidas (sin contraseña) para no borrar las posiciones ni las fórmulas.

Sheet Configuración
A1: Configuración
A2: Valores fijos del protocolo. No cambiarlos durante la medición.
A4: Parámetro | B4: Valor | C4: Nota
A5: Corriente de bombeo (A) | B5: 5 | C5: I1 del protocolo; hoja de pruebas de fábrica, tabla 5.
A6: τ0: ancho de pulso del fabricante (fs) | B6: 107 | C6: Tabla 5 de la hoja de pruebas de fábrica.
A7: Potencia media de fábrica (mW) | B7: 218 | C7: Referencia para comparar con la potencia medida.
A8: Paso del micrómetro (µm) | B8: 10 | C8: Fijo, como en el piloto.
A9: Veces que el haz recorre el desplazamiento | B9: 2 | C9: Retrorreflector: τ = 2Δx/c.
A10: Velocidad de la luz c (m/s) | B10: 299792458 | C10: Valor exacto (SI).
A11: Retardo por µm del micrómetro (fs) | B11: =pasos*10^-6/c_luz*10^15 -> 6.6712819 | C11: 6,6713 fs por µm.
A12: Factor de forma sech²: τp = factor × Δτ_AC | B12: 0.65 | C12: El que usa Calmar (teórico 0,648).
A13: Lecturas por ala para el fondo | B13: 2 | C13: Promedio de las 2 primeras y las 2 últimas lecturas.
A14: Semiventana de suavizado | B14: 0 | C14: 0 = sin suavizar (programa de análisis fijo).
A15: Lecturas mínimas dentro del ancho a media altura | B15: 4 | C15: Con paso de 10 µm el piloto tuvo 4–5 lecturas dentro del FWHM.
A16: Recorrido mínimo a cada lado del centro (múltiplos de Δτ_AC) | B16: 2 | C16: Si no se alcanza, el fondo sale alto y el ancho corto.
A17: α de la prueba t (dos colas) | B17: 0.05 | C17: Protocolo.

Sheet Registro
A1: Registro de la medición · 5 A (I1)
A2: Amarillo = llenar. Nueve réplicas seguidas a la misma corriente; R10–R12 solo si hay que reponer una traza descartada.
A4: Fecha | B4: martes 27 oct 2026 | D4: Encendido del láser | F4: Corriente (A) | G4: =corriente -> 5 | H4: Temperatura del laboratorio (°C) | J4: Responsables:
A6: N° | B6: Hoja | C6: Hora inicio | D6: Hora fin | E6: Duración (min) | F6: Δ inicio a la siguiente (min) | G6: Potencia media del láser (mW) | H6: Posición del pico (µm) | I6: ¿Válida? | J6: Observaciones (causa si no es válida) | K6: Δτ_AC (fs) | L6: τp (fs) | M6: Estado de la traza | N6: τp usable (fs)
A7: 1 | B7: R01 | C7: 0.29375 | D7: 0.29861111 | E7: =IF(AND(ISNUMBER(C7),ISNUMBER(D7)),(D7-C7)*1440,"") -> 7 | F7: =IF(AND(ISNUMBER(C7),ISNUMBER(C8)),(C8-C7)*1440,"") -> 10 | H7: =IFERROR('R01'!$M$19+0,"") -> 120 | I7: Sí | K7: =IFERROR('R01'!$M$12+0,"") -> 341.45313 | L7: =IFERROR('R01'!$M$13+0,"") -> 221.94453 | M7: ='R01'!$M$20 -> Aviso: el pico está corrido; el barrido no llega a una de las alas | N7: =IF(AND(ISNUMBER(L7),I7<>"No"),L7,"") -> 221.94453
A8: 2 | B8: R02 | C8: 0.30069444 | D8: 0.30555556 | E8: =IF(AND(ISNUMBER(C8),ISNUMBER(D8)),(D8-C8)*1440,"") -> 7 | F8: =IF(AND(ISNUMBER(C8),ISNUMBER(C9)),(C9-C8)*1440,"") -> 10 | H8: =IFERROR('R02'!$M$19+0,"") -> 120 | I8: Sí | K8: =IFERROR('R02'!$M$12+0,"") -> 335.46659 | L8: =IFERROR('R02'!$M$13+0,"") -> 218.05328 | M8: ='R02'!$M$20 -> Aviso: el pico está corrido; el barrido no llega a una de las alas | N8: =IF(AND(ISNUMBER(L8),I8<>"No"),L8,"") -> 218.05328
A9: 3 | B9: R03 | C9: 0.30763889 | D9: 0.31180556 | E9: =IF(AND(ISNUMBER(C9),ISNUMBER(D9)),(D9-C9)*1440,"") -> 6 | F9: =IF(AND(ISNUMBER(C9),ISNUMBER(C10)),(C10-C9)*1440,"") -> 9 | H9: =IFERROR('R03'!$M$19+0,"") -> 120 | I9: Sí | K9: =IFERROR('R03'!$M$12+0,"") -> 334.28165 | L9: =IFERROR('R03'!$M$13+0,"") -> 217.28307 | M9: ='R03'!$M$20 -> Aviso: el pico está corrido; el barrido no llega a una de las alas | N9: =IF(AND(ISNUMBER(L9),I9<>"No"),L9,"") -> 217.28307
A10: 4 | B10: R04 | C10: 0.31388889 | D10: 0.31805556 | E10: =IF(AND(ISNUMBER(C10),ISNUMBER(D10)),(D10-C10)*1440,"") -> 6 | F10: =IF(AND(ISNUMBER(C10),ISNUMBER(C11)),(C11-C10)*1440,"") -> 9 | H10: =IFERROR('R04'!$M$19+0,"") -> 120 | I10: Sí | K10: =IFERROR('R04'!$M$12+0,"") -> 335.06787 | L10: =IFERROR('R04'!$M$13+0,"") -> 217.79412 | M10: ='R04'!$M$20 -> Aviso: el pico está corrido; el barrido no llega a una de las alas | N10: =IF(AND(ISNUMBER(L10),I10<>"No"),L10,"") -> 217.79412
A11: 5 | B11: R05 | C11: 0.32013889 | D11: 0.32569444 | E11: =IF(AND(ISNUMBER(C11),ISNUMBER(D11)),(D11-C11)*1440,"") -> 8 | F11: =IF(AND(ISNUMBER(C11),ISNUMBER(C12)),(C12-C11)*1440,"") -> 11 | H11: =IFERROR('R05'!$M$19+0,"") -> 120 | I11: Sí | K11: =IFERROR('R05'!$M$12+0,"") -> 338.74885 | L11: =IFERROR('R05'!$M$13+0,"") -> 220.18675 | M11: ='R05'!$M$20 -> Aviso: el pico está corrido; el barrido no llega a una de las alas | N11: =IF(AND(ISNUMBER(L11),I11<>"No"),L11,"") -> 220.18675
A12: 6 | B12: R06 | C12: 0.32777778 | D12: 0.33263889 | E12: =IF(AND(ISNUMBER(C12),ISNUMBER(D12)),(D12-C12)*1440,"") -> 7 | F12: =IF(AND(ISNUMBER(C12),ISNUMBER(C13)),(C13-C12)*1440,"") -> 10 | H12: =IFERROR('R06'!$M$19+0,"") -> 120 | I12: Sí | K12: =IFERROR('R06'!$M$12+0,"") -> 346.62942 | L12: =IFERROR('R06'!$M$13+0,"") -> 225.30912 | M12: ='R06'!$M$20 -> Aviso: el pico está corrido; el barrido no llega a una de las alas | N12: =IF(AND(ISNUMBER(L12),I12<>"No"),L12,"") -> 225.30912
A13: 7 | B13: R07 | C13: 0.33472222 | D13: 0.33888889 | E13: =IF(AND(ISNUMBER(C13),ISNUMBER(D13)),(D13-C13)*1440,"") -> 6 | F13: =IF(AND(ISNUMBER(C13),ISNUMBER(C14)),(C14-C13)*1440,"") -> 9 | H13: =IFERROR('R07'!$M$19+0,"") -> 120 | I13: Sí | K13: =IFERROR('R07'!$M$12+0,"") -> 335.61307 | L13: =IFERROR('R07'!$M$13+0,"") -> 218.1485 | M13: ='R07'!$M$20 -> Aviso: el pico está corrido; el barrido no llega a una de las alas | N13: =IF(AND(ISNUMBER(L13),I13<>"No"),L13,"") -> 218.1485
A14: 8 | B14: R08 | C14: 0.34097222 | D14: 0.34513889 | E14: =IF(AND(ISNUMBER(C14),ISNUMBER(D14)),(D14-C14)*1440,"") -> 6 | F14: =IF(AND(ISNUMBER(C14),ISNUMBER(C15)),(C15-C14)*1440,"") -> 9 | H14: =IFERROR('R08'!$M$19+0,"") -> 120 | I14: Sí | K14: =IFERROR('R08'!$M$12+0,"") -> 336.68545 | L14: =IFERROR('R08'!$M$13+0,"") -> 218.84554 | M14: ='R08'!$M$20 -> Aviso: el pico está corrido; el barrido no llega a una de las alas | N14: =IF(AND(ISNUMBER(L14),I14<>"No"),L14,"") -> 218.84554
A15: 9 | B15: R09 | C15: 0.34722222 | D15: 0.35208333 | E15: =IF(AND(ISNUMBER(C15),ISNUMBER(D15)),(D15-C15)*1440,"") -> 7 | F15: =IF(AND(ISNUMBER(C15),ISNUMBER(C16)),(C16-C15)*1440,"") | H15: =IFERROR('R09'!$M$19+0,"") -> 120 | I15: Sí | K15: =IFERROR('R09'!$M$12+0,"") -> 339.31995 | L15: =IFERROR('R09'!$M$13+0,"") -> 220.55797 | M15: ='R09'!$M$20 -> Aviso: el pico está corrido; el barrido no llega a una de las alas | N15: =IF(AND(ISNUMBER(L15),I15<>"No"),L15,"") -> 220.55797
A16: 10 | B16: R10 | E16: =IF(AND(ISNUMBER(C16),ISNUMBER(D16)),(D16-C16)*1440,"") | F16: =IF(AND(ISNUMBER(C16),ISNUMBER(C17)),(C17-C16)*1440,"") | H16: =IFERROR('R10'!$M$19+0,"") | J16: Reposición: anotar qué traza reemplaza | K16: =IFERROR('R10'!$M$12+0,"") | L16: =IFERROR('R10'!$M$13+0,"") | M16: ='R10'!$M$20 -> Sin datos | N16: =IF(AND(ISNUMBER(L16),I16<>"No"),L16,"")
A17: 11 | B17: R11 | E17: =IF(AND(ISNUMBER(C17),ISNUMBER(D17)),(D17-C17)*1440,"") | F17: =IF(AND(ISNUMBER(C17),ISNUMBER(C18)),(C18-C17)*1440,"") | H17: =IFERROR('R11'!$M$19+0,"") | J17: Reposición: anotar qué traza reemplaza | K17: =IFERROR('R11'!$M$12+0,"") | L17: =IFERROR('R11'!$M$13+0,"") | M17: ='R11'!$M$20 -> Sin datos | N17: =IF(AND(ISNUMBER(L17),I17<>"No"),L17,"")
A18: 12 | B18: R12 | E18: =IF(AND(ISNUMBER(C18),ISNUMBER(D18)),(D18-C18)*1440,"") | H18: =IFERROR('R12'!$M$19+0,"") | J18: Reposición: anotar qué traza reemplaza | K18: =IFERROR('R12'!$M$12+0,"") | L18: =IFERROR('R12'!$M$13+0,"") | M18: ='R12'!$M$20 -> Sin datos | N18: =IF(AND(ISNUMBER(L18),I18<>"No"),L18,"")
D20: Media | E20: =IF(COUNT(E7:E18)=0,"",AVERAGE(E7:E18)) -> 6.6666667 | F20: =IF(COUNT(F7:F18)=0,"",AVERAGE(F7:F18)) -> 9.625
D21: Total (h) | E21: =IF(COUNT(C7:D18)<2,"",(MAX(D7:D18)-MIN(C7:C18))*24) -> 1.4 | F21: del primer inicio al último fin
A23: Reglas del protocolo (sección 5): una traza solo se marca «No» por una causa anotada en el momento (el láser perdió los pulsos, la potencia salió de rango, el barrido se interrumpió). Nunca por dar un valor inesperado. La traza que la reemplaza va en la siguiente hoja de reposición (R10, R11, R12), y se anota en Observaciones a cuál reemplaza.

Sheet Resumen
A1: Resumen y prueba t de una muestra · 5 A
A2: Cuentan las trazas con τp calculado y no marcadas «No» en el Registro (incluidas las de reposición).
A4: Cálculo | B4: Valor | C4: Nota
A5: Réplicas válidas n | B5: =COUNT(Registro!$N$7:$N$18) -> 9 | C5: Meta: 9.
A6: Media de τp, ȳ (fs) | B6: =IF(B5=0,"",AVERAGE(Registro!$N$7:$N$18)) -> 219.79143 | C6: Estimador: ancho a media altura × factor sech².
A7: Desviación estándar S (fs) | B7: =IF(B5<2,"",_xlfn.STDEV.S(Registro!$N$7:$N$18)) -> 2.5671214
A8: Coeficiente de variación (%) | B8: =IF(ISNUMBER(B7),100*B7/B6,"") -> 1.1679807
A9: τ0 del fabricante (fs) | B9: =tau0 -> 107 | C9: Tabla 5 de la hoja de pruebas.
A10: ȳ − τ0 (fs) | B10: =IF(ISNUMBER(B6),B6-B9,"") -> 112.79143
A11: Estadístico t0 = (ȳ − τ0) / (S/√n) | B11: =IF(ISNUMBER(B7),B10/(B7/SQRT(B5)),"") -> 131.81079 | C11: H0: μ = τ0 frente a H1: μ ≠ τ0.
A12: Grados de libertad n − 1 | B12: =IF(B5>1,B5-1,"") -> 8
A13: t crítico t(α/2, n − 1) | B13: =IF(ISNUMBER(B12),_xlfn.T.INV.2T(alfa,B12),"") -> 2.3060041
A14: Valor P (dos colas) | B14: =IF(ISNUMBER(B11),_xlfn.T.DIST.2T(ABS(B11),B12),"") -> 1.2271301e-14
A15: Límite inferior del IC 95 % de μ (fs) | B15: =IF(ISNUMBER(B13),B6-B13*B7/SQRT(B5),"") -> 217.81817
A16: Límite superior del IC 95 % de μ (fs) | B16: =IF(ISNUMBER(B13),B6+B13*B7/SQRT(B5),"") -> 221.7647
A17: Decisión | B17: =IF(ISNUMBER(B14),IF(B14<alfa,"Se rechaza H0: el ancho medido difiere de τ0","No se rechaza H0: no hay evidencia de diferencia con τ0"),"") -> Se rechaza H0: el ancho medido difiere de τ0
A18: Duración media por corrida (min) | B18: =Registro!E20 -> 6.6666667 | C18: Desde el Registro.
A20: Prueba preliminar con el estimador de la hoja (FWHM × 0,65). El informe usa el ajuste sech² de toda la traza (analiza_piloto.py) y valida los supuestos (normalidad, sin tendencia en el orden de medición).

Sheet R01
A1: Posición del micrómetro (µm) · fija | B1: Potencia óptica (W) | C1: Retardo τ (fs) | D1: Señal suavizada | E1: Señal normalizada | F1: Cruce izq. (fila) | G1: Cruce der. (fila) | H1: τ de cruce (fs) | I1: Retardo centrado (fs) · gráfica | J1: Normalizada · gráfica | K1: Sentido | L1: Traza R01 | M1: 5 A
A2: 0 | B2: -6.99e-09 | C2: =IF(ISNUMBER(A2),A2*conv,"") -> 0 | D2: =IF(ISNUMBER(B2),AVERAGE(INDEX($B$2:$B$23,MAX(1,1-semi)):INDEX($B$2:$B$23,MIN($M$3,1+semi))),"") -> -6.99e-09 | E2: =IF(AND(ISNUMBER(D2),ISNUMBER($M$4)),(D2-$M$4)/($M$5-$M$4),"") -> -0.0073639312 | F2: =IF(AND(ISNUMBER(E2),ISNUMBER(E3),ISNUMBER($M$6)),IF(AND(2<$M$6,E2<0.5,E3>=0.5),2,""),"") | G2: =IF(AND(ISNUMBER(E2),ISNUMBER(E3),ISNUMBER($M$6)),IF(AND(2>=$M$6,E2>=0.5,E3<0.5),2,""),"") | H2: =IF(OR(ISNUMBER(F2),ISNUMBER(G2)),C2+(0.5-E2)*(C3-C2)/(E3-E2),"") | I2: =IF(AND(ISNUMBER(E2),ISNUMBER($M$15)),C2-$M$15,NA()) -> -791.26356 | J2: =IF(ISNUMBER(E2),E2,NA()) -> -0.0073639312 | K2: =IF(AND(ISNUMBER(C2),ISNUMBER(C3)),SIGN(C3-C2),"") -> 1 | L2: Posiciones de la traza | M2: =COUNT($A$2:$A$23) -> 22
A3: 10 | B3: 4.83e-08 | C3: =IF(ISNUMBER(A3),A3*conv,"") -> 66.712819 | D3: =IF(ISNUMBER(B3),AVERAGE(INDEX($B$2:$B$23,MAX(1,2-semi)):INDEX($B$2:$B$23,MIN($M$3,2+semi))),"") -> 4.83e-08 | E3: =IF(AND(ISNUMBER(D3),ISNUMBER($M$4)),(D3-$M$4)/($M$5-$M$4),"") -> -0.0052206606 | F3: =IF(AND(ISNUMBER(E3),ISNUMBER(E4),ISNUMBER($M$6)),IF(AND(3<$M$6,E3<0.5,E4>=0.5),3,""),"") | G3: =IF(AND(ISNUMBER(E3),ISNUMBER(E4),ISNUMBER($M$6)),IF(AND(3>=$M$6,E3>=0.5,E4<0.5),3,""),"") | H3: =IF(OR(ISNUMBER(F3),ISNUMBER(G3)),C3+(0.5-E3)*(C4-C3)/(E4-E3),"") | I3: =IF(AND(ISNUMBER(E3),ISNUMBER($M$15)),C3-$M$15,NA()) -> -724.55075 | J3: =IF(ISNUMBER(E3),E3,NA()) -> -0.0052206606 | K3: =IF(AND(ISNUMBER(C3),ISNUMBER(C4)),SIGN(C4-C3),"") -> 1 | L3: Lecturas de potencia escritas | M3: =COUNT($B$2:$B$23) -> 22
A4: 20 | B4: 1.98e-07 | C4: =IF(ISNUMBER(A4),A4*conv,"") -> 133.42564 | D4: =IF(ISNUMBER(B4),AVERAGE(INDEX($B$2:$B$23,MAX(1,3-semi)):INDEX($B$2:$B$23,MIN($M$3,3+semi))),"") -> 1.98e-07 | E4: =IF(AND(ISNUMBER(D4),ISNUMBER($M$4)),(D4-$M$4)/($M$5-$M$4),"") -> 0.00058233465 | F4: =IF(AND(ISNUMBER(E4),ISNUMBER(E5),ISNUMBER($M$6)),IF(AND(4<$M$6,E4<0.5,E5>=0.5),4,""),"") | G4: =IF(AND(ISNUMBER(E4),ISNUMBER(E5),ISNUMBER($M$6)),IF(AND(4>=$M$6,E4>=0.5,E5<0.5),4,""),"") | H4: =IF(OR(ISNUMBER(F4),ISNUMBER(G4)),C4+(0.5-E4)*(C5-C4)/(E5-E4),"") | I4: =IF(AND(ISNUMBER(E4),ISNUMBER($M$15)),C4-$M$15,NA()) -> -657.83793 | J4: =IF(ISNUMBER(E4),E4,NA()) -> 0.00058233465 | K4: =IF(AND(ISNUMBER(C4),ISNUMBER(C5)),SIGN(C5-C4),"") -> 1 | L4: Fondo (promedio de las alas, W) | M4: =IF($M$3<$M$2,"",(AVERAGE(INDEX($B$2:$B$23,1):INDEX($B$2:$B$23,n_fondo))+AVERAGE(INDEX($B$2:$B$23,$M$3-n_fondo+1):INDEX($B$2:$B$23,$M$3)))/2) -> 1.829775e-07
A5: 30 | B5: 2.04e-07 | C5: =IF(ISNUMBER(A5),A5*conv,"") -> 200.13846 | D5: =IF(ISNUMBER(B5),AVERAGE(INDEX($B$2:$B$23,MAX(1,4-semi)):INDEX($B$2:$B$23,MIN($M$3,4+semi))),"") -> 2.04e-07 | E5: =IF(AND(ISNUMBER(D5),ISNUMBER($M$4)),(D5-$M$4)/($M$5-$M$4),"") -> 0.00081491963 | F5: =IF(AND(ISNUMBER(E5),ISNUMBER(E6),ISNUMBER($M$6)),IF(AND(5<$M$6,E5<0.5,E6>=0.5),5,""),"") | G5: =IF(AND(ISNUMBER(E5),ISNUMBER(E6),ISNUMBER($M$6)),IF(AND(5>=$M$6,E5>=0.5,E6<0.5),5,""),"") | H5: =IF(OR(ISNUMBER(F5),ISNUMBER(G5)),C5+(0.5-E5)*(C6-C5)/(E6-E5),"") | I5: =IF(AND(ISNUMBER(E5),ISNUMBER($M$15)),C5-$M$15,NA()) -> -591.12511 | J5: =IF(ISNUMBER(E5),E5,NA()) -> 0.00081491963 | K5: =IF(AND(ISNUMBER(C5),ISNUMBER(C6)),SIGN(C6-C5),"") -> 1 | L5: Máximo de la señal (W) | M5: =IF($M$3<$M$2,"",MAX($D$2:$D$23)) -> 2.598e-05
A6: 40 | B6: 4.03e-07 | C6: =IF(ISNUMBER(A6),A6*conv,"") -> 266.85128 | D6: =IF(ISNUMBER(B6),AVERAGE(INDEX($B$2:$B$23,MAX(1,5-semi)):INDEX($B$2:$B$23,MIN($M$3,5+semi))),"") -> 4.03e-07 | E6: =IF(AND(ISNUMBER(D6),ISNUMBER($M$4)),(D6-$M$4)/($M$5-$M$4),"") -> 0.0085289882 | F6: =IF(AND(ISNUMBER(E6),ISNUMBER(E7),ISNUMBER($M$6)),IF(AND(6<$M$6,E6<0.5,E7>=0.5),6,""),"") | G6: =IF(AND(ISNUMBER(E6),ISNUMBER(E7),ISNUMBER($M$6)),IF(AND(6>=$M$6,E6>=0.5,E7<0.5),6,""),"") | H6: =IF(OR(ISNUMBER(F6),ISNUMBER(G6)),C6+(0.5-E6)*(C7-C6)/(E7-E6),"") | I6: =IF(AND(ISNUMBER(E6),ISNUMBER($M$15)),C6-$M$15,NA()) -> -524.41229 | J6: =IF(ISNUMBER(E6),E6,NA()) -> 0.0085289882 | K6: =IF(AND(ISNUMBER(C6),ISNUMBER(C7)),SIGN(C7-C6),"") -> 1 | L6: Fila del máximo | M6: =IFERROR(MATCH($M$5,$D$2:$D$23,0)+1,"") -> 14
A7: 50 | B7: 6.95e-07 | C7: =IF(ISNUMBER(A7),A7*conv,"") -> 333.5641 | D7: =IF(ISNUMBER(B7),AVERAGE(INDEX($B$2:$B$23,MAX(1,6-semi)):INDEX($B$2:$B$23,MIN($M$3,6+semi))),"") -> 6.95e-07 | E7: =IF(AND(ISNUMBER(D7),ISNUMBER($M$4)),(D7-$M$4)/($M$5-$M$4),"") -> 0.019848124 | F7: =IF(AND(ISNUMBER(E7),ISNUMBER(E8),ISNUMBER($M$6)),IF(AND(7<$M$6,E7<0.5,E8>=0.5),7,""),"") | G7: =IF(AND(ISNUMBER(E7),ISNUMBER(E8),ISNUMBER($M$6)),IF(AND(7>=$M$6,E7>=0.5,E8<0.5),7,""),"") | H7: =IF(OR(ISNUMBER(F7),ISNUMBER(G7)),C7+(0.5-E7)*(C8-C7)/(E8-E7),"") | I7: =IF(AND(ISNUMBER(E7),ISNUMBER($M$15)),C7-$M$15,NA()) -> -457.69947 | J7: =IF(ISNUMBER(E7),E7,NA()) -> 0.019848124 | K7: =IF(AND(ISNUMBER(C7),ISNUMBER(C8)),SIGN(C8-C7),"") -> 1 | L7: Retardo del máximo (fs) | M7: =IFERROR(INDEX($C$1:$C$23,$M$6),"") -> 800.55383
A8: 60 | B8: 1.54e-06 | C8: =IF(ISNUMBER(A8),A8*conv,"") -> 400.27691 | D8: =IF(ISNUMBER(B8),AVERAGE(INDEX($B$2:$B$23,MAX(1,7-semi)):INDEX($B$2:$B$23,MIN($M$3,7+semi))),"") -> 1.54e-06 | E8: =IF(AND(ISNUMBER(D8),ISNUMBER($M$4)),(D8-$M$4)/($M$5-$M$4),"") -> 0.052603842 | F8: =IF(AND(ISNUMBER(E8),ISNUMBER(E9),ISNUMBER($M$6)),IF(AND(8<$M$6,E8<0.5,E9>=0.5),8,""),"") | G8: =IF(AND(ISNUMBER(E8),ISNUMBER(E9),ISNUMBER($M$6)),IF(AND(8>=$M$6,E8>=0.5,E9<0.5),8,""),"") | H8: =IF(OR(ISNUMBER(F8),ISNUMBER(G8)),C8+(0.5-E8)*(C9-C8)/(E9-E8),"") | I8: =IF(AND(ISNUMBER(E8),ISNUMBER($M$15)),C8-$M$15,NA()) -> -390.98665 | J8: =IF(ISNUMBER(E8),E8,NA()) -> 0.052603842 | K8: =IF(AND(ISNUMBER(C8),ISNUMBER(C9)),SIGN(C9-C8),"") -> 1 | L8: Fila del cruce izquierdo a media altura | M8: =MAX($F$2:$F$23) -> 11
A9: 70 | B9: 2.859e-06 | C9: =IF(ISNUMBER(A9),A9*conv,"") -> 466.98973 | D9: =IF(ISNUMBER(B9),AVERAGE(INDEX($B$2:$B$23,MAX(1,8-semi)):INDEX($B$2:$B$23,MIN($M$3,8+semi))),"") -> 2.859e-06 | E9: =IF(AND(ISNUMBER(D9),ISNUMBER($M$4)),(D9-$M$4)/($M$5-$M$4),"") -> 0.10373377 | F9: =IF(AND(ISNUMBER(E9),ISNUMBER(E10),ISNUMBER($M$6)),IF(AND(9<$M$6,E9<0.5,E10>=0.5),9,""),"") | G9: =IF(AND(ISNUMBER(E9),ISNUMBER(E10),ISNUMBER($M$6)),IF(AND(9>=$M$6,E9>=0.5,E10<0.5),9,""),"") | H9: =IF(OR(ISNUMBER(F9),ISNUMBER(G9)),C9+(0.5-E9)*(C10-C9)/(E10-E9),"") | I9: =IF(AND(ISNUMBER(E9),ISNUMBER($M$15)),C9-$M$15,NA()) -> -324.27383 | J9: =IF(ISNUMBER(E9),E9,NA()) -> 0.10373377 | K9: =IF(AND(ISNUMBER(C9),ISNUMBER(C10)),SIGN(C10-C9),"") -> 1 | L9: Fila del cruce derecho a media altura | M9: =MIN($G$2:$G$23) -> 16
A10: 80 | B10: 5.706e-06 | C10: =IF(ISNUMBER(A10),A10*conv,"") -> 533.70255 | D10: =IF(ISNUMBER(B10),AVERAGE(INDEX($B$2:$B$23,MAX(1,9-semi)):INDEX($B$2:$B$23,MIN($M$3,9+semi))),"") -> 5.706e-06 | E10: =IF(AND(ISNUMBER(D10),ISNUMBER($M$4)),(D10-$M$4)/($M$5-$M$4),"") -> 0.21409535 | F10: =IF(AND(ISNUMBER(E10),ISNUMBER(E11),ISNUMBER($M$6)),IF(AND(10<$M$6,E10<0.5,E11>=0.5),10,""),"") | G10: =IF(AND(ISNUMBER(E10),ISNUMBER(E11),ISNUMBER($M$6)),IF(AND(10>=$M$6,E10>=0.5,E11<0.5),10,""),"") | H10: =IF(OR(ISNUMBER(F10),ISNUMBER(G10)),C10+(0.5-E10)*(C11-C10)/(E11-E10),"") | I10: =IF(AND(ISNUMBER(E10),ISNUMBER($M$15)),C10-$M$15,NA()) -> -257.56101 | J10: =IF(ISNUMBER(E10),E10,NA()) -> 0.21409535 | K10: =IF(AND(ISNUMBER(C10),ISNUMBER(C11)),SIGN(C11-C10),"") -> 1 | L10: τ del cruce izquierdo (fs) | M10: =IF($M$8>0,INDEX($H$1:$H$23,$M$8),"") -> 620.537
A11: 90 | B11: 1.075e-05 | C11: =IF(ISNUMBER(A11),A11*conv,"") -> 600.41537 | D11: =IF(ISNUMBER(B11),AVERAGE(INDEX($B$2:$B$23,MAX(1,10-semi)):INDEX($B$2:$B$23,MIN($M$3,10+semi))),"") -> 1.075e-05 | E11: =IF(AND(ISNUMBER(D11),ISNUMBER($M$4)),(D11-$M$4)/($M$5-$M$4),"") -> 0.40962179 | F11: =IF(AND(ISNUMBER(E11),ISNUMBER(E12),ISNUMBER($M$6)),IF(AND(11<$M$6,E11<0.5,E12>=0.5),11,""),"") -> 11 | G11: =IF(AND(ISNUMBER(E11),ISNUMBER(E12),ISNUMBER($M$6)),IF(AND(11>=$M$6,E11>=0.5,E12<0.5),11,""),"") | H11: =IF(OR(ISNUMBER(F11),ISNUMBER(G11)),C11+(0.5-E11)*(C12-C11)/(E12-E11),"") -> 620.537 | I11: =IF(AND(ISNUMBER(E11),ISNUMBER($M$15)),C11-$M$15,NA()) -> -190.84819 | J11: =IF(ISNUMBER(E11),E11,NA()) -> 0.40962179 | K11: =IF(AND(ISNUMBER(C11),ISNUMBER(C12)),SIGN(C12-C11),"") -> 1 | L11: τ del cruce derecho (fs) | M11: =IF($M$9>0,INDEX($H$1:$H$23,$M$9),"") -> 961.99013
A12: 100 | B12: 1.848e-05 | C12: =IF(ISNUMBER(A12),A12*conv,"") -> 667.12819 | D12: =IF(ISNUMBER(B12),AVERAGE(INDEX($B$2:$B$23,MAX(1,11-semi)):INDEX($B$2:$B$23,MIN($M$3,11+semi))),"") -> 1.848e-05 | E12: =IF(AND(ISNUMBER(D12),ISNUMBER($M$4)),(D12-$M$4)/($M$5-$M$4),"") -> 0.70926877 | F12: =IF(AND(ISNUMBER(E12),ISNUMBER(E13),ISNUMBER($M$6)),IF(AND(12<$M$6,E12<0.5,E13>=0.5),12,""),"") | G12: =IF(AND(ISNUMBER(E12),ISNUMBER(E13),ISNUMBER($M$6)),IF(AND(12>=$M$6,E12>=0.5,E13<0.5),12,""),"") | H12: =IF(OR(ISNUMBER(F12),ISNUMBER(G12)),C12+(0.5-E12)*(C13-C12)/(E13-E12),"") | I12: =IF(AND(ISNUMBER(E12),ISNUMBER($M$15)),C12-$M$15,NA()) -> -124.13537 | J12: =IF(ISNUMBER(E12),E12,NA()) -> 0.70926877 | K12: =IF(AND(ISNUMBER(C12),ISNUMBER(C13)),SIGN(C13-C12),"") -> 1 | L12: Ancho de la traza a media altura Δτ_AC (fs) | M12: =IF(AND($M$8>0,$M$9>0),ABS($M$11-$M$10),"") -> 341.45313
A13: 110 | B13: 2.44e-05 | C13: =IF(ISNUMBER(A13),A13*conv,"") -> 733.84101 | D13: =IF(ISNUMBER(B13),AVERAGE(INDEX($B$2:$B$23,MAX(1,12-semi)):INDEX($B$2:$B$23,MIN($M$3,12+semi))),"") -> 2.44e-05 | E13: =IF(AND(ISNUMBER(D13),ISNUMBER($M$4)),(D13-$M$4)/($M$5-$M$4),"") -> 0.93875262 | F13: =IF(AND(ISNUMBER(E13),ISNUMBER(E14),ISNUMBER($M$6)),IF(AND(13<$M$6,E13<0.5,E14>=0.5),13,""),"") | G13: =IF(AND(ISNUMBER(E13),ISNUMBER(E14),ISNUMBER($M$6)),IF(AND(13>=$M$6,E13>=0.5,E14<0.5),13,""),"") | H13: =IF(OR(ISNUMBER(F13),ISNUMBER(G13)),C13+(0.5-E13)*(C14-C13)/(E14-E13),"") | I13: =IF(AND(ISNUMBER(E13),ISNUMBER($M$15)),C13-$M$15,NA()) -> -57.422555 | J13: =IF(ISNUMBER(E13),E13,NA()) -> 0.93875262 | K13: =IF(AND(ISNUMBER(C13),ISNUMBER(C14)),SIGN(C14-C13),"") -> 1 | L13: Ancho de pulso τp = factor × Δτ_AC (fs) | M13: =IF(ISNUMBER($M$12),factor_forma*$M$12,"") -> 221.94453
A14: 120 | B14: 2.598e-05 | C14: =IF(ISNUMBER(A14),A14*conv,"") -> 800.55383 | D14: =IF(ISNUMBER(B14),AVERAGE(INDEX($B$2:$B$23,MAX(1,13-semi)):INDEX($B$2:$B$23,MIN($M$3,13+semi))),"") -> 2.598e-05 | E14: =IF(AND(ISNUMBER(D14),ISNUMBER($M$4)),(D14-$M$4)/($M$5-$M$4),"") -> 1 | F14: =IF(AND(ISNUMBER(E14),ISNUMBER(E15),ISNUMBER($M$6)),IF(AND(14<$M$6,E14<0.5,E15>=0.5),14,""),"") | G14: =IF(AND(ISNUMBER(E14),ISNUMBER(E15),ISNUMBER($M$6)),IF(AND(14>=$M$6,E14>=0.5,E15<0.5),14,""),"") | H14: =IF(OR(ISNUMBER(F14),ISNUMBER(G14)),C14+(0.5-E14)*(C15-C14)/(E15-E14),"") | I14: =IF(AND(ISNUMBER(E14),ISNUMBER($M$15)),C14-$M$15,NA()) -> 9.2902643 | J14: =IF(ISNUMBER(E14),E14,NA()) -> 1 | K14: =IF(AND(ISNUMBER(C14),ISNUMBER(C15)),SIGN(C15-C14),"") -> 1 | L14: Referencia: τp si fuera gaussiano (fs) | M14: =IF(ISNUMBER($M$12),0.7071*$M$12,"") -> 241.44151
A15: 130 | B15: 2.27e-05 | C15: =IF(ISNUMBER(A15),A15*conv,"") -> 867.26665 | D15: =IF(ISNUMBER(B15),AVERAGE(INDEX($B$2:$B$23,MAX(1,14-semi)):INDEX($B$2:$B$23,MIN($M$3,14+semi))),"") -> 2.27e-05 | E15: =IF(AND(ISNUMBER(D15),ISNUMBER($M$4)),(D15-$M$4)/($M$5-$M$4),"") -> 0.87285354 | F15: =IF(AND(ISNUMBER(E15),ISNUMBER(E16),ISNUMBER($M$6)),IF(AND(15<$M$6,E15<0.5,E16>=0.5),15,""),"") | G15: =IF(AND(ISNUMBER(E15),ISNUMBER(E16),ISNUMBER($M$6)),IF(AND(15>=$M$6,E15>=0.5,E16<0.5),15,""),"") | H15: =IF(OR(ISNUMBER(F15),ISNUMBER(G15)),C15+(0.5-E15)*(C16-C15)/(E16-E15),"") | I15: =IF(AND(ISNUMBER(E15),ISNUMBER($M$15)),C15-$M$15,NA()) -> 76.003083 | J15: =IF(ISNUMBER(E15),E15,NA()) -> 0.87285354 | K15: =IF(AND(ISNUMBER(C15),ISNUMBER(C16)),SIGN(C16-C15),"") -> 1 | L15: Centro de la traza (fs) | M15: =IF(ISNUMBER($M$12),($M$10+$M$11)/2,$M$7) -> 791.26356
A16: 140 | B16: 1.6e-05 | C16: =IF(ISNUMBER(A16),A16*conv,"") -> 933.97947 | D16: =IF(ISNUMBER(B16),AVERAGE(INDEX($B$2:$B$23,MAX(1,15-semi)):INDEX($B$2:$B$23,MIN($M$3,15+semi))),"") -> 1.6e-05 | E16: =IF(AND(ISNUMBER(D16),ISNUMBER($M$4)),(D16-$M$4)/($M$5-$M$4),"") -> 0.61313365 | F16: =IF(AND(ISNUMBER(E16),ISNUMBER(E17),ISNUMBER($M$6)),IF(AND(16<$M$6,E16<0.5,E17>=0.5),16,""),"") | G16: =IF(AND(ISNUMBER(E16),ISNUMBER(E17),ISNUMBER($M$6)),IF(AND(16>=$M$6,E16>=0.5,E17<0.5),16,""),"") -> 16 | H16: =IF(OR(ISNUMBER(F16),ISNUMBER(G16)),C16+(0.5-E16)*(C17-C16)/(E17-E16),"") -> 961.99013 | I16: =IF(AND(ISNUMBER(E16),ISNUMBER($M$15)),C16-$M$15,NA()) -> 142.7159 | J16: =IF(ISNUMBER(E16),E16,NA()) -> 0.61313365 | K16: =IF(AND(ISNUMBER(C16),ISNUMBER(C17)),SIGN(C17-C16),"") -> 1 | L16: Lecturas dentro del ancho a media altura | M16: =COUNTIF($E$2:$E$23,">=0.5") -> 5
A17: 150 | B17: 9.049e-06 | C17: =IF(ISNUMBER(A17),A17*conv,"") -> 1000.6923 | D17: =IF(ISNUMBER(B17),AVERAGE(INDEX($B$2:$B$23,MAX(1,16-semi)):INDEX($B$2:$B$23,MIN($M$3,16+semi))),"") -> 9.049e-06 | E17: =IF(AND(ISNUMBER(D17),ISNUMBER($M$4)),(D17-$M$4)/($M$5-$M$4),"") -> 0.34368395 | F17: =IF(AND(ISNUMBER(E17),ISNUMBER(E18),ISNUMBER($M$6)),IF(AND(17<$M$6,E17<0.5,E18>=0.5),17,""),"") | G17: =IF(AND(ISNUMBER(E17),ISNUMBER(E18),ISNUMBER($M$6)),IF(AND(17>=$M$6,E17>=0.5,E18<0.5),17,""),"") | H17: =IF(OR(ISNUMBER(F17),ISNUMBER(G17)),C17+(0.5-E17)*(C18-C17)/(E18-E17),"") | I17: =IF(AND(ISNUMBER(E17),ISNUMBER($M$15)),C17-$M$15,NA()) -> 209.42872 | J17: =IF(ISNUMBER(E17),E17,NA()) -> 0.34368395 | K17: =IF(AND(ISNUMBER(C17),ISNUMBER(C18)),SIGN(C18-C17),"") -> 1 | L17: Recorrido a la izquierda del centro (fs) | M17: =IFERROR($M$15-MIN($C$2:$C$23),"") -> 791.26356
A18: 160 | B18: 4.523e-06 | C18: =IF(ISNUMBER(A18),A18*conv,"") -> 1067.4051 | D18: =IF(ISNUMBER(B18),AVERAGE(INDEX($B$2:$B$23,MAX(1,17-semi)):INDEX($B$2:$B$23,MIN($M$3,17+semi))),"") -> 4.523e-06 | E18: =IF(AND(ISNUMBER(D18),ISNUMBER($M$4)),(D18-$M$4)/($M$5-$M$4),"") -> 0.16823734 | F18: =IF(AND(ISNUMBER(E18),ISNUMBER(E19),ISNUMBER($M$6)),IF(AND(18<$M$6,E18<0.5,E19>=0.5),18,""),"") | G18: =IF(AND(ISNUMBER(E18),ISNUMBER(E19),ISNUMBER($M$6)),IF(AND(18>=$M$6,E18>=0.5,E19<0.5),18,""),"") | H18: =IF(OR(ISNUMBER(F18),ISNUMBER(G18)),C18+(0.5-E18)*(C19-C18)/(E19-E18),"") | I18: =IF(AND(ISNUMBER(E18),ISNUMBER($M$15)),C18-$M$15,NA()) -> 276.14154 | J18: =IF(ISNUMBER(E18),E18,NA()) -> 0.16823734 | K18: =IF(AND(ISNUMBER(C18),ISNUMBER(C19)),SIGN(C19-C18),"") -> 1 | L18: Recorrido a la derecha del centro (fs) | M18: =IFERROR(MAX($C$2:$C$23)-$M$15,"") -> 609.70564
A19: 170 | B19: 2.28e-06 | C19: =IF(ISNUMBER(A19),A19*conv,"") -> 1134.1179 | D19: =IF(ISNUMBER(B19),AVERAGE(INDEX($B$2:$B$23,MAX(1,18-semi)):INDEX($B$2:$B$23,MIN($M$3,18+semi))),"") -> 2.28e-06 | E19: =IF(AND(ISNUMBER(D19),ISNUMBER($M$4)),(D19-$M$4)/($M$5-$M$4),"") -> 0.081289323 | F19: =IF(AND(ISNUMBER(E19),ISNUMBER(E20),ISNUMBER($M$6)),IF(AND(19<$M$6,E19<0.5,E20>=0.5),19,""),"") | G19: =IF(AND(ISNUMBER(E19),ISNUMBER(E20),ISNUMBER($M$6)),IF(AND(19>=$M$6,E19>=0.5,E20<0.5),19,""),"") | H19: =IF(OR(ISNUMBER(F19),ISNUMBER(G19)),C19+(0.5-E19)*(C20-C19)/(E20-E19),"") | I19: =IF(AND(ISNUMBER(E19),ISNUMBER($M$15)),C19-$M$15,NA()) -> 342.85436 | J19: =IF(ISNUMBER(E19),E19,NA()) -> 0.081289323 | K19: =IF(AND(ISNUMBER(C19),ISNUMBER(C20)),SIGN(C20-C19),"") -> 1 | L19: Posición del pico (µm) | M19: =IF($M$3<$M$2,"",IFERROR(INDEX($A$1:$A$23,$M$6),"")) -> 120
A20: 180 | B20: 1.27e-06 | C20: =IF(ISNUMBER(A20),A20*conv,"") -> 1200.8307 | D20: =IF(ISNUMBER(B20),AVERAGE(INDEX($B$2:$B$23,MAX(1,19-semi)):INDEX($B$2:$B$23,MIN($M$3,19+semi))),"") -> 1.27e-06 | E20: =IF(AND(ISNUMBER(D20),ISNUMBER($M$4)),(D20-$M$4)/($M$5-$M$4),"") -> 0.042137518 | F20: =IF(AND(ISNUMBER(E20),ISNUMBER(E21),ISNUMBER($M$6)),IF(AND(20<$M$6,E20<0.5,E21>=0.5),20,""),"") | G20: =IF(AND(ISNUMBER(E20),ISNUMBER(E21),ISNUMBER($M$6)),IF(AND(20>=$M$6,E20>=0.5,E21<0.5),20,""),"") | H20: =IF(OR(ISNUMBER(F20),ISNUMBER(G20)),C20+(0.5-E20)*(C21-C20)/(E21-E20),"") | I20: =IF(AND(ISNUMBER(E20),ISNUMBER($M$15)),C20-$M$15,NA()) -> 409.56718 | J20: =IF(ISNUMBER(E20),E20,NA()) -> 0.042137518 | K20: =IF(AND(ISNUMBER(C20),ISNUMBER(C21)),SIGN(C21-C20),"") -> 1 | L20: Estado de la traza | M20: =IF($M$3=0,"Sin datos",IF($M$3<$M$2,"Incompleta: faltan lecturas de potencia",IF(OR($M$8=0,$M$9=0),"Revisar: no se hallaron los dos cruces de media altura",IF($M$16<pts_min,"Aviso: pocas lecturas dentro del ancho a media altura",IF(MIN($M$17,$M$18)<rec_min*$M$12,"Aviso: el pico está corrido; el barrido no llega a una de las alas","OK"))))) -> Aviso: el pico está corrido; el barrido no llega a una de las alas
A21: 190 | B21: 5.55e-07 | C21: =IF(ISNUMBER(A21),A21*conv,"") -> 1267.5436 | D21: =IF(ISNUMBER(B21),AVERAGE(INDEX($B$2:$B$23,MAX(1,20-semi)):INDEX($B$2:$B$23,MIN($M$3,20+semi))),"") -> 5.55e-07 | E21: =IF(AND(ISNUMBER(D21),ISNUMBER($M$4)),(D21-$M$4)/($M$5-$M$4),"") -> 0.014421141 | F21: =IF(AND(ISNUMBER(E21),ISNUMBER(E22),ISNUMBER($M$6)),IF(AND(21<$M$6,E21<0.5,E22>=0.5),21,""),"") | G21: =IF(AND(ISNUMBER(E21),ISNUMBER(E22),ISNUMBER($M$6)),IF(AND(21>=$M$6,E21>=0.5,E22<0.5),21,""),"") | H21: =IF(OR(ISNUMBER(F21),ISNUMBER(G21)),C21+(0.5-E21)*(C22-C21)/(E22-E21),"") | I21: =IF(AND(ISNUMBER(E21),ISNUMBER($M$15)),C21-$M$15,NA()) -> 476.28 | J21: =IF(ISNUMBER(E21),E21,NA()) -> 0.014421141 | K21: =IF(AND(ISNUMBER(C21),ISNUMBER(C22)),SIGN(C22-C21),"") -> 1
A22: 200 | B22: 4.152e-07 | C22: =IF(ISNUMBER(A22),A22*conv,"") -> 1334.2564 | D22: =IF(ISNUMBER(B22),AVERAGE(INDEX($B$2:$B$23,MAX(1,21-semi)):INDEX($B$2:$B$23,MIN($M$3,21+semi))),"") -> 4.152e-07 | E22: =IF(AND(ISNUMBER(D22),ISNUMBER($M$4)),(D22-$M$4)/($M$5-$M$4),"") -> 0.009001911 | F22: =IF(AND(ISNUMBER(E22),ISNUMBER(E23),ISNUMBER($M$6)),IF(AND(22<$M$6,E22<0.5,E23>=0.5),22,""),"") | G22: =IF(AND(ISNUMBER(E22),ISNUMBER(E23),ISNUMBER($M$6)),IF(AND(22>=$M$6,E22>=0.5,E23<0.5),22,""),"") | H22: =IF(OR(ISNUMBER(F22),ISNUMBER(G22)),C22+(0.5-E22)*(C23-C22)/(E23-E22),"") | I22: =IF(AND(ISNUMBER(E22),ISNUMBER($M$15)),C22-$M$15,NA()) -> 542.99282 | J22: =IF(ISNUMBER(E22),E22,NA()) -> 0.009001911 | K22: =IF(AND(ISNUMBER(C22),ISNUMBER(C23)),SIGN(C23-C22),"") -> 1 | L22: Línea de media altura (gráfica)
A23: 210 | B23: 2.754e-07 | C23: =IF(ISNUMBER(A23),A23*conv,"") -> 1400.9692 | D23: =IF(ISNUMBER(B23),AVERAGE(INDEX($B$2:$B$23,MAX(1,22-semi)):INDEX($B$2:$B$23,MIN($M$3,22+semi))),"") -> 2.754e-07 | E23: =IF(AND(ISNUMBER(D23),ISNUMBER($M$4)),(D23-$M$4)/($M$5-$M$4),"") -> 0.0035826809 | F23: =IF(AND(ISNUMBER(E23),ISNUMBER(E24),ISNUMBER($M$6)),IF(AND(23<$M$6,E23<0.5,E24>=0.5),23,""),"") | G23: =IF(AND(ISNUMBER(E23),ISNUMBER(E24),ISNUMBER($M$6)),IF(AND(23>=$M$6,E23>=0.5,E24<0.5),23,""),"") | H23: =IF(OR(ISNUMBER(F23),ISNUMBER(G23)),C23+(0.5-E23)*(C24-C23)/(E24-E23),"") | I23: =IF(AND(ISNUMBER(E23),ISNUMBER($M$15)),C23-$M$15,NA()) -> 609.70564 | J23: =IF(ISNUMBER(E23),E23,NA()) -> 0.0035826809 | K23: =IF(AND(ISNUMBER(C23),ISNUMBER(C24)),SIGN(C24-C23),"") | L23: =IF(ISNUMBER($M$12),$M$10-$M$15,NA()) -> -170.72656 | M23: =IF(ISNUMBER($M$12),0.5,NA()) -> 0.5
L24: =IF(ISNUMBER($M$12),$M$11-$M$15,NA()) -> 170.72656 | M24: =IF(ISNUMBER($M$12),0.5,NA()) -> 0.5
L26: Solo se llena la columna B (potencia en W), en el orden de las posiciones.

Sheet R02
A1: Posición del micrómetro (µm) · fija | B1: Potencia óptica (W) | C1: Retardo τ (fs) | D1: Señal suavizada | E1: Señal normalizada | F1: Cruce izq. (fila) | G1: Cruce der. (fila) | H1: τ de cruce (fs) | I1: Retardo centrado (fs) · gráfica | J1: Normalizada · gráfica | K1: Sentido | L1: Traza R02 | M1: 5 A
A2: 0 | B2: 2.335e-07 | C2: =IF(ISNUMBER(A2),A2*conv,"") -> 0 | D2: =IF(ISNUMBER(B2),AVERAGE(INDEX($B$2:$B$23,MAX(1,1-semi)):INDEX($B$2:$B$23,MIN($M$3,1+semi))),"") -> 2.335e-07 | E2: =IF(AND(ISNUMBER(D2),ISNUMBER($M$4)),(D2-$M$4)/($M$5-$M$4),"") -> 0.00077892227 | F2: =IF(AND(ISNUMBER(E2),ISNUMBER(E3),ISNUMBER($M$6)),IF(AND(2<$M$6,E2<0.5,E3>=0.5),2,""),"") | G2: =IF(AND(ISNUMBER(E2),ISNUMBER(E3),ISNUMBER($M$6)),IF(AND(2>=$M$6,E2>=0.5,E3<0.5),2,""),"") | H2: =IF(OR(ISNUMBER(F2),ISNUMBER(G2)),C2+(0.5-E2)*(C3-C2)/(E3-E2),"") | I2: =IF(AND(ISNUMBER(E2),ISNUMBER($M$15)),C2-$M$15,NA()) -> -786.59616 | J2: =IF(ISNUMBER(E2),E2,NA()) -> 0.00077892227 | K2: =IF(AND(ISNUMBER(C2),ISNUMBER(C3)),SIGN(C3-C2),"") -> 1 | L2: Posiciones de la traza | M2: =COUNT($A$2:$A$23) -> 22
A3: 10 | B3: 9.364e-08 | C3: =IF(ISNUMBER(A3),A3*conv,"") -> 66.712819 | D3: =IF(ISNUMBER(B3),AVERAGE(INDEX($B$2:$B$23,MAX(1,2-semi)):INDEX($B$2:$B$23,MIN($M$3,2+semi))),"") -> 9.364e-08 | E3: =IF(AND(ISNUMBER(D3),ISNUMBER($M$4)),(D3-$M$4)/($M$5-$M$4),"") -> -0.0044111715 | F3: =IF(AND(ISNUMBER(E3),ISNUMBER(E4),ISNUMBER($M$6)),IF(AND(3<$M$6,E3<0.5,E4>=0.5),3,""),"") | G3: =IF(AND(ISNUMBER(E3),ISNUMBER(E4),ISNUMBER($M$6)),IF(AND(3>=$M$6,E3>=0.5,E4<0.5),3,""),"") | H3: =IF(OR(ISNUMBER(F3),ISNUMBER(G3)),C3+(0.5-E3)*(C4-C3)/(E4-E3),"") | I3: =IF(AND(ISNUMBER(E3),ISNUMBER($M$15)),C3-$M$15,NA()) -> -719.88334 | J3: =IF(ISNUMBER(E3),E3,NA()) -> -0.0044111715 | K3: =IF(AND(ISNUMBER(C3),ISNUMBER(C4)),SIGN(C4-C3),"") -> 1 | L3: Lecturas de potencia escritas | M3: =COUNT($B$2:$B$23) -> 22
A4: 20 | B4: 4.711e-07 | C4: =IF(ISNUMBER(A4),A4*conv,"") -> 133.42564 | D4: =IF(ISNUMBER(B4),AVERAGE(INDEX($B$2:$B$23,MAX(1,3-semi)):INDEX($B$2:$B$23,MIN($M$3,3+semi))),"") -> 4.711e-07 | E4: =IF(AND(ISNUMBER(D4),ISNUMBER($M$4)),(D4-$M$4)/($M$5-$M$4),"") -> 0.00959607 | F4: =IF(AND(ISNUMBER(E4),ISNUMBER(E5),ISNUMBER($M$6)),IF(AND(4<$M$6,E4<0.5,E5>=0.5),4,""),"") | G4: =IF(AND(ISNUMBER(E4),ISNUMBER(E5),ISNUMBER($M$6)),IF(AND(4>=$M$6,E4>=0.5,E5<0.5),4,""),"") | H4: =IF(OR(ISNUMBER(F4),ISNUMBER(G4)),C4+(0.5-E4)*(C5-C4)/(E5-E4),"") | I4: =IF(AND(ISNUMBER(E4),ISNUMBER($M$15)),C4-$M$15,NA()) -> -653.17052 | J4: =IF(ISNUMBER(E4),E4,NA()) -> 0.00959607 | K4: =IF(AND(ISNUMBER(C4),ISNUMBER(C5)),SIGN(C5-C4),"") -> 1 | L4: Fondo (promedio de las alas, W) | M4: =IF($M$3<$M$2,"",(AVERAGE(INDEX($B$2:$B$23,1):INDEX($B$2:$B$23,n_fondo))+AVERAGE(INDEX($B$2:$B$23,$M$3-n_fondo+1):INDEX($B$2:$B$23,$M$3)))/2) -> 2.1251e-07
A5: 30 | B5: 4.152e-07 | C5: =IF(ISNUMBER(A5),A5*conv,"") -> 200.13846 | D5: =IF(ISNUMBER(B5),AVERAGE(INDEX($B$2:$B$23,MAX(1,4-semi)):INDEX($B$2:$B$23,MIN($M$3,4+semi))),"") -> 4.152e-07 | E5: =IF(AND(ISNUMBER(D5),ISNUMBER($M$4)),(D5-$M$4)/($M$5-$M$4),"") -> 0.0075216653 | F5: =IF(AND(ISNUMBER(E5),ISNUMBER(E6),ISNUMBER($M$6)),IF(AND(5<$M$6,E5<0.5,E6>=0.5),5,""),"") | G5: =IF(AND(ISNUMBER(E5),ISNUMBER(E6),ISNUMBER($M$6)),IF(AND(5>=$M$6,E5>=0.5,E6<0.5),5,""),"") | H5: =IF(OR(ISNUMBER(F5),ISNUMBER(G5)),C5+(0.5-E5)*(C6-C5)/(E6-E5),"") | I5: =IF(AND(ISNUMBER(E5),ISNUMBER($M$15)),C5-$M$15,NA()) -> -586.4577 | J5: =IF(ISNUMBER(E5),E5,NA()) -> 0.0075216653 | K5: =IF(AND(ISNUMBER(C5),ISNUMBER(C6)),SIGN(C6-C5),"") -> 1 | L5: Máximo de la señal (W) | M5: =IF($M$3<$M$2,"",MAX($D$2:$D$23)) -> 2.716e-05
A6: 40 | B6: 5.271e-07 | C6: =IF(ISNUMBER(A6),A6*conv,"") -> 266.85128 | D6: =IF(ISNUMBER(B6),AVERAGE(INDEX($B$2:$B$23,MAX(1,5-semi)):INDEX($B$2:$B$23,MIN($M$3,5+semi))),"") -> 5.271e-07 | E6: =IF(AND(ISNUMBER(D6),ISNUMBER($M$4)),(D6-$M$4)/($M$5-$M$4),"") -> 0.011674186 | F6: =IF(AND(ISNUMBER(E6),ISNUMBER(E7),ISNUMBER($M$6)),IF(AND(6<$M$6,E6<0.5,E7>=0.5),6,""),"") | G6: =IF(AND(ISNUMBER(E6),ISNUMBER(E7),ISNUMBER($M$6)),IF(AND(6>=$M$6,E6>=0.5,E7<0.5),6,""),"") | H6: =IF(OR(ISNUMBER(F6),ISNUMBER(G6)),C6+(0.5-E6)*(C7-C6)/(E7-E6),"") | I6: =IF(AND(ISNUMBER(E6),ISNUMBER($M$15)),C6-$M$15,NA()) -> -519.74488 | J6: =IF(ISNUMBER(E6),E6,NA()) -> 0.011674186 | K6: =IF(AND(ISNUMBER(C6),ISNUMBER(C7)),SIGN(C7-C6),"") -> 1 | L6: Fila del máximo | M6: =IFERROR(MATCH($M$5,$D$2:$D$23,0)+1,"") -> 14
A7: 50 | B7: 8.368e-07 | C7: =IF(ISNUMBER(A7),A7*conv,"") -> 333.5641 | D7: =IF(ISNUMBER(B7),AVERAGE(INDEX($B$2:$B$23,MAX(1,6-semi)):INDEX($B$2:$B$23,MIN($M$3,6+semi))),"") -> 8.368e-07 | E7: =IF(AND(ISNUMBER(D7),ISNUMBER($M$4)),(D7-$M$4)/($M$5-$M$4),"") -> 0.023166907 | F7: =IF(AND(ISNUMBER(E7),ISNUMBER(E8),ISNUMBER($M$6)),IF(AND(7<$M$6,E7<0.5,E8>=0.5),7,""),"") | G7: =IF(AND(ISNUMBER(E7),ISNUMBER(E8),ISNUMBER($M$6)),IF(AND(7>=$M$6,E7>=0.5,E8<0.5),7,""),"") | H7: =IF(OR(ISNUMBER(F7),ISNUMBER(G7)),C7+(0.5-E7)*(C8-C7)/(E8-E7),"") | I7: =IF(AND(ISNUMBER(E7),ISNUMBER($M$15)),C7-$M$15,NA()) -> -453.03206 | J7: =IF(ISNUMBER(E7),E7,NA()) -> 0.023166907 | K7: =IF(AND(ISNUMBER(C7),ISNUMBER(C8)),SIGN(C8-C7),"") -> 1 | L7: Retardo del máximo (fs) | M7: =IFERROR(INDEX($C$1:$C$23,$M$6),"") -> 800.55383
A8: 60 | B8: 1.636e-06 | C8: =IF(ISNUMBER(A8),A8*conv,"") -> 400.27691 | D8: =IF(ISNUMBER(B8),AVERAGE(INDEX($B$2:$B$23,MAX(1,7-semi)):INDEX($B$2:$B$23,MIN($M$3,7+semi))),"") -> 1.636e-06 | E8: =IF(AND(ISNUMBER(D8),ISNUMBER($M$4)),(D8-$M$4)/($M$5-$M$4),"") -> 0.052824586 | F8: =IF(AND(ISNUMBER(E8),ISNUMBER(E9),ISNUMBER($M$6)),IF(AND(8<$M$6,E8<0.5,E9>=0.5),8,""),"") | G8: =IF(AND(ISNUMBER(E8),ISNUMBER(E9),ISNUMBER($M$6)),IF(AND(8>=$M$6,E8>=0.5,E9<0.5),8,""),"") | H8: =IF(OR(ISNUMBER(F8),ISNUMBER(G8)),C8+(0.5-E8)*(C9-C8)/(E9-E8),"") | I8: =IF(AND(ISNUMBER(E8),ISNUMBER($M$15)),C8-$M$15,NA()) -> -386.31924 | J8: =IF(ISNUMBER(E8),E8,NA()) -> 0.052824586 | K8: =IF(AND(ISNUMBER(C8),ISNUMBER(C9)),SIGN(C9-C8),"") -> 1 | L8: Fila del cruce izquierdo a media altura | M8: =MAX($F$2:$F$23) -> 11
A9: 70 | B9: 2.868e-06 | C9: =IF(ISNUMBER(A9),A9*conv,"") -> 466.98973 | D9: =IF(ISNUMBER(B9),AVERAGE(INDEX($B$2:$B$23,MAX(1,8-semi)):INDEX($B$2:$B$23,MIN($M$3,8+semi))),"") -> 2.868e-06 | E9: =IF(AND(ISNUMBER(D9),ISNUMBER($M$4)),(D9-$M$4)/($M$5-$M$4),"") -> 0.09854313 | F9: =IF(AND(ISNUMBER(E9),ISNUMBER(E10),ISNUMBER($M$6)),IF(AND(9<$M$6,E9<0.5,E10>=0.5),9,""),"") | G9: =IF(AND(ISNUMBER(E9),ISNUMBER(E10),ISNUMBER($M$6)),IF(AND(9>=$M$6,E9>=0.5,E10<0.5),9,""),"") | H9: =IF(OR(ISNUMBER(F9),ISNUMBER(G9)),C9+(0.5-E9)*(C10-C9)/(E10-E9),"") | I9: =IF(AND(ISNUMBER(E9),ISNUMBER($M$15)),C9-$M$15,NA()) -> -319.60642 | J9: =IF(ISNUMBER(E9),E9,NA()) -> 0.09854313 | K9: =IF(AND(ISNUMBER(C9),ISNUMBER(C10)),SIGN(C10-C9),"") -> 1 | L9: Fila del cruce derecho a media altura | M9: =MIN($G$2:$G$23) -> 16
A10: 80 | B10: 5.587e-06 | C10: =IF(ISNUMBER(A10),A10*conv,"") -> 533.70255 | D10: =IF(ISNUMBER(B10),AVERAGE(INDEX($B$2:$B$23,MAX(1,9-semi)):INDEX($B$2:$B$23,MIN($M$3,9+semi))),"") -> 5.587e-06 | E10: =IF(AND(ISNUMBER(D10),ISNUMBER($M$4)),(D10-$M$4)/($M$5-$M$4),"") -> 0.19944307 | F10: =IF(AND(ISNUMBER(E10),ISNUMBER(E11),ISNUMBER($M$6)),IF(AND(10<$M$6,E10<0.5,E11>=0.5),10,""),"") | G10: =IF(AND(ISNUMBER(E10),ISNUMBER(E11),ISNUMBER($M$6)),IF(AND(10>=$M$6,E10>=0.5,E11<0.5),10,""),"") | H10: =IF(OR(ISNUMBER(F10),ISNUMBER(G10)),C10+(0.5-E10)*(C11-C10)/(E11-E10),"") | I10: =IF(AND(ISNUMBER(E10),ISNUMBER($M$15)),C10-$M$15,NA()) -> -252.8936 | J10: =IF(ISNUMBER(E10),E10,NA()) -> 0.19944307 | K10: =IF(AND(ISNUMBER(C10),ISNUMBER(C11)),SIGN(C11-C10),"") -> 1 | L10: τ del cruce izquierdo (fs) | M10: =IF($M$8>0,INDEX($H$1:$H$23,$M$8),"") -> 618.86286
A11: 90 | B11: 1.164e-05 | C11: =IF(ISNUMBER(A11),A11*conv,"") -> 600.41537 | D11: =IF(ISNUMBER(B11),AVERAGE(INDEX($B$2:$B$23,MAX(1,10-semi)):INDEX($B$2:$B$23,MIN($M$3,10+semi))),"") -> 1.164e-05 | E11: =IF(AND(ISNUMBER(D11),ISNUMBER($M$4)),(D11-$M$4)/($M$5-$M$4),"") -> 0.4240651 | F11: =IF(AND(ISNUMBER(E11),ISNUMBER(E12),ISNUMBER($M$6)),IF(AND(11<$M$6,E11<0.5,E12>=0.5),11,""),"") -> 11 | G11: =IF(AND(ISNUMBER(E11),ISNUMBER(E12),ISNUMBER($M$6)),IF(AND(11>=$M$6,E11>=0.5,E12<0.5),11,""),"") | H11: =IF(OR(ISNUMBER(F11),ISNUMBER(G11)),C11+(0.5-E11)*(C12-C11)/(E12-E11),"") -> 618.86286 | I11: =IF(AND(ISNUMBER(E11),ISNUMBER($M$15)),C11-$M$15,NA()) -> -186.18079 | J11: =IF(ISNUMBER(E11),E11,NA()) -> 0.4240651 | K11: =IF(AND(ISNUMBER(C11),ISNUMBER(C12)),SIGN(C12-C11),"") -> 1 | L11: τ del cruce derecho (fs) | M11: =IF($M$9>0,INDEX($H$1:$H$23,$M$9),"") -> 954.32945
A12: 100 | B12: 1.904e-05 | C12: =IF(ISNUMBER(A12),A12*conv,"") -> 667.12819 | D12: =IF(ISNUMBER(B12),AVERAGE(INDEX($B$2:$B$23,MAX(1,11-semi)):INDEX($B$2:$B$23,MIN($M$3,11+semi))),"") -> 1.904e-05 | E12: =IF(AND(ISNUMBER(D12),ISNUMBER($M$4)),(D12-$M$4)/($M$5-$M$4),"") -> 0.69867323 | F12: =IF(AND(ISNUMBER(E12),ISNUMBER(E13),ISNUMBER($M$6)),IF(AND(12<$M$6,E12<0.5,E13>=0.5),12,""),"") | G12: =IF(AND(ISNUMBER(E12),ISNUMBER(E13),ISNUMBER($M$6)),IF(AND(12>=$M$6,E12>=0.5,E13<0.5),12,""),"") | H12: =IF(OR(ISNUMBER(F12),ISNUMBER(G12)),C12+(0.5-E12)*(C13-C12)/(E13-E12),"") | I12: =IF(AND(ISNUMBER(E12),ISNUMBER($M$15)),C12-$M$15,NA()) -> -119.46797 | J12: =IF(ISNUMBER(E12),E12,NA()) -> 0.69867323 | K12: =IF(AND(ISNUMBER(C12),ISNUMBER(C13)),SIGN(C13-C12),"") -> 1 | L12: Ancho de la traza a media altura Δτ_AC (fs) | M12: =IF(AND($M$8>0,$M$9>0),ABS($M$11-$M$10),"") -> 335.46659
A13: 110 | B13: 2.493e-05 | C13: =IF(ISNUMBER(A13),A13*conv,"") -> 733.84101 | D13: =IF(ISNUMBER(B13),AVERAGE(INDEX($B$2:$B$23,MAX(1,12-semi)):INDEX($B$2:$B$23,MIN($M$3,12+semi))),"") -> 2.493e-05 | E13: =IF(AND(ISNUMBER(D13),ISNUMBER($M$4)),(D13-$M$4)/($M$5-$M$4),"") -> 0.91724647 | F13: =IF(AND(ISNUMBER(E13),ISNUMBER(E14),ISNUMBER($M$6)),IF(AND(13<$M$6,E13<0.5,E14>=0.5),13,""),"") | G13: =IF(AND(ISNUMBER(E13),ISNUMBER(E14),ISNUMBER($M$6)),IF(AND(13>=$M$6,E13>=0.5,E14<0.5),13,""),"") | H13: =IF(OR(ISNUMBER(F13),ISNUMBER(G13)),C13+(0.5-E13)*(C14-C13)/(E14-E13),"") | I13: =IF(AND(ISNUMBER(E13),ISNUMBER($M$15)),C13-$M$15,NA()) -> -52.755148 | J13: =IF(ISNUMBER(E13),E13,NA()) -> 0.91724647 | K13: =IF(AND(ISNUMBER(C13),ISNUMBER(C14)),SIGN(C14-C13),"") -> 1 | L13: Ancho de pulso τp = factor × Δτ_AC (fs) | M13: =IF(ISNUMBER($M$12),factor_forma*$M$12,"") -> 218.05328
A14: 120 | B14: 2.716e-05 | C14: =IF(ISNUMBER(A14),A14*conv,"") -> 800.55383 | D14: =IF(ISNUMBER(B14),AVERAGE(INDEX($B$2:$B$23,MAX(1,13-semi)):INDEX($B$2:$B$23,MIN($M$3,13+semi))),"") -> 2.716e-05 | E14: =IF(AND(ISNUMBER(D14),ISNUMBER($M$4)),(D14-$M$4)/($M$5-$M$4),"") -> 1 | F14: =IF(AND(ISNUMBER(E14),ISNUMBER(E15),ISNUMBER($M$6)),IF(AND(14<$M$6,E14<0.5,E15>=0.5),14,""),"") | G14: =IF(AND(ISNUMBER(E14),ISNUMBER(E15),ISNUMBER($M$6)),IF(AND(14>=$M$6,E14>=0.5,E15<0.5),14,""),"") | H14: =IF(OR(ISNUMBER(F14),ISNUMBER(G14)),C14+(0.5-E14)*(C15-C14)/(E15-E14),"") | I14: =IF(AND(ISNUMBER(E14),ISNUMBER($M$15)),C14-$M$15,NA()) -> 13.957671 | J14: =IF(ISNUMBER(E14),E14,NA()) -> 1 | K14: =IF(AND(ISNUMBER(C14),ISNUMBER(C15)),SIGN(C15-C14),"") -> 1 | L14: Referencia: τp si fuera gaussiano (fs) | M14: =IF(ISNUMBER($M$12),0.7071*$M$12,"") -> 237.20842
A15: 130 | B15: 2.307e-05 | C15: =IF(ISNUMBER(A15),A15*conv,"") -> 867.26665 | D15: =IF(ISNUMBER(B15),AVERAGE(INDEX($B$2:$B$23,MAX(1,14-semi)):INDEX($B$2:$B$23,MIN($M$3,14+semi))),"") -> 2.307e-05 | E15: =IF(AND(ISNUMBER(D15),ISNUMBER($M$4)),(D15-$M$4)/($M$5-$M$4),"") -> 0.84822334 | F15: =IF(AND(ISNUMBER(E15),ISNUMBER(E16),ISNUMBER($M$6)),IF(AND(15<$M$6,E15<0.5,E16>=0.5),15,""),"") | G15: =IF(AND(ISNUMBER(E15),ISNUMBER(E16),ISNUMBER($M$6)),IF(AND(15>=$M$6,E15>=0.5,E16<0.5),15,""),"") | H15: =IF(OR(ISNUMBER(F15),ISNUMBER(G15)),C15+(0.5-E15)*(C16-C15)/(E16-E15),"") | I15: =IF(AND(ISNUMBER(E15),ISNUMBER($M$15)),C15-$M$15,NA()) -> 80.67049 | J15: =IF(ISNUMBER(E15),E15,NA()) -> 0.84822334 | K15: =IF(AND(ISNUMBER(C15),ISNUMBER(C16)),SIGN(C16-C15),"") -> 1 | L15: Centro de la traza (fs) | M15: =IF(ISNUMBER($M$12),($M$10+$M$11)/2,$M$7) -> 786.59616
A16: 140 | B16: 1.582e-05 | C16: =IF(ISNUMBER(A16),A16*conv,"") -> 933.97947 | D16: =IF(ISNUMBER(B16),AVERAGE(INDEX($B$2:$B$23,MAX(1,15-semi)):INDEX($B$2:$B$23,MIN($M$3,15+semi))),"") -> 1.582e-05 | E16: =IF(AND(ISNUMBER(D16),ISNUMBER($M$4)),(D16-$M$4)/($M$5-$M$4),"") -> 0.57918159 | F16: =IF(AND(ISNUMBER(E16),ISNUMBER(E17),ISNUMBER($M$6)),IF(AND(16<$M$6,E16<0.5,E17>=0.5),16,""),"") | G16: =IF(AND(ISNUMBER(E16),ISNUMBER(E17),ISNUMBER($M$6)),IF(AND(16>=$M$6,E16>=0.5,E17<0.5),16,""),"") -> 16 | H16: =IF(OR(ISNUMBER(F16),ISNUMBER(G16)),C16+(0.5-E16)*(C17-C16)/(E17-E16),"") -> 954.32945 | I16: =IF(AND(ISNUMBER(E16),ISNUMBER($M$15)),C16-$M$15,NA()) -> 147.38331 | J16: =IF(ISNUMBER(E16),E16,NA()) -> 0.57918159 | K16: =IF(AND(ISNUMBER(C16),ISNUMBER(C17)),SIGN(C17-C16),"") -> 1 | L16: Lecturas dentro del ancho a media altura | M16: =COUNTIF($E$2:$E$23,">=0.5") -> 5
A17: 150 | B17: 8.825e-06 | C17: =IF(ISNUMBER(A17),A17*conv,"") -> 1000.6923 | D17: =IF(ISNUMBER(B17),AVERAGE(INDEX($B$2:$B$23,MAX(1,16-semi)):INDEX($B$2:$B$23,MIN($M$3,16+semi))),"") -> 8.825e-06 | E17: =IF(AND(ISNUMBER(D17),ISNUMBER($M$4)),(D17-$M$4)/($M$5-$M$4),"") -> 0.31960268 | F17: =IF(AND(ISNUMBER(E17),ISNUMBER(E18),ISNUMBER($M$6)),IF(AND(17<$M$6,E17<0.5,E18>=0.5),17,""),"") | G17: =IF(AND(ISNUMBER(E17),ISNUMBER(E18),ISNUMBER($M$6)),IF(AND(17>=$M$6,E17>=0.5,E18<0.5),17,""),"") | H17: =IF(OR(ISNUMBER(F17),ISNUMBER(G17)),C17+(0.5-E17)*(C18-C17)/(E18-E17),"") | I17: =IF(AND(ISNUMBER(E17),ISNUMBER($M$15)),C17-$M$15,NA()) -> 214.09613 | J17: =IF(ISNUMBER(E17),E17,NA()) -> 0.31960268 | K17: =IF(AND(ISNUMBER(C17),ISNUMBER(C18)),SIGN(C18-C17),"") -> 1 | L17: Recorrido a la izquierda del centro (fs) | M17: =IFERROR($M$15-MIN($C$2:$C$23),"") -> 786.59616
A18: 160 | B18: 4.341e-06 | C18: =IF(ISNUMBER(A18),A18*conv,"") -> 1067.4051 | D18: =IF(ISNUMBER(B18),AVERAGE(INDEX($B$2:$B$23,MAX(1,17-semi)):INDEX($B$2:$B$23,MIN($M$3,17+semi))),"") -> 4.341e-06 | E18: =IF(AND(ISNUMBER(D18),ISNUMBER($M$4)),(D18-$M$4)/($M$5-$M$4),"") -> 0.15320499 | F18: =IF(AND(ISNUMBER(E18),ISNUMBER(E19),ISNUMBER($M$6)),IF(AND(18<$M$6,E18<0.5,E19>=0.5),18,""),"") | G18: =IF(AND(ISNUMBER(E18),ISNUMBER(E19),ISNUMBER($M$6)),IF(AND(18>=$M$6,E18>=0.5,E19<0.5),18,""),"") | H18: =IF(OR(ISNUMBER(F18),ISNUMBER(G18)),C18+(0.5-E18)*(C19-C18)/(E19-E18),"") | I18: =IF(AND(ISNUMBER(E18),ISNUMBER($M$15)),C18-$M$15,NA()) -> 280.80895 | J18: =IF(ISNUMBER(E18),E18,NA()) -> 0.15320499 | K18: =IF(AND(ISNUMBER(C18),ISNUMBER(C19)),SIGN(C19-C18),"") -> 1 | L18: Recorrido a la derecha del centro (fs) | M18: =IFERROR(MAX($C$2:$C$23)-$M$15,"") -> 614.37304
A19: 170 | B19: 2.125e-06 | C19: =IF(ISNUMBER(A19),A19*conv,"") -> 1134.1179 | D19: =IF(ISNUMBER(B19),AVERAGE(INDEX($B$2:$B$23,MAX(1,18-semi)):INDEX($B$2:$B$23,MIN($M$3,18+semi))),"") -> 2.125e-06 | E19: =IF(AND(ISNUMBER(D19),ISNUMBER($M$4)),(D19-$M$4)/($M$5-$M$4),"") -> 0.070970988 | F19: =IF(AND(ISNUMBER(E19),ISNUMBER(E20),ISNUMBER($M$6)),IF(AND(19<$M$6,E19<0.5,E20>=0.5),19,""),"") | G19: =IF(AND(ISNUMBER(E19),ISNUMBER(E20),ISNUMBER($M$6)),IF(AND(19>=$M$6,E19>=0.5,E20<0.5),19,""),"") | H19: =IF(OR(ISNUMBER(F19),ISNUMBER(G19)),C19+(0.5-E19)*(C20-C19)/(E20-E19),"") | I19: =IF(AND(ISNUMBER(E19),ISNUMBER($M$15)),C19-$M$15,NA()) -> 347.52177 | J19: =IF(ISNUMBER(E19),E19,NA()) -> 0.070970988 | K19: =IF(AND(ISNUMBER(C19),ISNUMBER(C20)),SIGN(C20-C19),"") -> 1 | L19: Posición del pico (µm) | M19: =IF($M$3<$M$2,"",IFERROR(INDEX($A$1:$A$23,$M$6),"")) -> 120
A20: 180 | B20: 1.005e-06 | C20: =IF(ISNUMBER(A20),A20*conv,"") -> 1200.8307 | D20: =IF(ISNUMBER(B20),AVERAGE(INDEX($B$2:$B$23,MAX(1,19-semi)):INDEX($B$2:$B$23,MIN($M$3,19+semi))),"") -> 1.005e-06 | E20: =IF(AND(ISNUMBER(D20),ISNUMBER($M$4)),(D20-$M$4)/($M$5-$M$4),"") -> 0.029408676 | F20: =IF(AND(ISNUMBER(E20),ISNUMBER(E21),ISNUMBER($M$6)),IF(AND(20<$M$6,E20<0.5,E21>=0.5),20,""),"") | G20: =IF(AND(ISNUMBER(E20),ISNUMBER(E21),ISNUMBER($M$6)),IF(AND(20>=$M$6,E20>=0.5,E21<0.5),20,""),"") | H20: =IF(OR(ISNUMBER(F20),ISNUMBER(G20)),C20+(0.5-E20)*(C21-C20)/(E21-E20),"") | I20: =IF(AND(ISNUMBER(E20),ISNUMBER($M$15)),C20-$M$15,NA()) -> 414.23459 | J20: =IF(ISNUMBER(E20),E20,NA()) -> 0.029408676 | K20: =IF(AND(ISNUMBER(C20),ISNUMBER(C21)),SIGN(C21-C20),"") -> 1 | L20: Estado de la traza | M20: =IF($M$3=0,"Sin datos",IF($M$3<$M$2,"Incompleta: faltan lecturas de potencia",IF(OR($M$8=0,$M$9=0),"Revisar: no se hallaron los dos cruces de media altura",IF($M$16<pts_min,"Aviso: pocas lecturas dentro del ancho a media altura",IF(MIN($M$17,$M$18)<rec_min*$M$12,"Aviso: el pico está corrido; el barrido no llega a una de las alas","OK"))))) -> Aviso: el pico está corrido; el barrido no llega a una de las alas
A21: 190 | B21: 5.55e-07 | C21: =IF(ISNUMBER(A21),A21*conv,"") -> 1267.5436 | D21: =IF(ISNUMBER(B21),AVERAGE(INDEX($B$2:$B$23,MAX(1,20-semi)):INDEX($B$2:$B$23,MIN($M$3,20+semi))),"") -> 5.55e-07 | E21: =IF(AND(ISNUMBER(D21),ISNUMBER($M$4)),(D21-$M$4)/($M$5-$M$4),"") -> 0.012709533 | F21: =IF(AND(ISNUMBER(E21),ISNUMBER(E22),ISNUMBER($M$6)),IF(AND(21<$M$6,E21<0.5,E22>=0.5),21,""),"") | G21: =IF(AND(ISNUMBER(E21),ISNUMBER(E22),ISNUMBER($M$6)),IF(AND(21>=$M$6,E21>=0.5,E22<0.5),21,""),"") | H21: =IF(OR(ISNUMBER(F21),ISNUMBER(G21)),C21+(0.5-E21)*(C22-C21)/(E22-E21),"") | I21: =IF(AND(ISNUMBER(E21),ISNUMBER($M$15)),C21-$M$15,NA()) -> 480.9474 | J21: =IF(ISNUMBER(E21),E21,NA()) -> 0.012709533 | K21: =IF(AND(ISNUMBER(C21),ISNUMBER(C22)),SIGN(C22-C21),"") -> 1
A22: 200 | B22: 2.894e-07 | C22: =IF(ISNUMBER(A22),A22*conv,"") -> 1334.2564 | D22: =IF(ISNUMBER(B22),AVERAGE(INDEX($B$2:$B$23,MAX(1,21-semi)):INDEX($B$2:$B$23,MIN($M$3,21+semi))),"") -> 2.894e-07 | E22: =IF(AND(ISNUMBER(D22),ISNUMBER($M$4)),(D22-$M$4)/($M$5-$M$4),"") -> 0.002853327 | F22: =IF(AND(ISNUMBER(E22),ISNUMBER(E23),ISNUMBER($M$6)),IF(AND(22<$M$6,E22<0.5,E23>=0.5),22,""),"") | G22: =IF(AND(ISNUMBER(E22),ISNUMBER(E23),ISNUMBER($M$6)),IF(AND(22>=$M$6,E22>=0.5,E23<0.5),22,""),"") | H22: =IF(OR(ISNUMBER(F22),ISNUMBER(G22)),C22+(0.5-E22)*(C23-C22)/(E23-E22),"") | I22: =IF(AND(ISNUMBER(E22),ISNUMBER($M$15)),C22-$M$15,NA()) -> 547.66022 | J22: =IF(ISNUMBER(E22),E22,NA()) -> 0.002853327 | K22: =IF(AND(ISNUMBER(C22),ISNUMBER(C23)),SIGN(C23-C22),"") -> 1 | L22: Línea de media altura (gráfica)
A23: 210 | B23: 2.335e-07 | C23: =IF(ISNUMBER(A23),A23*conv,"") -> 1400.9692 | D23: =IF(ISNUMBER(B23),AVERAGE(INDEX($B$2:$B$23,MAX(1,22-semi)):INDEX($B$2:$B$23,MIN($M$3,22+semi))),"") -> 2.335e-07 | E23: =IF(AND(ISNUMBER(D23),ISNUMBER($M$4)),(D23-$M$4)/($M$5-$M$4),"") -> 0.00077892227 | F23: =IF(AND(ISNUMBER(E23),ISNUMBER(E24),ISNUMBER($M$6)),IF(AND(23<$M$6,E23<0.5,E24>=0.5),23,""),"") | G23: =IF(AND(ISNUMBER(E23),ISNUMBER(E24),ISNUMBER($M$6)),IF(AND(23>=$M$6,E23>=0.5,E24<0.5),23,""),"") | H23: =IF(OR(ISNUMBER(F23),ISNUMBER(G23)),C23+(0.5-E23)*(C24-C23)/(E24-E23),"") | I23: =IF(AND(ISNUMBER(E23),ISNUMBER($M$15)),C23-$M$15,NA()) -> 614.37304 | J23: =IF(ISNUMBER(E23),E23,NA()) -> 0.00077892227 | K23: =IF(AND(ISNUMBER(C23),ISNUMBER(C24)),SIGN(C24-C23),"") | L23: =IF(ISNUMBER($M$12),$M$10-$M$15,NA()) -> -167.73329 | M23: =IF(ISNUMBER($M$12),0.5,NA()) -> 0.5
L24: =IF(ISNUMBER($M$12),$M$11-$M$15,NA()) -> 167.73329 | M24: =IF(ISNUMBER($M$12),0.5,NA()) -> 0.5
L26: Solo se llena la columna B (potencia en W), en el orden de las posiciones.

Sheet R03
A1: Posición del micrómetro (µm) · fija | B1: Potencia óptica (W) | C1: Retardo τ (fs) | D1: Señal suavizada | E1: Señal normalizada | F1: Cruce izq. (fila) | G1: Cruce der. (fila) | H1: τ de cruce (fs) | I1: Retardo centrado (fs) · gráfica | J1: Normalizada · gráfica | K1: Sentido | L1: Traza R03 | M1: 5 A
A2: 0 | B2: 1.356e-07 | C2: =IF(ISNUMBER(A2),A2*conv,"") -> 0 | D2: =IF(ISNUMBER(B2),AVERAGE(INDEX($B$2:$B$23,MAX(1,1-semi)):INDEX($B$2:$B$23,MIN($M$3,1+semi))),"") -> 1.356e-07 | E2: =IF(AND(ISNUMBER(D2),ISNUMBER($M$4)),(D2-$M$4)/($M$5-$M$4),"") -> 0.00039348096 | F2: =IF(AND(ISNUMBER(E2),ISNUMBER(E3),ISNUMBER($M$6)),IF(AND(2<$M$6,E2<0.5,E3>=0.5),2,""),"") | G2: =IF(AND(ISNUMBER(E2),ISNUMBER(E3),ISNUMBER($M$6)),IF(AND(2>=$M$6,E2>=0.5,E3<0.5),2,""),"") | H2: =IF(OR(ISNUMBER(F2),ISNUMBER(G2)),C2+(0.5-E2)*(C3-C2)/(E3-E2),"") | I2: =IF(AND(ISNUMBER(E2),ISNUMBER($M$15)),C2-$M$15,NA()) -> -783.41292 | J2: =IF(ISNUMBER(E2),E2,NA()) -> 0.00039348096 | K2: =IF(AND(ISNUMBER(C2),ISNUMBER(C3)),SIGN(C3-C2),"") -> 1 | L2: Posiciones de la traza | M2: =COUNT($A$2:$A$23) -> 22
A3: 10 | B3: 1.076e-07 | C3: =IF(ISNUMBER(A3),A3*conv,"") -> 66.712819 | D3: =IF(ISNUMBER(B3),AVERAGE(INDEX($B$2:$B$23,MAX(1,2-semi)):INDEX($B$2:$B$23,MIN($M$3,2+semi))),"") -> 1.076e-07 | E3: =IF(AND(ISNUMBER(D3),ISNUMBER($M$4)),(D3-$M$4)/($M$5-$M$4),"") -> -0.0006558016 | F3: =IF(AND(ISNUMBER(E3),ISNUMBER(E4),ISNUMBER($M$6)),IF(AND(3<$M$6,E3<0.5,E4>=0.5),3,""),"") | G3: =IF(AND(ISNUMBER(E3),ISNUMBER(E4),ISNUMBER($M$6)),IF(AND(3>=$M$6,E3>=0.5,E4<0.5),3,""),"") | H3: =IF(OR(ISNUMBER(F3),ISNUMBER(G3)),C3+(0.5-E3)*(C4-C3)/(E4-E3),"") | I3: =IF(AND(ISNUMBER(E3),ISNUMBER($M$15)),C3-$M$15,NA()) -> -716.7001 | J3: =IF(ISNUMBER(E3),E3,NA()) -> -0.0006558016 | K3: =IF(AND(ISNUMBER(C3),ISNUMBER(C4)),SIGN(C4-C3),"") -> 1 | L3: Lecturas de potencia escritas | M3: =COUNT($B$2:$B$23) -> 22
A4: 20 | B4: 1.356e-07 | C4: =IF(ISNUMBER(A4),A4*conv,"") -> 133.42564 | D4: =IF(ISNUMBER(B4),AVERAGE(INDEX($B$2:$B$23,MAX(1,3-semi)):INDEX($B$2:$B$23,MIN($M$3,3+semi))),"") -> 1.356e-07 | E4: =IF(AND(ISNUMBER(D4),ISNUMBER($M$4)),(D4-$M$4)/($M$5-$M$4),"") -> 0.00039348096 | F4: =IF(AND(ISNUMBER(E4),ISNUMBER(E5),ISNUMBER($M$6)),IF(AND(4<$M$6,E4<0.5,E5>=0.5),4,""),"") | G4: =IF(AND(ISNUMBER(E4),ISNUMBER(E5),ISNUMBER($M$6)),IF(AND(4>=$M$6,E4>=0.5,E5<0.5),4,""),"") | H4: =IF(OR(ISNUMBER(F4),ISNUMBER(G4)),C4+(0.5-E4)*(C5-C4)/(E5-E4),"") | I4: =IF(AND(ISNUMBER(E4),ISNUMBER($M$15)),C4-$M$15,NA()) -> -649.98728 | J4: =IF(ISNUMBER(E4),E4,NA()) -> 0.00039348096 | K4: =IF(AND(ISNUMBER(C4),ISNUMBER(C5)),SIGN(C5-C4),"") -> 1 | L4: Fondo (promedio de las alas, W) | M4: =IF($M$3<$M$2,"",(AVERAGE(INDEX($B$2:$B$23,1):INDEX($B$2:$B$23,n_fondo))+AVERAGE(INDEX($B$2:$B$23,$M$3-n_fondo+1):INDEX($B$2:$B$23,$M$3)))/2) -> 1.251e-07
A5: 30 | B5: 3.034e-07 | C5: =IF(ISNUMBER(A5),A5*conv,"") -> 200.13846 | D5: =IF(ISNUMBER(B5),AVERAGE(INDEX($B$2:$B$23,MAX(1,4-semi)):INDEX($B$2:$B$23,MIN($M$3,4+semi))),"") -> 3.034e-07 | E5: =IF(AND(ISNUMBER(D5),ISNUMBER($M$4)),(D5-$M$4)/($M$5-$M$4),"") -> 0.0066816814 | F5: =IF(AND(ISNUMBER(E5),ISNUMBER(E6),ISNUMBER($M$6)),IF(AND(5<$M$6,E5<0.5,E6>=0.5),5,""),"") | G5: =IF(AND(ISNUMBER(E5),ISNUMBER(E6),ISNUMBER($M$6)),IF(AND(5>=$M$6,E5>=0.5,E6<0.5),5,""),"") | H5: =IF(OR(ISNUMBER(F5),ISNUMBER(G5)),C5+(0.5-E5)*(C6-C5)/(E6-E5),"") | I5: =IF(AND(ISNUMBER(E5),ISNUMBER($M$15)),C5-$M$15,NA()) -> -583.27446 | J5: =IF(ISNUMBER(E5),E5,NA()) -> 0.0066816814 | K5: =IF(AND(ISNUMBER(C5),ISNUMBER(C6)),SIGN(C6-C5),"") -> 1 | L5: Máximo de la señal (W) | M5: =IF($M$3<$M$2,"",MAX($D$2:$D$23)) -> 2.681e-05
A6: 40 | B6: 4.012e-07 | C6: =IF(ISNUMBER(A6),A6*conv,"") -> 266.85128 | D6: =IF(ISNUMBER(B6),AVERAGE(INDEX($B$2:$B$23,MAX(1,5-semi)):INDEX($B$2:$B$23,MIN($M$3,5+semi))),"") -> 4.012e-07 | E6: =IF(AND(ISNUMBER(D6),ISNUMBER($M$4)),(D6-$M$4)/($M$5-$M$4),"") -> 0.010346675 | F6: =IF(AND(ISNUMBER(E6),ISNUMBER(E7),ISNUMBER($M$6)),IF(AND(6<$M$6,E6<0.5,E7>=0.5),6,""),"") | G6: =IF(AND(ISNUMBER(E6),ISNUMBER(E7),ISNUMBER($M$6)),IF(AND(6>=$M$6,E6>=0.5,E7<0.5),6,""),"") | H6: =IF(OR(ISNUMBER(F6),ISNUMBER(G6)),C6+(0.5-E6)*(C7-C6)/(E7-E6),"") | I6: =IF(AND(ISNUMBER(E6),ISNUMBER($M$15)),C6-$M$15,NA()) -> -516.56164 | J6: =IF(ISNUMBER(E6),E6,NA()) -> 0.010346675 | K6: =IF(AND(ISNUMBER(C6),ISNUMBER(C7)),SIGN(C7-C6),"") -> 1 | L6: Fila del máximo | M6: =IFERROR(MATCH($M$5,$D$2:$D$23,0)+1,"") -> 14
A7: 50 | B7: 8.088e-07 | C7: =IF(ISNUMBER(A7),A7*conv,"") -> 333.5641 | D7: =IF(ISNUMBER(B7),AVERAGE(INDEX($B$2:$B$23,MAX(1,6-semi)):INDEX($B$2:$B$23,MIN($M$3,6+semi))),"") -> 8.088e-07 | E7: =IF(AND(ISNUMBER(D7),ISNUMBER($M$4)),(D7-$M$4)/($M$5-$M$4),"") -> 0.025621231 | F7: =IF(AND(ISNUMBER(E7),ISNUMBER(E8),ISNUMBER($M$6)),IF(AND(7<$M$6,E7<0.5,E8>=0.5),7,""),"") | G7: =IF(AND(ISNUMBER(E7),ISNUMBER(E8),ISNUMBER($M$6)),IF(AND(7>=$M$6,E7>=0.5,E8<0.5),7,""),"") | H7: =IF(OR(ISNUMBER(F7),ISNUMBER(G7)),C7+(0.5-E7)*(C8-C7)/(E8-E7),"") | I7: =IF(AND(ISNUMBER(E7),ISNUMBER($M$15)),C7-$M$15,NA()) -> -449.84882 | J7: =IF(ISNUMBER(E7),E7,NA()) -> 0.025621231 | K7: =IF(AND(ISNUMBER(C7),ISNUMBER(C8)),SIGN(C8-C7),"") -> 1 | L7: Retardo del máximo (fs) | M7: =IFERROR(INDEX($C$1:$C$23,$M$6),"") -> 800.55383
A8: 60 | B8: 1.538e-06 | C8: =IF(ISNUMBER(A8),A8*conv,"") -> 400.27691 | D8: =IF(ISNUMBER(B8),AVERAGE(INDEX($B$2:$B$23,MAX(1,7-semi)):INDEX($B$2:$B$23,MIN($M$3,7+semi))),"") -> 1.538e-06 | E8: =IF(AND(ISNUMBER(D8),ISNUMBER($M$4)),(D8-$M$4)/($M$5-$M$4),"") -> 0.052947547 | F8: =IF(AND(ISNUMBER(E8),ISNUMBER(E9),ISNUMBER($M$6)),IF(AND(8<$M$6,E8<0.5,E9>=0.5),8,""),"") | G8: =IF(AND(ISNUMBER(E8),ISNUMBER(E9),ISNUMBER($M$6)),IF(AND(8>=$M$6,E8>=0.5,E9<0.5),8,""),"") | H8: =IF(OR(ISNUMBER(F8),ISNUMBER(G8)),C8+(0.5-E8)*(C9-C8)/(E9-E8),"") | I8: =IF(AND(ISNUMBER(E8),ISNUMBER($M$15)),C8-$M$15,NA()) -> -383.136 | J8: =IF(ISNUMBER(E8),E8,NA()) -> 0.052947547 | K8: =IF(AND(ISNUMBER(C8),ISNUMBER(C9)),SIGN(C9-C8),"") -> 1 | L8: Fila del cruce izquierdo a media altura | M8: =MAX($F$2:$F$23) -> 11
A9: 70 | B9: 2.812e-06 | C9: =IF(ISNUMBER(A9),A9*conv,"") -> 466.98973 | D9: =IF(ISNUMBER(B9),AVERAGE(INDEX($B$2:$B$23,MAX(1,8-semi)):INDEX($B$2:$B$23,MIN($M$3,8+semi))),"") -> 2.812e-06 | E9: =IF(AND(ISNUMBER(D9),ISNUMBER($M$4)),(D9-$M$4)/($M$5-$M$4),"") -> 0.1006899 | F9: =IF(AND(ISNUMBER(E9),ISNUMBER(E10),ISNUMBER($M$6)),IF(AND(9<$M$6,E9<0.5,E10>=0.5),9,""),"") | G9: =IF(AND(ISNUMBER(E9),ISNUMBER(E10),ISNUMBER($M$6)),IF(AND(9>=$M$6,E9>=0.5,E10<0.5),9,""),"") | H9: =IF(OR(ISNUMBER(F9),ISNUMBER(G9)),C9+(0.5-E9)*(C10-C9)/(E10-E9),"") | I9: =IF(AND(ISNUMBER(E9),ISNUMBER($M$15)),C9-$M$15,NA()) -> -316.42318 | J9: =IF(ISNUMBER(E9),E9,NA()) -> 0.1006899 | K9: =IF(AND(ISNUMBER(C9),ISNUMBER(C10)),SIGN(C10-C9),"") -> 1 | L9: Fila del cruce derecho a media altura | M9: =MIN($G$2:$G$23) -> 16
A10: 80 | B10: 6.163e-06 | C10: =IF(ISNUMBER(A10),A10*conv,"") -> 533.70255 | D10: =IF(ISNUMBER(B10),AVERAGE(INDEX($B$2:$B$23,MAX(1,9-semi)):INDEX($B$2:$B$23,MIN($M$3,9+semi))),"") -> 6.163e-06 | E10: =IF(AND(ISNUMBER(D10),ISNUMBER($M$4)),(D10-$M$4)/($M$5-$M$4),"") -> 0.22626654 | F10: =IF(AND(ISNUMBER(E10),ISNUMBER(E11),ISNUMBER($M$6)),IF(AND(10<$M$6,E10<0.5,E11>=0.5),10,""),"") | G10: =IF(AND(ISNUMBER(E10),ISNUMBER(E11),ISNUMBER($M$6)),IF(AND(10>=$M$6,E10>=0.5,E11<0.5),10,""),"") | H10: =IF(OR(ISNUMBER(F10),ISNUMBER(G10)),C10+(0.5-E10)*(C11-C10)/(E11-E10),"") | I10: =IF(AND(ISNUMBER(E10),ISNUMBER($M$15)),C10-$M$15,NA()) -> -249.71037 | J10: =IF(ISNUMBER(E10),E10,NA()) -> 0.22626654 | K10: =IF(AND(ISNUMBER(C10),ISNUMBER(C11)),SIGN(C11-C10),"") -> 1 | L10: τ del cruce izquierdo (fs) | M10: =IF($M$8>0,INDEX($H$1:$H$23,$M$8),"") -> 616.27209
A11: 90 | B11: 1.149e-05 | C11: =IF(ISNUMBER(A11),A11*conv,"") -> 600.41537 | D11: =IF(ISNUMBER(B11),AVERAGE(INDEX($B$2:$B$23,MAX(1,10-semi)):INDEX($B$2:$B$23,MIN($M$3,10+semi))),"") -> 1.149e-05 | E11: =IF(AND(ISNUMBER(D11),ISNUMBER($M$4)),(D11-$M$4)/($M$5-$M$4),"") -> 0.42589255 | F11: =IF(AND(ISNUMBER(E11),ISNUMBER(E12),ISNUMBER($M$6)),IF(AND(11<$M$6,E11<0.5,E12>=0.5),11,""),"") -> 11 | G11: =IF(AND(ISNUMBER(E11),ISNUMBER(E12),ISNUMBER($M$6)),IF(AND(11>=$M$6,E11>=0.5,E12<0.5),11,""),"") | H11: =IF(OR(ISNUMBER(F11),ISNUMBER(G11)),C11+(0.5-E11)*(C12-C11)/(E12-E11),"") -> 616.27209 | I11: =IF(AND(ISNUMBER(E11),ISNUMBER($M$15)),C11-$M$15,NA()) -> -182.99755 | J11: =IF(ISNUMBER(E11),E11,NA()) -> 0.42589255 | K11: =IF(AND(ISNUMBER(C11),ISNUMBER(C12)),SIGN(C12-C11),"") -> 1 | L11: τ del cruce derecho (fs) | M11: =IF($M$9>0,INDEX($H$1:$H$23,$M$9),"") -> 950.55374
